<sdf version='1.6'>
  <world name='default'>
    <light name='sun' type='directional'>
      <cast_shadows>1</cast_shadows>
      <pose frame=''>0 0 10 0 -0 0</pose>
      <diffuse>0.8 0.8 0.8 1</diffuse>
      <specular>0.1 0.1 0.1 1</specular>
      <attenuation>
        <range>1000</range>
        <constant>0.9</constant>
        <linear>0.01</linear>
        <quadratic>0.001</quadratic>
      </attenuation>
      <direction>-0.5 0.5 -1</direction>
    </light>
    <model name='ground_plane'>
      <static>1</static>
      <link name='link'>
        <collision name='collision'>
          <geometry>
            <plane>
              <normal>0 0 1</normal>
              <size>100 100</size>
            </plane>
          </geometry>
          <surface>
            <friction>
              <ode>
                <mu>100</mu>
                <mu2>50</mu2>
              </ode>
              <torsional>
                <ode/>
              </torsional>
            </friction>
            <contact>
              <ode/>
            </contact>
            <bounce/>
          </surface>
          <max_contacts>10</max_contacts>
        </collision>
        <visual name='visual'>
          <cast_shadows>0</cast_shadows>
          <geometry>
            <plane>
              <normal>0 0 1</normal>
              <size>100 100</size>
            </plane>
          </geometry>
          <material>
            <script>
              <uri>file://media/materials/scripts/gazebo.material</uri>
              <name>Gazebo/Grey</name>
            </script>
          </material>
        </visual>
        <self_collide>0</self_collide>
        <kinematic>0</kinematic>
        <gravity>1</gravity>
      </link>
    </model>
    <gravity>0 0 -9.8</gravity>
    <magnetic_field>6e-06 2.3e-05 -4.2e-05</magnetic_field>
    <atmosphere type='adiabatic'/>
    <physics name='default_physics' default='0' type='ode'>
      <max_step_size>0.001</max_step_size>
      <real_time_factor>1</real_time_factor>
      <real_time_update_rate>1000</real_time_update_rate>
    </physics>
    <scene>
      <ambient>0.4 0.4 0.4 1</ambient>
      <background>0.7 0.7 0.7 1</background>
      <shadows>1</shadows>
    </scene>
    <spherical_coordinates>
      <surface_model>EARTH_WGS84</surface_model>
      <latitude_deg>0</latitude_deg>
      <longitude_deg>0</longitude_deg>
      <elevation>0</elevation>
      <heading_deg>0</heading_deg>
    </spherical_coordinates>
    <model name='/'>
      <link name='base_link'>
        <pose frame=''>0 0 0 0 -0 0</pose>
        <inertial>
          <pose frame=''>-0 0 0 0 -0 0</pose>
          <mass>10.238</mass>
          <inertia>
            <ixx>0.74932</ixx>
            <ixy>-1.2062e-17</ixy>
            <ixz>-1.9781e-17</ixz>
            <iyy>2.3017</iyy>
            <iyz>7.9134e-17</iyz>
            <izz>2.9675</izz>
          </inertia>
        </inertial>
        <collision name='base_link_collision'>
          <pose frame=''>0 0 0 0 -0 0</pose>
          <geometry>
            <mesh>
              <scale>1 1 1</scale>
              <uri>/home/hitstar/catkin_ws_sim/src/simpleDog/meshes/base_link.STL</uri>
            </mesh>
          </geometry>
          <surface>
            <contact>
              <ode>
                <kp>1e+07</kp>
                <kd>1</kd>
              </ode>
            </contact>
            <friction>
              <ode>
                <mu>10</mu>
                <mu2>10</mu2>
                <fdir1>1 0 0</fdir1>
              </ode>
              <torsional>
                <ode/>
              </torsional>
            </friction>
            <bounce/>
          </surface>
          <max_contacts>10</max_contacts>
        </collision>
        <collision name='base_link_fixed_joint_lump__camera_link_collision_1'>
          <pose frame=''>0.3 0 0.1 0 0.18 0</pose>
          <geometry>
            <box>
              <size>0.07 0.3 0.09</size>
            </box>
          </geometry>
          <surface>
            <contact>
              <ode/>
            </contact>
            <friction>
              <ode/>
              <torsional>
                <ode/>
              </torsional>
            </friction>
            <bounce/>
          </surface>
          <max_contacts>10</max_contacts>
        </collision>
        <visual name='base_link_visual'>
          <pose frame=''>0 0 0 0 -0 0</pose>
          <geometry>
            <mesh>
              <scale>1 1 1</scale>
              <uri>/home/hitstar/catkin_ws_sim/src/simpleDog/meshes/base_link.STL</uri>
            </mesh>
          </geometry>
          <material>
            <script>
              <name>Gazebo/DarkGrey</name>
              <uri>file://media/materials/scripts/gazebo.material</uri>
            </script>
          </material>
        </visual>
        <visual name='base_link_fixed_joint_lump__camera_link_visual_1'>
          <pose frame=''>0.3 0 0.1 0.18 -1e-06 1.5708</pose>
          <geometry>
            <mesh>
              <scale>1 1 1</scale>
              <uri>/home/hitstar/catkin_ws_sim/src/simpleDog/meshes/kinect.dae</uri>
            </mesh>
          </geometry>
          <material>
            <script>
              <uri>__default__</uri>
              <name>__default__</name>
            </script>
          </material>
        </visual>
        <velocity_decay/>
        <gravity>1</gravity>
        <gravity>1</gravity>
        <velocity_decay/>
        <self_collide>0</self_collide>
        <sensor name='camera' type='depth'>
          <always_on>1</always_on>
          <update_rate>10</update_rate>
          <camera name='__default__'>
            <horizontal_fov>1.04667</horizontal_fov>
            <image>
              <format>R8G8B8</format>
              <width>640</width>
              <height>480</height>
            </image>
            <clip>
              <near>0.05</near>
              <far>8</far>
            </clip>
          </camera>
          <plugin name='kinect_camera_controller' filename='libgazebo_ros_openni_kinect.so'>
            <cameraName>camera</cameraName>
            <alwaysOn>true</alwaysOn>
            <updateRate>10.0</updateRate>
            <imageTopicName>rgb/image_raw</imageTopicName>
            <depthImageTopicName>depth/image_raw</depthImageTopicName>
            <pointCloudTopicName>depth/points</pointCloudTopicName>
            <cameraInfoTopicName>rgb/camera_info</cameraInfoTopicName>
            <depthImageCameraInfoTopicName>depth/camera_info</depthImageCameraInfoTopicName>
            <frameName>camera_frame_optical</frameName>
            <baseline>0.1</baseline>
            <distortion_k1>0.0</distortion_k1>
            <distortion_k2>0.0</distortion_k2>
            <distortion_k3>0.0</distortion_k3>
            <distortion_t1>0.0</distortion_t1>
            <distortion_t2>0.0</distortion_t2>
            <pointCloudCutoff>0.4</pointCloudCutoff>
            <robotNamespace>/</robotNamespace>
          </plugin>
          <pose frame=''>0.3 0 0.1 0 0.18 0</pose>
        </sensor>
        <kinematic>0</kinematic>
      </link>
      <link name='front_left_1_Link'>
        <pose frame=''>-0.36 -0.175 0 -1.5708 0.00028 1.5708</pose>
        <inertial>
          <pose frame=''>-0.012793 -0 0.04 0 -0 0</pose>
          <mass>1.1709</mass>
          <inertia>
            <ixx>0.0013167</ixx>
            <ixy>-4.8862e-17</ixy>
            <ixz>7.6795e-20</ixz>
            <iyy>0.001719</iyy>
            <iyz>-1.6433e-19</iyz>
            <izz>0.0021511</izz>
          </inertia>
        </inertial>
        <collision name='front_left_1_Link_collision'>
          <pose frame=''>0 0 0 0 -0 0</pose>
          <geometry>
            <mesh>
              <scale>1 1 1</scale>
              <uri>/home/hitstar/catkin_ws_sim/src/simpleDog/meshes/front_left_1_Link.STL</uri>
            </mesh>
          </geometry>
          <surface>
            <contact>
              <ode>
                <kp>1e+07</kp>
                <kd>1</kd>
              </ode>
            </contact>
            <friction>
              <ode>
                <mu>10</mu>
                <mu2>10</mu2>
                <fdir1>1 0 0</fdir1>
              </ode>
              <torsional>
                <ode/>
              </torsional>
            </friction>
            <bounce/>
          </surface>
          <max_contacts>10</max_contacts>
        </collision>
        <visual name='front_left_1_Link_visual'>
          <pose frame=''>0 0 0 0 -0 0</pose>
          <geometry>
            <mesh>
              <scale>1 1 1</scale>
              <uri>/home/hitstar/catkin_ws_sim/src/simpleDog/meshes/front_left_1_Link.STL</uri>
            </mesh>
          </geometry>
          <material>
            <script>
              <uri>__default__</uri>
              <name>__default__</name>
            </script>
          </material>
        </visual>
        <gravity>1</gravity>
        <velocity_decay/>
        <self_collide>0</self_collide>
        <gravity>1</gravity>
        <kinematic>0</kinematic>
      </link>
      <joint name='front_left_1_joint' type='revolute'>
        <child>front_left_1_Link</child>
        <parent>base_link</parent>
        <axis>
          <xyz>1 4e-06 4e-06</xyz>
          <limit>
            <lower>-3</lower>
            <upper>3</upper>
            <effort>100</effort>
            <velocity>10</velocity>
          </limit>
          <dynamics>
            <spring_reference>0</spring_reference>
            <spring_stiffness>0</spring_stiffness>
          </dynamics>
          <use_parent_model_frame>1</use_parent_model_frame>
        </axis>
        <physics>
          <provide_feedback>1</provide_feedback>
          <ode>
            <provide_feedback>1</provide_feedback>
            <limit>
              <cfm>0</cfm>
              <erp>0.2</erp>
            </limit>
          </ode>
        </physics>
      </joint>
      <link name='front_left_2_Link'>
        <pose frame=''>-0.4 -0.209321 9e-06 0.2981 -0.000288 -1.57079</pose>
        <inertial>
          <pose frame=''>0.025099 3e-06 -0.11431 0 -0 0</pose>
          <mass>3.3902</mass>
          <inertia>
            <ixx>0.028484</ixx>
            <ixy>2.4654e-16</ixy>
            <ixz>1.2624e-14</ixz>
            <iyy>0.026875</iyy>
            <iyz>5.6397e-18</iyz>
            <izz>0.0030209</izz>
          </inertia>
        </inertial>
        <collision name='front_left_2_Link_collision'>
          <pose frame=''>0 0 0 0 -0 0</pose>
          <geometry>
            <mesh>
              <scale>1 1 1</scale>
              <uri>/home/hitstar/catkin_ws_sim/src/simpleDog/meshes/front_left_2_Link.STL</uri>
            </mesh>
          </geometry>
          <surface>
            <contact>
              <ode>
                <kp>1e+07</kp>
                <kd>1</kd>
              </ode>
            </contact>
            <friction>
              <ode>
                <mu>10</mu>
                <mu2>10</mu2>
                <fdir1>1 0 0</fdir1>
              </ode>
              <torsional>
                <ode/>
              </torsional>
            </friction>
            <bounce/>
          </surface>
          <max_contacts>10</max_contacts>
        </collision>
        <visual name='front_left_2_Link_visual'>
          <pose frame=''>0 0 0 0 -0 0</pose>
          <geometry>
            <mesh>
              <scale>1 1 1</scale>
              <uri>/home/hitstar/catkin_ws_sim/src/simpleDog/meshes/front_left_2_Link.STL</uri>
            </mesh>
          </geometry>
          <material>
            <script>
              <uri>__default__</uri>
              <name>__default__</name>
            </script>
          </material>
        </visual>
        <gravity>1</gravity>
        <velocity_decay/>
        <self_collide>0</self_collide>
        <gravity>1</gravity>
        <kinematic>0</kinematic>
      </link>
      <joint name='front_left_2_joint' type='revolute'>
        <child>front_left_2_Link</child>
        <parent>front_left_1_Link</parent>
        <axis>
          <xyz>4e-06 -1 0.000288</xyz>
          <limit>
            <lower>-3</lower>
            <upper>3</upper>
            <effort>100</effort>
            <velocity>10</velocity>
          </limit>
          <dynamics>
            <spring_reference>0</spring_reference>
            <spring_stiffness>0</spring_stiffness>
          </dynamics>
          <use_parent_model_frame>1</use_parent_model_frame>
        </axis>
        <physics>
          <provide_feedback>1</provide_feedback>
          <ode>
            <provide_feedback>1</provide_feedback>
            <limit>
              <cfm>0</cfm>
              <erp>0.2</erp>
            </limit>
          </ode>
        </physics>
      </joint>
      <link name='front_left_3_Link'>
        <pose frame=''>-0.326577 -0.229405 -0.238949 0.53853 0.000285 1.57079</pose>
        <inertial>
          <pose frame=''>-0.043355 -1e-05 -0.087821 0 -0 0</pose>
          <mass>1.3523</mass>
          <inertia>
            <ixx>0.0093381</ixx>
            <ixy>-2.3773e-08</ixy>
            <ixz>-0.00020532</ixz>
            <iyy>0.0091429</iyy>
            <iyz>-9.1579e-07</iyz>
            <izz>0.00053022</izz>
          </inertia>
        </inertial>
        <collision name='front_left_3_Link_collision'>
          <pose frame=''>0 0 0 0 -0 0</pose>
          <geometry>
            <mesh>
              <scale>1 1 1</scale>
              <uri>/home/hitstar/catkin_ws_sim/src/simpleDog/meshes/front_left_3_Link.STL</uri>
            </mesh>
          </geometry>
          <surface>
            <contact>
              <ode>
                <kp>1e+07</kp>
                <kd>1</kd>
              </ode>
            </contact>
            <friction>
              <ode>
                <mu>10</mu>
                <mu2>10</mu2>
                <fdir1>1 0 0</fdir1>
              </ode>
              <torsional>
                <ode/>
              </torsional>
            </friction>
            <bounce/>
          </surface>
          <max_contacts>10</max_contacts>
        </collision>
        <visual name='front_left_3_Link_visual'>
          <pose frame=''>0 0 0 0 -0 0</pose>
          <geometry>
            <mesh>
              <scale>1 1 1</scale>
              <uri>/home/hitstar/catkin_ws_sim/src/simpleDog/meshes/front_left_3_Link.STL</uri>
            </mesh>
          </geometry>
          <material>
            <script>
              <uri>__default__</uri>
              <name>__default__</name>
            </script>
          </material>
        </visual>
        <gravity>1</gravity>
        <velocity_decay/>
        <self_collide>0</self_collide>
        <gravity>1</gravity>
        <kinematic>0</kinematic>
      </link>
      <joint name='front_left_3_joint' type='revolute'>
        <child>front_left_3_Link</child>
        <parent>front_left_2_Link</parent>
        <axis>
          <xyz>-3e-06 -1 0.000285</xyz>
          <limit>
            <lower>-3</lower>
            <upper>3</upper>
            <effort>100</effort>
            <velocity>10</velocity>
          </limit>
          <dynamics>
            <spring_reference>0</spring_reference>
            <spring_stiffness>0</spring_stiffness>
          </dynamics>
          <use_parent_model_frame>1</use_parent_model_frame>
        </axis>
        <physics>
          <provide_feedback>1</provide_feedback>
          <ode>
            <provide_feedback>1</provide_feedback>
            <limit>
              <cfm>0</cfm>
              <erp>0.2</erp>
            </limit>
          </ode>
        </physics>
      </joint>
      <link name='front_right_1_Link'>
        <pose frame=''>-0.36 0.175 0 1.5708 0.0004 -1.5708</pose>
        <inertial>
          <pose frame=''>-0.012793 0 0.04 0 -0 0</pose>
          <mass>1.1709</mass>
          <inertia>
            <ixx>0.0013167</ixx>
            <ixy>1.2874e-16</ixy>
            <ixz>-2.0543e-19</ixz>
            <iyy>0.001719</iyy>
            <iyz>-1.7779e-19</iyz>
            <izz>0.0021511</izz>
          </inertia>
        </inertial>
        <collision name='front_right_1_Link_collision'>
          <pose frame=''>0 0 0 0 -0 0</pose>
          <geometry>
            <mesh>
              <scale>1 1 1</scale>
              <uri>/home/hitstar/catkin_ws_sim/src/simpleDog/meshes/front_right_1_Link.STL</uri>
            </mesh>
          </geometry>
          <surface>
            <contact>
              <ode>
                <kp>1e+07</kp>
                <kd>1</kd>
              </ode>
            </contact>
            <friction>
              <ode>
                <mu>10</mu>
                <mu2>10</mu2>
                <fdir1>1 0 0</fdir1>
              </ode>
              <torsional>
                <ode/>
              </torsional>
            </friction>
            <bounce/>
          </surface>
          <max_contacts>10</max_contacts>
        </collision>
        <visual name='front_right_1_Link_visual'>
          <pose frame=''>0 0 0 0 -0 0</pose>
          <geometry>
            <mesh>
              <scale>1 1 1</scale>
              <uri>/home/hitstar/catkin_ws_sim/src/simpleDog/meshes/front_right_1_Link.STL</uri>
            </mesh>
          </geometry>
          <material>
            <script>
              <uri>__default__</uri>
              <name>__default__</name>
            </script>
          </material>
        </visual>
        <gravity>1</gravity>
        <velocity_decay/>
        <self_collide>0</self_collide>
        <gravity>1</gravity>
        <kinematic>0</kinematic>
      </link>
      <joint name='front_right_1_joint' type='revolute'>
        <child>front_right_1_Link</child>
        <parent>base_link</parent>
        <axis>
          <xyz>1 -4e-06 4e-06</xyz>
          <limit>
            <lower>-3</lower>
            <upper>3</upper>
            <effort>100</effort>
            <velocity>10</velocity>
          </limit>
          <dynamics>
            <spring_reference>0</spring_reference>
            <spring_stiffness>0</spring_stiffness>
          </dynamics>
          <use_parent_model_frame>1</use_parent_model_frame>
        </axis>
        <physics>
          <provide_feedback>1</provide_feedback>
          <ode>
            <provide_feedback>1</provide_feedback>
            <limit>
              <cfm>0</cfm>
              <erp>0.2</erp>
            </limit>
          </ode>
        </physics>
      </joint>
      <link name='front_right_2_Link'>
        <pose frame=''>-0.4 0.20942 1.4e-05 -0.2973 -0.000393 1.57079</pose>
        <inertial>
          <pose frame=''>0.025 -0 -0.11432 0 -0 0</pose>
          <mass>3.3902</mass>
          <inertia>
            <ixx>0.028484</ixx>
            <ixy>-1.9935e-17</ixy>
            <ixz>1.0386e-15</ixz>
            <iyy>0.026875</iyy>
            <iyz>-1.4151e-17</iyz>
            <izz>0.0030209</izz>
          </inertia>
        </inertial>
        <collision name='front_right_2_Link_collision'>
          <pose frame=''>0 0 0 0 -0 0</pose>
          <geometry>
            <mesh>
              <scale>1 1 1</scale>
              <uri>/home/hitstar/catkin_ws_sim/src/simpleDog/meshes/front_right_2_Link.STL</uri>
            </mesh>
          </geometry>
          <surface>
            <contact>
              <ode>
                <kp>1e+07</kp>
                <kd>1</kd>
              </ode>
            </contact>
            <friction>
              <ode>
                <mu>10</mu>
                <mu2>10</mu2>
                <fdir1>1 0 0</fdir1>
              </ode>
              <torsional>
                <ode/>
              </torsional>
            </friction>
            <bounce/>
          </surface>
          <max_contacts>10</max_contacts>
        </collision>
        <visual name='front_right_2_Link_visual'>
          <pose frame=''>0 0 0 0 -0 0</pose>
          <geometry>
            <mesh>
              <scale>1 1 1</scale>
              <uri>/home/hitstar/catkin_ws_sim/src/simpleDog/meshes/front_right_2_Link.STL</uri>
            </mesh>
          </geometry>
          <material>
            <script>
              <uri>__default__</uri>
              <name>__default__</name>
            </script>
          </material>
        </visual>
        <gravity>1</gravity>
        <velocity_decay/>
        <self_collide>0</self_collide>
        <gravity>1</gravity>
        <kinematic>0</kinematic>
      </link>
      <joint name='front_right_2_joint' type='revolute'>
        <child>front_right_2_Link</child>
        <parent>front_right_1_Link</parent>
        <axis>
          <xyz>-4e-06 -1 -0.000393</xyz>
          <limit>
            <lower>-3</lower>
            <upper>3</upper>
            <effort>100</effort>
            <velocity>10</velocity>
          </limit>
          <dynamics>
            <spring_reference>0</spring_reference>
            <spring_stiffness>0</spring_stiffness>
          </dynamics>
          <use_parent_model_frame>1</use_parent_model_frame>
        </axis>
        <physics>
          <provide_feedback>1</provide_feedback>
          <ode>
            <provide_feedback>1</provide_feedback>
            <limit>
              <cfm>0</cfm>
              <erp>0.2</erp>
            </limit>
          </ode>
        </physics>
      </joint>
      <link name='front_right_3_Link'>
        <pose frame=''>-0.326765 0.229514 -0.239011 -0.54065 0.000395 -1.57081</pose>
        <inertial>
          <pose frame=''>-0.043271 -1e-05 -0.087821 0 -0 0</pose>
          <mass>1.3523</mass>
          <inertia>
            <ixx>0.0093381</ixx>
            <ixy>-2.3773e-08</ixy>
            <ixz>-0.00020532</ixz>
            <iyy>0.0091429</iyy>
            <iyz>-9.1579e-07</iyz>
            <izz>0.00053022</izz>
          </inertia>
        </inertial>
        <collision name='front_right_3_Link_collision'>
          <pose frame=''>0 0 0 0 -0 0</pose>
          <geometry>
            <mesh>
              <scale>1 1 1</scale>
              <uri>/home/hitstar/catkin_ws_sim/src/simpleDog/meshes/front_right_3_Link.STL</uri>
            </mesh>
          </geometry>
          <surface>
            <contact>
              <ode>
                <kp>1e+07</kp>
                <kd>1</kd>
              </ode>
            </contact>
            <friction>
              <ode>
                <mu>10</mu>
                <mu2>10</mu2>
                <fdir1>1 0 0</fdir1>
              </ode>
              <torsional>
                <ode/>
              </torsional>
            </friction>
            <bounce/>
          </surface>
          <max_contacts>10</max_contacts>
        </collision>
        <visual name='front_right_3_Link_visual'>
          <pose frame=''>0 0 0 0 -0 0</pose>
          <geometry>
            <mesh>
              <scale>1 1 1</scale>
              <uri>/home/hitstar/catkin_ws_sim/src/simpleDog/meshes/front_right_3_Link.STL</uri>
            </mesh>
          </geometry>
          <material>
            <script>
              <uri>__default__</uri>
              <name>__default__</name>
            </script>
          </material>
        </visual>
        <gravity>1</gravity>
        <velocity_decay/>
        <self_collide>0</self_collide>
        <gravity>1</gravity>
        <kinematic>0</kinematic>
      </link>
      <joint name='front_right_3_joint' type='revolute'>
        <child>front_right_3_Link</child>
        <parent>front_right_2_Link</parent>
        <axis>
          <xyz>-1.1e-05 -1 -0.000395</xyz>
          <limit>
            <lower>-3</lower>
            <upper>3</upper>
            <effort>100</effort>
            <velocity>10</velocity>
          </limit>
          <dynamics>
            <spring_reference>0</spring_reference>
            <spring_stiffness>0</spring_stiffness>
          </dynamics>
          <use_parent_model_frame>1</use_parent_model_frame>
        </axis>
        <physics>
          <provide_feedback>1</provide_feedback>
          <ode>
            <provide_feedback>1</provide_feedback>
            <limit>
              <cfm>0</cfm>
              <erp>0.2</erp>
            </limit>
          </ode>
        </physics>
      </joint>
      <link name='rear_left_1_Link'>
        <pose frame=''>0.36 -0.175 0 -1.5708 0.005597 1.5708</pose>
        <inertial>
          <pose frame=''>-0.012793 0 -0.04 0 -0 0</pose>
          <mass>1.1709</mass>
          <inertia>
            <ixx>0.0013167</ixx>
            <ixy>2.8409e-18</ixy>
            <ixz>3.3901e-19</ixz>
            <iyy>0.001719</iyy>
            <iyz>5.3128e-21</iyz>
            <izz>0.0021511</izz>
          </inertia>
        </inertial>
        <collision name='rear_left_1_Link_collision'>
          <pose frame=''>0 0 0 0 -0 0</pose>
          <geometry>
            <mesh>
              <scale>1 1 1</scale>
              <uri>/home/hitstar/catkin_ws_sim/src/simpleDog/meshes/rear_left_1_Link.STL</uri>
            </mesh>
          </geometry>
          <surface>
            <contact>
              <ode>
                <kp>1e+07</kp>
                <kd>1</kd>
              </ode>
            </contact>
            <friction>
              <ode>
                <mu>10</mu>
                <mu2>10</mu2>
                <fdir1>1 0 0</fdir1>
              </ode>
              <torsional>
                <ode/>
              </torsional>
            </friction>
            <bounce/>
          </surface>
          <max_contacts>10</max_contacts>
        </collision>
        <visual name='rear_left_1_Link_visual'>
          <pose frame=''>0 0 0 0 -0 0</pose>
          <geometry>
            <mesh>
              <scale>1 1 1</scale>
              <uri>/home/hitstar/catkin_ws_sim/src/simpleDog/meshes/rear_left_1_Link.STL</uri>
            </mesh>
          </geometry>
          <material>
            <script>
              <uri>__default__</uri>
              <name>__default__</name>
            </script>
          </material>
        </visual>
        <gravity>1</gravity>
        <velocity_decay/>
        <self_collide>0</self_collide>
        <gravity>1</gravity>
        <kinematic>0</kinematic>
      </link>
      <joint name='rear_left_1_joint' type='revolute'>
        <child>rear_left_1_Link</child>
        <parent>base_link</parent>
        <axis>
          <xyz>1 4e-06 4e-06</xyz>
          <limit>
            <lower>-3</lower>
            <upper>3</upper>
            <effort>100</effort>
            <velocity>10</velocity>
          </limit>
          <dynamics>
            <spring_reference>0</spring_reference>
            <spring_stiffness>0</spring_stiffness>
          </dynamics>
          <use_parent_model_frame>1</use_parent_model_frame>
        </axis>
        <physics>
          <provide_feedback>1</provide_feedback>
          <ode>
            <provide_feedback>1</provide_feedback>
            <limit>
              <cfm>0</cfm>
              <erp>0.2</erp>
            </limit>
          </ode>
        </physics>
      </joint>
      <link name='rear_left_2_Link'>
        <pose frame=''>0.4 -0.207452 0.000182 0.348 -0.00559 -1.57079</pose>
        <inertial>
          <pose frame=''>0.026967 -0 -0.11432 0 -0 0</pose>
          <mass>3.3902</mass>
          <inertia>
            <ixx>0.028484</ixx>
            <ixy>-2.8833e-18</ixy>
            <ixz>-1.9987e-16</ixz>
            <iyy>0.026875</iyy>
            <iyz>7.9636e-18</iyz>
            <izz>0.0030209</izz>
          </inertia>
        </inertial>
        <collision name='rear_left_2_Link_collision'>
          <pose frame=''>0 0 0 0 -0 0</pose>
          <geometry>
            <mesh>
              <scale>1 1 1</scale>
              <uri>/home/hitstar/catkin_ws_sim/src/simpleDog/meshes/rear_left_2_Link.STL</uri>
            </mesh>
          </geometry>
          <surface>
            <contact>
              <ode>
                <kp>1e+07</kp>
                <kd>1</kd>
              </ode>
            </contact>
            <friction>
              <ode>
                <mu>10</mu>
                <mu2>10</mu2>
                <fdir1>1 0 0</fdir1>
              </ode>
              <torsional>
                <ode/>
              </torsional>
            </friction>
            <bounce/>
          </surface>
          <max_contacts>10</max_contacts>
        </collision>
        <visual name='rear_left_2_Link_visual'>
          <pose frame=''>0 0 0 0 -0 0</pose>
          <geometry>
            <mesh>
              <scale>1 1 1</scale>
              <uri>/home/hitstar/catkin_ws_sim/src/simpleDog/meshes/rear_left_2_Link.STL</uri>
            </mesh>
          </geometry>
          <material>
            <script>
              <uri>__default__</uri>
              <name>__default__</name>
            </script>
          </material>
        </visual>
        <gravity>1</gravity>
        <velocity_decay/>
        <self_collide>0</self_collide>
        <gravity>1</gravity>
        <kinematic>0</kinematic>
      </link>
      <joint name='rear_left_2_joint' type='revolute'>
        <child>rear_left_2_Link</child>
        <parent>rear_left_1_Link</parent>
        <axis>
          <xyz>4e-06 -0.999984 0.00559</xyz>
          <limit>
            <lower>-3</lower>
            <upper>3</upper>
            <effort>100</effort>
            <velocity>10</velocity>
          </limit>
          <dynamics>
            <spring_reference>0</spring_reference>
            <spring_stiffness>0</spring_stiffness>
          </dynamics>
          <use_parent_model_frame>1</use_parent_model_frame>
        </axis>
        <physics>
          <provide_feedback>1</provide_feedback>
          <ode>
            <provide_feedback>1</provide_feedback>
            <limit>
              <cfm>0</cfm>
              <erp>0.2</erp>
            </limit>
          </ode>
        </physics>
      </joint>
      <link name='rear_left_3_Link'>
        <pose frame=''>0.485255 -0.229058 -0.234715 0.52907 0.005592 1.57081</pose>
        <inertial>
          <pose frame=''>-0.044945 -1e-05 -0.087821 0 -0 0</pose>
          <mass>1.3523</mass>
          <inertia>
            <ixx>0.0093381</ixx>
            <ixy>-2.3773e-08</ixy>
            <ixz>-0.00020532</ixz>
            <iyy>0.0091429</iyy>
            <iyz>-9.1579e-07</iyz>
            <izz>0.00053022</izz>
          </inertia>
        </inertial>
        <collision name='rear_left_3_Link_collision'>
          <pose frame=''>0 0 0 0 -0 0</pose>
          <geometry>
            <mesh>
              <scale>1 1 1</scale>
              <uri>/home/hitstar/catkin_ws_sim/src/simpleDog/meshes/rear_left_3_Link.STL</uri>
            </mesh>
          </geometry>
          <surface>
            <contact>
              <ode>
                <kp>1e+07</kp>
                <kd>1</kd>
              </ode>
            </contact>
            <friction>
              <ode>
                <mu>10</mu>
                <mu2>10</mu2>
                <fdir1>1 0 0</fdir1>
              </ode>
              <torsional>
                <ode/>
              </torsional>
            </friction>
            <bounce/>
          </surface>
          <max_contacts>10</max_contacts>
        </collision>
        <visual name='rear_left_3_Link_visual'>
          <pose frame=''>0 0 0 0 -0 0</pose>
          <geometry>
            <mesh>
              <scale>1 1 1</scale>
              <uri>/home/hitstar/catkin_ws_sim/src/simpleDog/meshes/rear_left_3_Link.STL</uri>
            </mesh>
          </geometry>
          <material>
            <script>
              <uri>__default__</uri>
              <name>__default__</name>
            </script>
          </material>
        </visual>
        <gravity>1</gravity>
        <velocity_decay/>
        <self_collide>0</self_collide>
        <gravity>1</gravity>
        <kinematic>0</kinematic>
      </link>
      <joint name='rear_left_3_joint' type='revolute'>
        <child>rear_left_3_Link</child>
        <parent>rear_left_2_Link</parent>
        <axis>
          <xyz>1.1e-05 -0.999984 0.005592</xyz>
          <limit>
            <lower>-3</lower>
            <upper>3</upper>
            <effort>100</effort>
            <velocity>10</velocity>
          </limit>
          <dynamics>
            <spring_reference>0</spring_reference>
            <spring_stiffness>0</spring_stiffness>
          </dynamics>
          <use_parent_model_frame>1</use_parent_model_frame>
        </axis>
        <physics>
          <provide_feedback>1</provide_feedback>
          <ode>
            <provide_feedback>1</provide_feedback>
            <limit>
              <cfm>0</cfm>
              <erp>0.2</erp>
            </limit>
          </ode>
        </physics>
      </joint>
      <link name='rear_right_1_Link'>
        <pose frame=''>0.36 0.175 0 1.5708 0.000492 -1.5708</pose>
        <inertial>
          <pose frame=''>-0.012793 -0 -0.04 0 -0 0</pose>
          <mass>1.1709</mass>
          <inertia>
            <ixx>0.0013167</ixx>
            <ixy>-7.0709e-18</ixy>
            <ixz>-1.3209e-19</ixz>
            <iyy>0.001719</iyy>
            <iyz>-1.4321e-19</iyz>
            <izz>0.0021511</izz>
          </inertia>
        </inertial>
        <collision name='rear_right_1_Link_collision'>
          <pose frame=''>0 0 0 0 -0 0</pose>
          <geometry>
            <mesh>
              <scale>1 1 1</scale>
              <uri>/home/hitstar/catkin_ws_sim/src/simpleDog/meshes/rear_right_1_Link.STL</uri>
            </mesh>
          </geometry>
          <surface>
            <contact>
              <ode>
                <kp>1e+07</kp>
                <kd>1</kd>
              </ode>
            </contact>
            <friction>
              <ode>
                <mu>10</mu>
                <mu2>10</mu2>
                <fdir1>1 0 0</fdir1>
              </ode>
              <torsional>
                <ode/>
              </torsional>
            </friction>
            <bounce/>
          </surface>
          <max_contacts>10</max_contacts>
        </collision>
        <visual name='rear_right_1_Link_visual'>
          <pose frame=''>0 0 0 0 -0 0</pose>
          <geometry>
            <mesh>
              <scale>1 1 1</scale>
              <uri>/home/hitstar/catkin_ws_sim/src/simpleDog/meshes/rear_right_1_Link.STL</uri>
            </mesh>
          </geometry>
          <material>
            <script>
              <uri>__default__</uri>
              <name>__default__</name>
            </script>
          </material>
        </visual>
        <gravity>1</gravity>
        <velocity_decay/>
        <self_collide>0</self_collide>
        <gravity>1</gravity>
        <kinematic>0</kinematic>
      </link>
      <joint name='rear_right_1_joint' type='revolute'>
        <child>rear_right_1_Link</child>
        <parent>base_link</parent>
        <axis>
          <xyz>1 -4e-06 4e-06</xyz>
          <limit>
            <lower>-3</lower>
            <upper>3</upper>
            <effort>100</effort>
            <velocity>10</velocity>
          </limit>
          <dynamics>
            <spring_reference>0</spring_reference>
            <spring_stiffness>0</spring_stiffness>
          </dynamics>
          <use_parent_model_frame>1</use_parent_model_frame>
        </axis>
        <physics>
          <provide_feedback>1</provide_feedback>
          <ode>
            <provide_feedback>1</provide_feedback>
            <limit>
              <cfm>0</cfm>
              <erp>0.2</erp>
            </limit>
          </ode>
        </physics>
      </joint>
      <link name='rear_right_2_Link'>
        <pose frame=''>0.4 0.20942 1.7e-05 -0.3499 -0.000485 1.57079</pose>
        <inertial>
          <pose frame=''>0.025 0 -0.11432 0 -0 0</pose>
          <mass>3.3902</mass>
          <inertia>
            <ixx>0.028484</ixx>
            <ixy>1.1937e-17</ixy>
            <ixz>-4.1954e-16</ixz>
            <iyy>0.026875</iyy>
            <iyz>4.0516e-18</iyz>
            <izz>0.0030209</izz>
          </inertia>
        </inertial>
        <collision name='rear_right_2_Link_collision'>
          <pose frame=''>0 0 0 0 -0 0</pose>
          <geometry>
            <mesh>
              <scale>1 1 1</scale>
              <uri>/home/hitstar/catkin_ws_sim/src/simpleDog/meshes/rear_right_2_Link.STL</uri>
            </mesh>
          </geometry>
          <surface>
            <contact>
              <ode>
                <kp>1e+07</kp>
                <kd>1</kd>
              </ode>
            </contact>
            <friction>
              <ode>
                <mu>10</mu>
                <mu2>10</mu2>
                <fdir1>1 0 0</fdir1>
              </ode>
              <torsional>
                <ode/>
              </torsional>
            </friction>
            <bounce/>
          </surface>
          <max_contacts>10</max_contacts>
        </collision>
        <visual name='rear_right_2_Link_visual'>
          <pose frame=''>0 0 0 0 -0 0</pose>
          <geometry>
            <mesh>
              <scale>1 1 1</scale>
              <uri>/home/hitstar/catkin_ws_sim/src/simpleDog/meshes/rear_right_2_Link.STL</uri>
            </mesh>
          </geometry>
          <material>
            <script>
              <uri>__default__</uri>
              <name>__default__</name>
            </script>
          </material>
        </visual>
        <gravity>1</gravity>
        <velocity_decay/>
        <self_collide>0</self_collide>
        <gravity>1</gravity>
        <kinematic>0</kinematic>
      </link>
      <joint name='rear_right_2_joint' type='revolute'>
        <child>rear_right_2_Link</child>
        <parent>rear_right_1_Link</parent>
        <axis>
          <xyz>-4e-06 -1 -0.000485</xyz>
          <limit>
            <lower>-3</lower>
            <upper>3</upper>
            <effort>100</effort>
            <velocity>10</velocity>
          </limit>
          <dynamics>
            <spring_reference>0</spring_reference>
            <spring_stiffness>0</spring_stiffness>
          </dynamics>
          <use_parent_model_frame>1</use_parent_model_frame>
        </axis>
        <physics>
          <provide_feedback>1</provide_feedback>
          <ode>
            <provide_feedback>1</provide_feedback>
            <limit>
              <cfm>0</cfm>
              <erp>0.2</erp>
            </limit>
          </ode>
        </physics>
      </joint>
      <link name='rear_right_3_Link'>
        <pose frame=''>0.485701 0.229533 -0.234825 -0.52989 0.000487 -1.57081</pose>
        <inertial>
          <pose frame=''>-0.043271 -1e-05 -0.087821 0 -0 0</pose>
          <mass>1.3523</mass>
          <inertia>
            <ixx>0.0093381</ixx>
            <ixy>-2.3773e-08</ixy>
            <ixz>-0.00020532</ixz>
            <iyy>0.0091429</iyy>
            <iyz>-9.1579e-07</iyz>
            <izz>0.00053022</izz>
          </inertia>
        </inertial>
        <collision name='rear_right_3_Link_collision'>
          <pose frame=''>0 0 0 0 -0 0</pose>
          <geometry>
            <mesh>
              <scale>1 1 1</scale>
              <uri>/home/hitstar/catkin_ws_sim/src/simpleDog/meshes/rear_right_3_Link.STL</uri>
            </mesh>
          </geometry>
          <surface>
            <contact>
              <ode>
                <kp>1e+07</kp>
                <kd>1</kd>
              </ode>
            </contact>
            <friction>
              <ode>
                <mu>10</mu>
                <mu2>10</mu2>
                <fdir1>1 0 0</fdir1>
              </ode>
              <torsional>
                <ode/>
              </torsional>
            </friction>
            <bounce/>
          </surface>
          <max_contacts>10</max_contacts>
        </collision>
        <visual name='rear_right_3_Link_visual'>
          <pose frame=''>0 0 0 0 -0 0</pose>
          <geometry>
            <mesh>
              <scale>1 1 1</scale>
              <uri>/home/hitstar/catkin_ws_sim/src/simpleDog/meshes/rear_right_3_Link.STL</uri>
            </mesh>
          </geometry>
          <material>
            <script>
              <uri>__default__</uri>
              <name>__default__</name>
            </script>
          </material>
        </visual>
        <gravity>1</gravity>
        <velocity_decay/>
        <self_collide>0</self_collide>
        <gravity>1</gravity>
        <kinematic>0</kinematic>
      </link>
      <joint name='rear_right_3_joint' type='revolute'>
        <child>rear_right_3_Link</child>
        <parent>rear_right_2_Link</parent>
        <axis>
          <xyz>-1.1e-05 -1 -0.000487</xyz>
          <limit>
            <lower>-3</lower>
            <upper>3</upper>
            <effort>100</effort>
            <velocity>10</velocity>
          </limit>
          <dynamics>
            <spring_reference>0</spring_reference>
            <spring_stiffness>0</spring_stiffness>
          </dynamics>
          <use_parent_model_frame>1</use_parent_model_frame>
        </axis>
        <physics>
          <provide_feedback>1</provide_feedback>
          <ode>
            <provide_feedback>1</provide_feedback>
            <limit>
              <cfm>0</cfm>
              <erp>0.2</erp>
            </limit>
          </ode>
        </physics>
      </joint>
      <plugin name='gazebo_ros_control' filename='libgazebo_ros_control.so'>
        <robotNamespace>/</robotNamespace>
      </plugin>
      <plugin name='ft_sensor' filename='libgazebo_ros_ft_sensor.so'>
        <updateRate>100.0</updateRate>
        <topicName>front_left_1_joint_ft_feedback</topicName>
        <jointName>front_left_1_joint</jointName>
        <robotNamespace>/</robotNamespace>
      </plugin>
      <plugin name='ft_sensor' filename='libgazebo_ros_ft_sensor.so'>
        <updateRate>100.0</updateRate>
        <topicName>front_left_2_joint_ft_feedback</topicName>
        <jointName>front_left_2_joint</jointName>
        <robotNamespace>/</robotNamespace>
      </plugin>
      <plugin name='ft_sensor' filename='libgazebo_ros_ft_sensor.so'>
        <updateRate>100.0</updateRate>
        <topicName>front_left_3_joint_ft_feedback</topicName>
        <jointName>front_left_3_joint</jointName>
        <robotNamespace>/</robotNamespace>
      </plugin>
      <plugin name='ft_sensor' filename='libgazebo_ros_ft_sensor.so'>
        <updateRate>100.0</updateRate>
        <topicName>front_right_1_joint_ft_feedback</topicName>
        <jointName>front_right_1_joint</jointName>
        <robotNamespace>/</robotNamespace>
      </plugin>
      <plugin name='ft_sensor' filename='libgazebo_ros_ft_sensor.so'>
        <updateRate>100.0</updateRate>
        <topicName>front_right_2_joint_ft_feedback</topicName>
        <jointName>front_right_2_joint</jointName>
        <robotNamespace>/</robotNamespace>
      </plugin>
      <plugin name='ft_sensor' filename='libgazebo_ros_ft_sensor.so'>
        <updateRate>100.0</updateRate>
        <topicName>front_right_3_joint_ft_feedback</topicName>
        <jointName>front_right_3_joint</jointName>
        <robotNamespace>/</robotNamespace>
      </plugin>
      <plugin name='ft_sensor' filename='libgazebo_ros_ft_sensor.so'>
        <updateRate>100.0</updateRate>
        <topicName>rear_right_1_joint_ft_feedback</topicName>
        <jointName>rear_right_1_joint</jointName>
        <robotNamespace>/</robotNamespace>
      </plugin>
      <plugin name='ft_sensor' filename='libgazebo_ros_ft_sensor.so'>
        <updateRate>100.0</updateRate>
        <topicName>rear_right_2_joint_ft_feedback</topicName>
        <jointName>rear_right_2_joint</jointName>
        <robotNamespace>/</robotNamespace>
      </plugin>
      <plugin name='ft_sensor' filename='libgazebo_ros_ft_sensor.so'>
        <updateRate>100.0</updateRate>
        <topicName>rear_right_3_joint_ft_feedback</topicName>
        <jointName>rear_right_3_joint</jointName>
        <robotNamespace>/</robotNamespace>
      </plugin>
      <plugin name='ft_sensor' filename='libgazebo_ros_ft_sensor.so'>
        <updateRate>100.0</updateRate>
        <topicName>rear_left_1_joint_ft_feedback</topicName>
        <jointName>rear_left_1_joint</jointName>
        <robotNamespace>/</robotNamespace>
      </plugin>
      <plugin name='ft_sensor' filename='libgazebo_ros_ft_sensor.so'>
        <updateRate>100.0</updateRate>
        <topicName>rear_left_2_joint_ft_feedback</topicName>
        <jointName>rear_left_2_joint</jointName>
        <robotNamespace>/</robotNamespace>
      </plugin>
      <static>0</static>
      <plugin name='ft_sensor' filename='libgazebo_ros_ft_sensor.so'>
        <updateRate>100.0</updateRate>
        <topicName>rear_left_3_joint_ft_feedback</topicName>
        <jointName>rear_left_3_joint</jointName>
        <robotNamespace>/</robotNamespace>
      </plugin>
      <pose frame=''>0 0 0.5 0 -0 0</pose>
    </model>
    <model name='frc2016_field'>
      <static>1</static>
      <link name='walls'>
        <visual name='walls_visual'>
          <geometry>
            <mesh>
              <uri>model://frc2016_field/meshes/walls.dae</uri>
              <scale>1 1 1</scale>
            </mesh>
          </geometry>
        </visual>
        <collision name='front_turret'>
          <geometry>
            <mesh>
              <uri>model://frc2016_field/meshes/turret_collide.dae</uri>
              <scale>1 1 1</scale>
            </mesh>
          </geometry>
          <max_contacts>10</max_contacts>
          <surface>
            <contact>
              <ode/>
            </contact>
            <bounce/>
            <friction>
              <torsional>
                <ode/>
              </torsional>
              <ode/>
            </friction>
          </surface>
        </collision>
        <collision name='back_turret'>
          <pose frame=''>0 0 0 0 -0 3.1415</pose>
          <geometry>
            <mesh>
              <uri>model://frc2016_field/meshes/turret_collide.dae</uri>
              <scale>1 1 1</scale>
            </mesh>
          </geometry>
          <max_contacts>10</max_contacts>
          <surface>
            <contact>
              <ode/>
            </contact>
            <bounce/>
            <friction>
              <torsional>
                <ode/>
              </torsional>
              <ode/>
            </friction>
          </surface>
        </collision>
        <collision name='left_wall'>
          <pose frame=''>4.09997 0 0.2413 0 -0 0</pose>
          <geometry>
            <box>
              <size>0.1 16.4592 0.4826</size>
            </box>
          </geometry>
          <max_contacts>10</max_contacts>
          <surface>
            <contact>
              <ode/>
            </contact>
            <bounce/>
            <friction>
              <torsional>
                <ode/>
              </torsional>
              <ode/>
            </friction>
          </surface>
        </collision>
        <collision name='right_wall'>
          <pose frame=''>-4.09997 0 0.2413 0 -0 0</pose>
          <geometry>
            <box>
              <size>0.1 16.4592 0.4826</size>
            </box>
          </geometry>
          <max_contacts>10</max_contacts>
          <surface>
            <contact>
              <ode/>
            </contact>
            <bounce/>
            <friction>
              <torsional>
                <ode/>
              </torsional>
              <ode/>
            </friction>
          </surface>
        </collision>
        <collision name='front_solid_wall'>
          <pose frame=''>-2.2105 8.2196 1 0 -0 0</pose>
          <geometry>
            <box>
              <size>3.8 0.1 2</size>
            </box>
          </geometry>
          <max_contacts>10</max_contacts>
          <surface>
            <contact>
              <ode/>
            </contact>
            <bounce/>
            <friction>
              <torsional>
                <ode/>
              </torsional>
              <ode/>
            </friction>
          </surface>
        </collision>
        <collision name='back_solid_wall'>
          <pose frame=''>2.2105 -8.2196 1 0 -0 0</pose>
          <geometry>
            <box>
              <size>3.8 0.1 2</size>
            </box>
          </geometry>
          <max_contacts>10</max_contacts>
          <surface>
            <contact>
              <ode/>
            </contact>
            <bounce/>
            <friction>
              <torsional>
                <ode/>
              </torsional>
              <ode/>
            </friction>
          </surface>
        </collision>
        <collision name='front_partial_wall'>
          <pose frame=''>1.85 8.2196 1 0 -0 0</pose>
          <geometry>
            <box>
              <size>2.1 0.1 2</size>
            </box>
          </geometry>
          <max_contacts>10</max_contacts>
          <surface>
            <contact>
              <ode/>
            </contact>
            <bounce/>
            <friction>
              <torsional>
                <ode/>
              </torsional>
              <ode/>
            </friction>
          </surface>
        </collision>
        <collision name='front_partial_wall_mid'>
          <pose frame=''>3.4 8.2196 0.86 0 -0 0</pose>
          <geometry>
            <box>
              <size>1.25 0.1 1.12</size>
            </box>
          </geometry>
          <max_contacts>10</max_contacts>
          <surface>
            <contact>
              <ode/>
            </contact>
            <bounce/>
            <friction>
              <torsional>
                <ode/>
              </torsional>
              <ode/>
            </friction>
          </surface>
        </collision>
        <collision name='front_partial_wall_lower_left'>
          <pose frame=''>3.36 8.2196 0.25 0 -0 0</pose>
          <geometry>
            <box>
              <size>0.3 0.1 0.5</size>
            </box>
          </geometry>
          <max_contacts>10</max_contacts>
          <surface>
            <contact>
              <ode/>
            </contact>
            <bounce/>
            <friction>
              <torsional>
                <ode/>
              </torsional>
              <ode/>
            </friction>
          </surface>
        </collision>
        <collision name='front_partial_wall_lower_right'>
          <pose frame=''>4 8.2196 0.25 0 -0 0</pose>
          <geometry>
            <box>
              <size>0.3 0.1 0.5</size>
            </box>
          </geometry>
          <max_contacts>10</max_contacts>
          <surface>
            <contact>
              <ode/>
            </contact>
            <bounce/>
            <friction>
              <torsional>
                <ode/>
              </torsional>
              <ode/>
            </friction>
          </surface>
        </collision>
        <collision name='front_partial_wall_upper_right'>
          <pose frame=''>3.76 8.2196 1.7 0 -0 0</pose>
          <geometry>
            <box>
              <size>0.54 0.1 0.6</size>
            </box>
          </geometry>
          <max_contacts>10</max_contacts>
          <surface>
            <contact>
              <ode/>
            </contact>
            <bounce/>
            <friction>
              <torsional>
                <ode/>
              </torsional>
              <ode/>
            </friction>
          </surface>
        </collision>
        <collision name='front_partial_wall_upper_left'>
          <pose frame=''>2.95 8.2196 1.7 0 -0 0</pose>
          <geometry>
            <box>
              <size>0.54 0.1 0.6</size>
            </box>
          </geometry>
          <max_contacts>10</max_contacts>
          <surface>
            <contact>
              <ode/>
            </contact>
            <bounce/>
            <friction>
              <torsional>
                <ode/>
              </torsional>
              <ode/>
            </friction>
          </surface>
        </collision>
        <collision name='front_partial_wall_upper_mid'>
          <pose frame=''>3.36 8.2196 1.84 0 -0 0</pose>
          <geometry>
            <box>
              <size>0.3 0.1 0.3</size>
            </box>
          </geometry>
          <max_contacts>10</max_contacts>
          <surface>
            <contact>
              <ode/>
            </contact>
            <bounce/>
            <friction>
              <torsional>
                <ode/>
              </torsional>
              <ode/>
            </friction>
          </surface>
        </collision>
        <collision name='back_partial_wall'>
          <pose frame=''>-1.85 -8.2196 1 0 -0 0</pose>
          <geometry>
            <box>
              <size>2.1 0.1 2</size>
            </box>
          </geometry>
          <max_contacts>10</max_contacts>
          <surface>
            <contact>
              <ode/>
            </contact>
            <bounce/>
            <friction>
              <torsional>
                <ode/>
              </torsional>
              <ode/>
            </friction>
          </surface>
        </collision>
        <collision name='back_partial_wall_mid'>
          <pose frame=''>-3.4 -8.2196 0.86 0 -0 0</pose>
          <geometry>
            <box>
              <size>1.25 0.1 1.12</size>
            </box>
          </geometry>
          <max_contacts>10</max_contacts>
          <surface>
            <contact>
              <ode/>
            </contact>
            <bounce/>
            <friction>
              <torsional>
                <ode/>
              </torsional>
              <ode/>
            </friction>
          </surface>
        </collision>
        <collision name='back_partial_wall_lower_left'>
          <pose frame=''>-3.36 -8.2196 0.25 0 -0 0</pose>
          <geometry>
            <box>
              <size>0.3 0.1 0.5</size>
            </box>
          </geometry>
          <max_contacts>10</max_contacts>
          <surface>
            <contact>
              <ode/>
            </contact>
            <bounce/>
            <friction>
              <torsional>
                <ode/>
              </torsional>
              <ode/>
            </friction>
          </surface>
        </collision>
        <collision name='back_partial_wall_lower_right'>
          <pose frame=''>-4 -8.2196 0.25 0 -0 0</pose>
          <geometry>
            <box>
              <size>0.3 0.1 0.5</size>
            </box>
          </geometry>
          <max_contacts>10</max_contacts>
          <surface>
            <contact>
              <ode/>
            </contact>
            <bounce/>
            <friction>
              <torsional>
                <ode/>
              </torsional>
              <ode/>
            </friction>
          </surface>
        </collision>
        <collision name='back_partial_wall_upper_right'>
          <pose frame=''>-3.76 -8.2196 1.7 0 -0 0</pose>
          <geometry>
            <box>
              <size>0.54 0.1 0.6</size>
            </box>
          </geometry>
          <max_contacts>10</max_contacts>
          <surface>
            <contact>
              <ode/>
            </contact>
            <bounce/>
            <friction>
              <torsional>
                <ode/>
              </torsional>
              <ode/>
            </friction>
          </surface>
        </collision>
        <collision name='back_partial_wall_upper_left'>
          <pose frame=''>-2.95 -8.2196 1.7 0 -0 0</pose>
          <geometry>
            <box>
              <size>0.54 0.1 0.6</size>
            </box>
          </geometry>
          <max_contacts>10</max_contacts>
          <surface>
            <contact>
              <ode/>
            </contact>
            <bounce/>
            <friction>
              <torsional>
                <ode/>
              </torsional>
              <ode/>
            </friction>
          </surface>
        </collision>
        <collision name='back_partial_wall_upper_mid'>
          <pose frame=''>-3.36 -8.2196 1.84 0 -0 0</pose>
          <geometry>
            <box>
              <size>0.3 0.1 0.3</size>
            </box>
          </geometry>
          <max_contacts>10</max_contacts>
          <surface>
            <contact>
              <ode/>
            </contact>
            <bounce/>
            <friction>
              <torsional>
                <ode/>
              </torsional>
              <ode/>
            </friction>
          </surface>
        </collision>
        <visual name='blue_passage_border_long'>
          <pose frame=''>2.72665 4.5882 0.0127 0 -0 0</pose>
          <geometry>
            <box>
              <size>0.0762 7.3025 0.0254</size>
            </box>
          </geometry>
          <material>
            <ambient>0 0 1 1</ambient>
            <diffuse>0 0 1 1</diffuse>
          </material>
        </visual>
        <collision name='blue_passage_border_long'>
          <pose frame=''>2.72665 4.5882 0.0127 0 -0 0</pose>
          <geometry>
            <box>
              <size>0.0762 7.3025 0.0254</size>
            </box>
          </geometry>
          <max_contacts>10</max_contacts>
          <surface>
            <contact>
              <ode/>
            </contact>
            <bounce/>
            <friction>
              <torsional>
                <ode/>
              </torsional>
              <ode/>
            </friction>
          </surface>
        </collision>
        <visual name='blue_passage_border_short'>
          <pose frame=''>3.37435 0.97352 0.0127 0 -0 0</pose>
          <geometry>
            <box>
              <size>1.37165 0.0762 0.0254</size>
            </box>
          </geometry>
          <material>
            <ambient>0 0 1 1</ambient>
            <diffuse>0 0 1 1</diffuse>
          </material>
        </visual>
        <collision name='blue_passage_border_short'>
          <pose frame=''>3.37435 0.97352 0.0127 0 -0 0</pose>
          <geometry>
            <box>
              <size>1.37165 0.0762 0.0254</size>
            </box>
          </geometry>
          <max_contacts>10</max_contacts>
          <surface>
            <contact>
              <ode/>
            </contact>
            <bounce/>
            <friction>
              <torsional>
                <ode/>
              </torsional>
              <ode/>
            </friction>
          </surface>
        </collision>
        <visual name='blue_divider_1'>
          <pose frame=''>2.63052 2.80648 0.31114 0 -0 0</pose>
          <geometry>
            <box>
              <size>0.009525 1.2192 0.6096</size>
            </box>
          </geometry>
        </visual>
        <collision name='blue_divider_1'>
          <pose frame=''>2.63052 2.80648 0.31114 0 -0 0</pose>
          <geometry>
            <box>
              <size>0.009525 1.2192 0.6096</size>
            </box>
          </geometry>
          <max_contacts>10</max_contacts>
          <surface>
            <contact>
              <ode/>
            </contact>
            <bounce/>
            <friction>
              <torsional>
                <ode/>
              </torsional>
              <ode/>
            </friction>
          </surface>
        </collision>
        <visual name='blue_divider_2'>
          <pose frame=''>1.28432 2.80648 0.31114 0 -0 0</pose>
          <geometry>
            <box>
              <size>0.009525 1.2192 0.6096</size>
            </box>
          </geometry>
        </visual>
        <collision name='blue_divider_2'>
          <pose frame=''>1.28432 2.80648 0.31114 0 -0 0</pose>
          <geometry>
            <box>
              <size>0.009525 1.2192 0.6096</size>
            </box>
          </geometry>
          <max_contacts>10</max_contacts>
          <surface>
            <contact>
              <ode/>
            </contact>
            <bounce/>
            <friction>
              <torsional>
                <ode/>
              </torsional>
              <ode/>
            </friction>
          </surface>
        </collision>
        <visual name='blue_divider_3'>
          <pose frame=''>-0.06189 2.80648 0.31114 0 -0 0</pose>
          <geometry>
            <box>
              <size>0.009525 1.2192 0.6096</size>
            </box>
          </geometry>
        </visual>
        <collision name='blue_divider_3'>
          <pose frame=''>-0.06189 2.80648 0.31114 0 -0 0</pose>
          <geometry>
            <box>
              <size>0.009525 1.2192 0.6096</size>
            </box>
          </geometry>
          <max_contacts>10</max_contacts>
          <surface>
            <contact>
              <ode/>
            </contact>
            <bounce/>
            <friction>
              <torsional>
                <ode/>
              </torsional>
              <ode/>
            </friction>
          </surface>
        </collision>
        <visual name='blue_divider_4'>
          <pose frame=''>-1.40809 2.80648 0.31114 0 -0 0</pose>
          <geometry>
            <box>
              <size>0.009525 1.2192 0.6096</size>
            </box>
          </geometry>
        </visual>
        <collision name='blue_divider_4'>
          <pose frame=''>-1.40809 2.80648 0.31114 0 -0 0</pose>
          <geometry>
            <box>
              <size>0.009525 1.2192 0.6096</size>
            </box>
          </geometry>
          <max_contacts>10</max_contacts>
          <surface>
            <contact>
              <ode/>
            </contact>
            <bounce/>
            <friction>
              <torsional>
                <ode/>
              </torsional>
              <ode/>
            </friction>
          </surface>
        </collision>
        <visual name='blue_divider_5'>
          <pose frame=''>-2.75428 2.80648 0.31114 0 -0 0</pose>
          <geometry>
            <box>
              <size>0.009525 1.2192 0.6096</size>
            </box>
          </geometry>
        </visual>
        <collision name='blue_divider_5'>
          <pose frame=''>-2.75428 2.80648 0.31114 0 -0 0</pose>
          <geometry>
            <box>
              <size>0.009525 1.2192 0.6096</size>
            </box>
          </geometry>
          <max_contacts>10</max_contacts>
          <surface>
            <contact>
              <ode/>
            </contact>
            <bounce/>
            <friction>
              <torsional>
                <ode/>
              </torsional>
              <ode/>
            </friction>
          </surface>
        </collision>
        <visual name='blue_barrier_ramp_up'>
          <pose frame=''>-0.7334 3.22301 0.05063 -0.248866 0 0</pose>
          <geometry>
            <box>
              <size>6.71817 0.3048 0.00635</size>
            </box>
          </geometry>
        </visual>
        <collision name='blue_barrier_ramp_up'>
          <pose frame=''>-0.7334 3.22301 0.05063 -0.248866 0 0</pose>
          <geometry>
            <box>
              <size>6.71817 0.3048 0.00635</size>
            </box>
          </geometry>
          <max_contacts>10</max_contacts>
          <surface>
            <contact>
              <ode/>
            </contact>
            <bounce/>
            <friction>
              <torsional>
                <ode/>
              </torsional>
              <ode/>
            </friction>
          </surface>
        </collision>
        <visual name='blue_barrier_ramp_down'>
          <pose frame=''>-0.7334 2.31802 0.05063 0.248866 -0 0</pose>
          <geometry>
            <box>
              <size>6.71817 0.3048 0.00635</size>
            </box>
          </geometry>
        </visual>
        <collision name='blue_barrier_ramp_down'>
          <pose frame=''>-0.7334 2.31802 0.05063 0.248866 -0 0</pose>
          <geometry>
            <box>
              <size>6.71817 0.3048 0.00635</size>
            </box>
          </geometry>
          <max_contacts>10</max_contacts>
          <surface>
            <contact>
              <ode/>
            </contact>
            <bounce/>
            <friction>
              <torsional>
                <ode/>
              </torsional>
              <ode/>
            </friction>
          </surface>
        </collision>
        <visual name='red_passage_border_long'>
          <pose frame=''>-2.7273 -4.58839 0.0127 0 -0 0</pose>
          <geometry>
            <box>
              <size>0.0762 7.3025 0.0254</size>
            </box>
          </geometry>
          <material>
            <ambient>1 0 0 1</ambient>
            <diffuse>1 0 0 1</diffuse>
          </material>
        </visual>
        <collision name='red_passage_border_long'>
          <pose frame=''>-2.7273 -4.58839 0.0127 0 -0 0</pose>
          <geometry>
            <box>
              <size>0.0762 7.3025 0.0254</size>
            </box>
          </geometry>
          <max_contacts>10</max_contacts>
          <surface>
            <contact>
              <ode/>
            </contact>
            <bounce/>
            <friction>
              <torsional>
                <ode/>
              </torsional>
              <ode/>
            </friction>
          </surface>
        </collision>
        <visual name='red_passage_border_short'>
          <pose frame=''>-3.375 -0.97372 0.0127 0 -0 0</pose>
          <geometry>
            <box>
              <size>1.37165 0.0762 0.0254</size>
            </box>
          </geometry>
          <material>
            <ambient>1 0 0 1</ambient>
            <diffuse>1 0 0 1</diffuse>
          </material>
        </visual>
        <collision name='red_passage_border_short'>
          <pose frame=''>-3.375 -0.97372 0.0127 0 -0 0</pose>
          <geometry>
            <box>
              <size>1.37165 0.0762 0.0254</size>
            </box>
          </geometry>
          <max_contacts>10</max_contacts>
          <surface>
            <contact>
              <ode/>
            </contact>
            <bounce/>
            <friction>
              <torsional>
                <ode/>
              </torsional>
              <ode/>
            </friction>
          </surface>
        </collision>
        <visual name='red_divider_1'>
          <pose frame=''>-2.63117 -2.76442 0.31114 0 -0 0</pose>
          <geometry>
            <box>
              <size>0.009525 1.2192 0.6096</size>
            </box>
          </geometry>
        </visual>
        <collision name='red_divider_1'>
          <pose frame=''>-2.63117 -2.72845 0.31114 0 -0 0</pose>
          <geometry>
            <box>
              <size>0.009525 1.2192 0.6096</size>
            </box>
          </geometry>
          <max_contacts>10</max_contacts>
          <surface>
            <contact>
              <ode/>
            </contact>
            <bounce/>
            <friction>
              <torsional>
                <ode/>
              </torsional>
              <ode/>
            </friction>
          </surface>
        </collision>
        <visual name='red_divider_2'>
          <pose frame=''>-1.28496 -2.76442 0.31114 0 -0 0</pose>
          <geometry>
            <box>
              <size>0.009525 1.2192 0.6096</size>
            </box>
          </geometry>
        </visual>
        <collision name='red_divider_2'>
          <pose frame=''>-1.28496 -2.76442 0.31114 0 -0 0</pose>
          <geometry>
            <box>
              <size>0.009525 1.2192 0.6096</size>
            </box>
          </geometry>
          <max_contacts>10</max_contacts>
          <surface>
            <contact>
              <ode/>
            </contact>
            <bounce/>
            <friction>
              <torsional>
                <ode/>
              </torsional>
              <ode/>
            </friction>
          </surface>
        </collision>
        <visual name='red_divider_3'>
          <pose frame=''>0.06124 -2.76442 0.31114 0 -0 0</pose>
          <geometry>
            <box>
              <size>0.009525 1.2192 0.6096</size>
            </box>
          </geometry>
        </visual>
        <collision name='red_divider_3'>
          <pose frame=''>0.06124 -2.76442 0.31114 0 -0 0</pose>
          <geometry>
            <box>
              <size>0.009525 1.2192 0.6096</size>
            </box>
          </geometry>
          <max_contacts>10</max_contacts>
          <surface>
            <contact>
              <ode/>
            </contact>
            <bounce/>
            <friction>
              <torsional>
                <ode/>
              </torsional>
              <ode/>
            </friction>
          </surface>
        </collision>
        <visual name='red_divider_4'>
          <pose frame=''>1.40744 -2.76442 0.31114 0 -0 0</pose>
          <geometry>
            <box>
              <size>0.009525 1.2192 0.6096</size>
            </box>
          </geometry>
        </visual>
        <collision name='red_divider_4'>
          <pose frame=''>1.40744 -2.76442 0.31114 0 -0 0</pose>
          <geometry>
            <box>
              <size>0.009525 1.2192 0.6096</size>
            </box>
          </geometry>
          <max_contacts>10</max_contacts>
          <surface>
            <contact>
              <ode/>
            </contact>
            <bounce/>
            <friction>
              <torsional>
                <ode/>
              </torsional>
              <ode/>
            </friction>
          </surface>
        </collision>
        <visual name='red_divider_5'>
          <pose frame=''>2.75363 -2.76442 0.31114 0 -0 0</pose>
          <geometry>
            <box>
              <size>0.009525 1.2192 0.6096</size>
            </box>
          </geometry>
        </visual>
        <collision name='red_divider_5'>
          <pose frame=''>2.75363 -2.76442 0.31114 0 -0 0</pose>
          <geometry>
            <box>
              <size>0.009525 1.2192 0.6096</size>
            </box>
          </geometry>
          <max_contacts>10</max_contacts>
          <surface>
            <contact>
              <ode/>
            </contact>
            <bounce/>
            <friction>
              <torsional>
                <ode/>
              </torsional>
              <ode/>
            </friction>
          </surface>
        </collision>
        <visual name='red_barrier_ramp_down'>
          <pose frame=''>0.73275 -2.31261 0.05063 -0.248866 0 0</pose>
          <geometry>
            <box>
              <size>6.71817 0.3048 0.00635</size>
            </box>
          </geometry>
        </visual>
        <collision name='red_barrier_ramp_down'>
          <pose frame=''>0.73275 -2.31261 0.05063 -0.248866 0 0</pose>
          <geometry>
            <box>
              <size>6.71817 0.3048 0.00635</size>
            </box>
          </geometry>
          <max_contacts>10</max_contacts>
          <surface>
            <contact>
              <ode/>
            </contact>
            <bounce/>
            <friction>
              <torsional>
                <ode/>
              </torsional>
              <ode/>
            </friction>
          </surface>
        </collision>
        <visual name='red_barrier_ramp_up'>
          <pose frame=''>0.73275 -3.21691 0.05063 0.248866 -0 0</pose>
          <geometry>
            <box>
              <size>6.71817 0.3048 0.00635</size>
            </box>
          </geometry>
        </visual>
        <collision name='red_barrier_ramp_up'>
          <pose frame=''>0.73275 -3.21691 0.05063 0.248866 -0 0</pose>
          <geometry>
            <box>
              <size>6.71817 0.3048 0.00635</size>
            </box>
          </geometry>
          <max_contacts>10</max_contacts>
          <surface>
            <contact>
              <ode/>
            </contact>
            <bounce/>
            <friction>
              <torsional>
                <ode/>
              </torsional>
              <ode/>
            </friction>
          </surface>
        </collision>
        <self_collide>0</self_collide>
        <kinematic>0</kinematic>
        <gravity>1</gravity>
      </link>
      <pose frame=''>0.932876 -0.11768 0 0 -0 0</pose>
    </model>
    <model name='lumber_4x4x20'>
      <link name='link'>
        <inertial>
          <mass>1.37</mass>
          <inertia>
            <ixx>0.0018</ixx>
            <ixy>0</ixy>
            <ixz>0</ixz>
            <iyy>0.0303</iyy>
            <iyz>0</iyz>
            <izz>0.0303</izz>
          </inertia>
        </inertial>
        <collision name='collision'>
          <geometry>
            <box>
              <size>0.508 0.0888 0.0888</size>
            </box>
          </geometry>
          <surface>
            <bounce>
              <restitution_coefficient>0</restitution_coefficient>
              <threshold>2</threshold>
            </bounce>
            <friction>
              <ode>
                <mu>10</mu>
                <mu2>10</mu2>
              </ode>
              <torsional>
                <ode/>
              </torsional>
            </friction>
            <contact>
              <ode>
                <soft_cfm>0.001</soft_cfm>
                <kp>100000</kp>
                <kd>1000</kd>
              </ode>
            </contact>
          </surface>
          <max_contacts>10</max_contacts>
        </collision>
        <visual name='visual'>
          <geometry>
            <mesh>
              <uri>model://drc_practice_4x4x20/meshes/4x4x20.dae</uri>
              <scale>1 1 1</scale>
            </mesh>
          </geometry>
        </visual>
        <self_collide>0</self_collide>
        <kinematic>0</kinematic>
        <gravity>1</gravity>
      </link>
      <pose frame=''>0.890607 -0.382046 0 0 -0 0</pose>
    </model>
    <model name='lumber_4x4x20_0'>
      <link name='link'>
        <inertial>
          <mass>1.37</mass>
          <inertia>
            <ixx>0.0018</ixx>
            <ixy>0</ixy>
            <ixz>0</ixz>
            <iyy>0.0303</iyy>
            <iyz>0</iyz>
            <izz>0.0303</izz>
          </inertia>
        </inertial>
        <collision name='collision'>
          <geometry>
            <box>
              <size>0.508 0.0888 0.0888</size>
            </box>
          </geometry>
          <surface>
            <bounce>
              <restitution_coefficient>0</restitution_coefficient>
              <threshold>2</threshold>
            </bounce>
            <friction>
              <ode>
                <mu>10</mu>
                <mu2>10</mu2>
              </ode>
              <torsional>
                <ode/>
              </torsional>
            </friction>
            <contact>
              <ode>
                <soft_cfm>0.001</soft_cfm>
                <kp>100000</kp>
                <kd>1000</kd>
              </ode>
            </contact>
          </surface>
          <max_contacts>10</max_contacts>
        </collision>
        <visual name='visual'>
          <geometry>
            <mesh>
              <uri>model://drc_practice_4x4x20/meshes/4x4x20.dae</uri>
              <scale>1 1 1</scale>
            </mesh>
          </geometry>
        </visual>
        <self_collide>0</self_collide>
        <kinematic>0</kinematic>
        <gravity>1</gravity>
      </link>
      <pose frame=''>0.149124 -0.894597 0 0 -0 0</pose>
    </model>
    <model name='lumber_2x4x48'>
      <link name='link'>
        <inertial>
          <mass>1.4111</mass>
          <inertia>
            <ixx>0.0011</ixx>
            <ixy>0</ixy>
            <ixz>0</ixz>
            <iyy>0.1771</iyy>
            <iyz>0</iyz>
            <izz>0.1763</izz>
          </inertia>
        </inertial>
        <collision name='collision'>
          <geometry>
            <box>
              <size>1.2192 0.038 0.0888</size>
            </box>
          </geometry>
          <surface>
            <bounce>
              <restitution_coefficient>0.01</restitution_coefficient>
              <threshold>5</threshold>
            </bounce>
            <friction>
              <ode>
                <mu>5</mu>
                <mu2>5</mu2>
              </ode>
              <torsional>
                <ode/>
              </torsional>
            </friction>
            <contact>
              <ode>
                <soft_cfm>0.001</soft_cfm>
                <kp>10000</kp>
                <kd>1000</kd>
                <max_vel>0.01</max_vel>
                <min_depth>0.001</min_depth>
              </ode>
            </contact>
          </surface>
          <max_contacts>10</max_contacts>
        </collision>
        <visual name='visual'>
          <geometry>
            <mesh>
              <uri>model://drc_practice_2x4/meshes/2x4x48.dae</uri>
              <scale>1 1 1</scale>
            </mesh>
          </geometry>
        </visual>
        <self_collide>0</self_collide>
        <kinematic>0</kinematic>
        <gravity>1</gravity>
      </link>
      <pose frame=''>1.0783 0.60559 0 0 -0 0</pose>
    </model>
    <model name='lumber_2x6x48'>
      <link name='link'>
        <self_collide>0</self_collide>
        <inertial>
          <mass>2.22</mass>
          <inertia>
            <ixx>0.0039</ixx>
            <ixy>0</ixy>
            <ixz>0</ixz>
            <iyy>0.28</iyy>
            <iyz>0</iyz>
            <izz>0.2766</izz>
          </inertia>
        </inertial>
        <collision name='collision'>
          <geometry>
            <box>
              <size>1.2192 0.038 0.1396</size>
            </box>
          </geometry>
          <surface>
            <bounce>
              <restitution_coefficient>0.01</restitution_coefficient>
              <threshold>5</threshold>
            </bounce>
            <friction>
              <ode>
                <mu>5</mu>
                <mu2>5</mu2>
              </ode>
              <torsional>
                <ode/>
              </torsional>
            </friction>
            <contact>
              <ode>
                <soft_cfm>0.01</soft_cfm>
                <kp>10000</kp>
                <kd>1000</kd>
                <min_depth>0.001</min_depth>
              </ode>
            </contact>
          </surface>
          <max_contacts>10</max_contacts>
        </collision>
        <visual name='visual'>
          <geometry>
            <mesh>
              <uri>model://drc_practice_2x6/meshes/2x6x48.dae</uri>
              <scale>1 1 1</scale>
            </mesh>
          </geometry>
        </visual>
        <kinematic>0</kinematic>
        <gravity>1</gravity>
      </link>
      <pose frame=''>1.58397 -1.10665 0 0 -0 0</pose>
    </model>
    <model name='wood_slats'>
      <static>1</static>
      <link name='link'>
        <collision name='collision'>
          <geometry>
            <mesh>
              <uri>model://drc_practice_wood_slats/meshes/wood_slats.dae</uri>
              <scale>1 1 1</scale>
            </mesh>
          </geometry>
          <surface>
            <bounce>
              <restitution_coefficient>0.01</restitution_coefficient>
              <threshold>5</threshold>
            </bounce>
            <friction>
              <ode>
                <mu>5</mu>
                <mu2>5</mu2>
              </ode>
              <torsional>
                <ode/>
              </torsional>
            </friction>
            <contact>
              <ode>
                <soft_cfm>0.001</soft_cfm>
                <kp>10000</kp>
                <kd>1000</kd>
                <max_vel>0.01</max_vel>
                <min_depth>0.001</min_depth>
              </ode>
            </contact>
          </surface>
          <max_contacts>10</max_contacts>
        </collision>
        <visual name='visual'>
          <geometry>
            <mesh>
              <uri>model://drc_practice_wood_slats/meshes/wood_slats.dae</uri>
              <scale>1 1 1</scale>
            </mesh>
          </geometry>
        </visual>
        <self_collide>0</self_collide>
        <kinematic>0</kinematic>
        <gravity>1</gravity>
      </link>
      <pose frame=''>2.19663 -1.94952 0 0 -0 0</pose>
    </model>
    <model name='truss'>
      <link name='link'>
        <inertial>
          <mass>20.7307</mass>
          <inertia>
            <ixx>4.7978</ixx>
            <ixy>0</ixy>
            <ixz>0</ixz>
            <iyy>0.4699</iyy>
            <iyz>-0.002</iyz>
            <izz>4.7978</izz>
          </inertia>
        </inertial>
        <collision name='collision'>
          <geometry>
            <mesh>
              <uri>model://drc_practice_truss/meshes/truss.dae</uri>
              <scale>1 1 1</scale>
            </mesh>
          </geometry>
          <surface>
            <bounce>
              <restitution_coefficient>0</restitution_coefficient>
              <threshold>100000</threshold>
            </bounce>
            <friction>
              <ode>
                <mu>10</mu>
                <mu2>10</mu2>
              </ode>
              <torsional>
                <ode/>
              </torsional>
            </friction>
            <contact>
              <ode/>
            </contact>
          </surface>
          <max_contacts>10</max_contacts>
        </collision>
        <visual name='visual'>
          <geometry>
            <mesh>
              <uri>model://drc_practice_truss/meshes/truss.dae</uri>
              <scale>1 1 1</scale>
            </mesh>
          </geometry>
        </visual>
        <self_collide>0</self_collide>
        <kinematic>0</kinematic>
        <gravity>1</gravity>
      </link>
      <pose frame=''>0.376479 -1.0815 0 0 -0 0</pose>
    </model>
    <model name='frc2016_roughterrain'>
      <static>1</static>
      <link name='link'>
        <visual name='platform'>
          <pose frame=''>0 0 0.08269 0 -0 0</pose>
          <geometry>
            <box>
              <size>1.27 0.5969 0.003175</size>
            </box>
          </geometry>
        </visual>
        <collision name='platform'>
          <pose frame=''>0 0 0.08269 0 -0 0</pose>
          <geometry>
            <box>
              <size>1.27 0.5969 0.003175</size>
            </box>
          </geometry>
          <max_contacts>10</max_contacts>
          <surface>
            <contact>
              <ode/>
            </contact>
            <bounce/>
            <friction>
              <torsional>
                <ode/>
              </torsional>
              <ode/>
            </friction>
          </surface>
        </collision>
        <visual name='row1_block1_sm'>
          <pose frame=''>0.51435 0.1143 0.09698 0 -0 0</pose>
          <geometry>
            <box>
              <size>0.0762 0.0762 0.0254</size>
            </box>
          </geometry>
        </visual>
        <collision name='row1_block1_sm'>
          <pose frame=''>0.51435 0.1143 0.09698 0 -0 0</pose>
          <geometry>
            <box>
              <size>0.0762 0.0762 0.0254</size>
            </box>
          </geometry>
          <max_contacts>10</max_contacts>
          <surface>
            <contact>
              <ode/>
            </contact>
            <bounce/>
            <friction>
              <torsional>
                <ode/>
              </torsional>
              <ode/>
            </friction>
          </surface>
        </collision>
        <visual name='row1_block2_lg'>
          <pose frame=''>0.40005 0.1143 0.12238 0 -0 0</pose>
          <geometry>
            <box>
              <size>0.0762 0.0762 0.0762</size>
            </box>
          </geometry>
        </visual>
        <collision name='row1_block2_lg'>
          <pose frame=''>0.40005 0.1143 0.12238 0 -0 0</pose>
          <geometry>
            <box>
              <size>0.0762 0.0762 0.0762</size>
            </box>
          </geometry>
          <max_contacts>10</max_contacts>
          <surface>
            <contact>
              <ode/>
            </contact>
            <bounce/>
            <friction>
              <torsional>
                <ode/>
              </torsional>
              <ode/>
            </friction>
          </surface>
        </collision>
        <visual name='row1_block3_md'>
          <pose frame=''>0.28575 0.1143 0.10968 0 -0 0</pose>
          <geometry>
            <box>
              <size>0.0762 0.0762 0.0508</size>
            </box>
          </geometry>
        </visual>
        <collision name='row1_block3_md'>
          <pose frame=''>0.28575 0.1143 0.10968 0 -0 0</pose>
          <geometry>
            <box>
              <size>0.0762 0.0762 0.0508</size>
            </box>
          </geometry>
          <max_contacts>10</max_contacts>
          <surface>
            <contact>
              <ode/>
            </contact>
            <bounce/>
            <friction>
              <torsional>
                <ode/>
              </torsional>
              <ode/>
            </friction>
          </surface>
        </collision>
        <visual name='row1_block4_sm'>
          <pose frame=''>0.17145 0.1143 0.09698 0 -0 0</pose>
          <geometry>
            <box>
              <size>0.0762 0.0762 0.0254</size>
            </box>
          </geometry>
        </visual>
        <collision name='row1_block4_sm'>
          <pose frame=''>0.17145 0.1143 0.09698 0 -0 0</pose>
          <geometry>
            <box>
              <size>0.0762 0.0762 0.0254</size>
            </box>
          </geometry>
          <max_contacts>10</max_contacts>
          <surface>
            <contact>
              <ode/>
            </contact>
            <bounce/>
            <friction>
              <torsional>
                <ode/>
              </torsional>
              <ode/>
            </friction>
          </surface>
        </collision>
        <visual name='row1_block5_md'>
          <pose frame=''>0.05715 0.1143 0.10968 0 -0 0</pose>
          <geometry>
            <box>
              <size>0.0762 0.0762 0.0508</size>
            </box>
          </geometry>
        </visual>
        <collision name='row1_block5_md'>
          <pose frame=''>0.05715 0.1143 0.10968 0 -0 0</pose>
          <geometry>
            <box>
              <size>0.0762 0.0762 0.0508</size>
            </box>
          </geometry>
          <max_contacts>10</max_contacts>
          <surface>
            <contact>
              <ode/>
            </contact>
            <bounce/>
            <friction>
              <torsional>
                <ode/>
              </torsional>
              <ode/>
            </friction>
          </surface>
        </collision>
        <visual name='row1_block6_lg'>
          <pose frame=''>-0.05715 0.1143 0.12238 0 -0 0</pose>
          <geometry>
            <box>
              <size>0.0762 0.0762 0.0762</size>
            </box>
          </geometry>
        </visual>
        <collision name='row1_block6_lg'>
          <pose frame=''>-0.05715 0.1143 0.12238 0 -0 0</pose>
          <geometry>
            <box>
              <size>0.0762 0.0762 0.0762</size>
            </box>
          </geometry>
          <max_contacts>10</max_contacts>
          <surface>
            <contact>
              <ode/>
            </contact>
            <bounce/>
            <friction>
              <torsional>
                <ode/>
              </torsional>
              <ode/>
            </friction>
          </surface>
        </collision>
        <visual name='row1_block7_sm'>
          <pose frame=''>-0.17145 0.1143 0.09698 0 -0 0</pose>
          <geometry>
            <box>
              <size>0.0762 0.0762 0.0254</size>
            </box>
          </geometry>
        </visual>
        <collision name='row1_block7_sm'>
          <pose frame=''>-0.17145 0.1143 0.09698 0 -0 0</pose>
          <geometry>
            <box>
              <size>0.0762 0.0762 0.0254</size>
            </box>
          </geometry>
          <max_contacts>10</max_contacts>
          <surface>
            <contact>
              <ode/>
            </contact>
            <bounce/>
            <friction>
              <torsional>
                <ode/>
              </torsional>
              <ode/>
            </friction>
          </surface>
        </collision>
        <visual name='row1_block8_sm'>
          <pose frame=''>-0.28575 0.1143 0.09698 0 -0 0</pose>
          <geometry>
            <box>
              <size>0.0762 0.0762 0.0254</size>
            </box>
          </geometry>
        </visual>
        <collision name='row1_block8_sm'>
          <pose frame=''>-0.28575 0.1143 0.09698 0 -0 0</pose>
          <geometry>
            <box>
              <size>0.0762 0.0762 0.0254</size>
            </box>
          </geometry>
          <max_contacts>10</max_contacts>
          <surface>
            <contact>
              <ode/>
            </contact>
            <bounce/>
            <friction>
              <torsional>
                <ode/>
              </torsional>
              <ode/>
            </friction>
          </surface>
        </collision>
        <visual name='row1_block9_md'>
          <pose frame=''>-0.40005 0.1143 0.10968 0 -0 0</pose>
          <geometry>
            <box>
              <size>0.0762 0.0762 0.0508</size>
            </box>
          </geometry>
        </visual>
        <collision name='row1_block9_md'>
          <pose frame=''>-0.40005 0.1143 0.10968 0 -0 0</pose>
          <geometry>
            <box>
              <size>0.0762 0.0762 0.0508</size>
            </box>
          </geometry>
          <max_contacts>10</max_contacts>
          <surface>
            <contact>
              <ode/>
            </contact>
            <bounce/>
            <friction>
              <torsional>
                <ode/>
              </torsional>
              <ode/>
            </friction>
          </surface>
        </collision>
        <visual name='row1_block10_lg'>
          <pose frame=''>-0.51435 0.1143 0.12238 0 -0 0</pose>
          <geometry>
            <box>
              <size>0.0762 0.0762 0.0762</size>
            </box>
          </geometry>
        </visual>
        <collision name='row1_block10_lg'>
          <pose frame=''>-0.51435 0.1143 0.12238 0 -0 0</pose>
          <geometry>
            <box>
              <size>0.0762 0.0762 0.0762</size>
            </box>
          </geometry>
          <max_contacts>10</max_contacts>
          <surface>
            <contact>
              <ode/>
            </contact>
            <bounce/>
            <friction>
              <torsional>
                <ode/>
              </torsional>
              <ode/>
            </friction>
          </surface>
        </collision>
        <visual name='row2_block1_md'>
          <pose frame=''>0.5715 0 0.10968 0 -0 0</pose>
          <geometry>
            <box>
              <size>0.0762 0.0762 0.0508</size>
            </box>
          </geometry>
        </visual>
        <collision name='row2_block1_md'>
          <pose frame=''>0.5715 0 0.10968 0 -0 0</pose>
          <geometry>
            <box>
              <size>0.0762 0.0762 0.0508</size>
            </box>
          </geometry>
          <max_contacts>10</max_contacts>
          <surface>
            <contact>
              <ode/>
            </contact>
            <bounce/>
            <friction>
              <torsional>
                <ode/>
              </torsional>
              <ode/>
            </friction>
          </surface>
        </collision>
        <visual name='row2_block2_sm'>
          <pose frame=''>0.4572 0 0.09698 0 -0 0</pose>
          <geometry>
            <box>
              <size>0.0762 0.0762 0.0254</size>
            </box>
          </geometry>
        </visual>
        <collision name='row2_block2_sm'>
          <pose frame=''>0.4572 0 0.09698 0 -0 0</pose>
          <geometry>
            <box>
              <size>0.0762 0.0762 0.0254</size>
            </box>
          </geometry>
          <max_contacts>10</max_contacts>
          <surface>
            <contact>
              <ode/>
            </contact>
            <bounce/>
            <friction>
              <torsional>
                <ode/>
              </torsional>
              <ode/>
            </friction>
          </surface>
        </collision>
        <visual name='row2_block3_lg'>
          <pose frame=''>0.3429 0 0.12238 0 -0 0</pose>
          <geometry>
            <box>
              <size>0.0762 0.0762 0.0762</size>
            </box>
          </geometry>
        </visual>
        <collision name='row2_block3_lg'>
          <pose frame=''>0.3429 0 0.12238 0 -0 0</pose>
          <geometry>
            <box>
              <size>0.0762 0.0762 0.0762</size>
            </box>
          </geometry>
          <max_contacts>10</max_contacts>
          <surface>
            <contact>
              <ode/>
            </contact>
            <bounce/>
            <friction>
              <torsional>
                <ode/>
              </torsional>
              <ode/>
            </friction>
          </surface>
        </collision>
        <visual name='row2_block4_md'>
          <pose frame=''>0.2286 0 0.10968 0 -0 0</pose>
          <geometry>
            <box>
              <size>0.0762 0.0762 0.0508</size>
            </box>
          </geometry>
        </visual>
        <collision name='row2_block4_md'>
          <pose frame=''>0.2286 0 0.10968 0 -0 0</pose>
          <geometry>
            <box>
              <size>0.0762 0.0762 0.0508</size>
            </box>
          </geometry>
          <max_contacts>10</max_contacts>
          <surface>
            <contact>
              <ode/>
            </contact>
            <bounce/>
            <friction>
              <torsional>
                <ode/>
              </torsional>
              <ode/>
            </friction>
          </surface>
        </collision>
        <visual name='row2_block5_lg'>
          <pose frame=''>0.1143 0 0.12238 0 -0 0</pose>
          <geometry>
            <box>
              <size>0.0762 0.0762 0.0762</size>
            </box>
          </geometry>
        </visual>
        <collision name='row2_block5_lg'>
          <pose frame=''>0.1143 0 0.12238 0 -0 0</pose>
          <geometry>
            <box>
              <size>0.0762 0.0762 0.0762</size>
            </box>
          </geometry>
          <max_contacts>10</max_contacts>
          <surface>
            <contact>
              <ode/>
            </contact>
            <bounce/>
            <friction>
              <torsional>
                <ode/>
              </torsional>
              <ode/>
            </friction>
          </surface>
        </collision>
        <visual name='row2_block6_sm'>
          <pose frame=''>0 0 0.09698 0 -0 0</pose>
          <geometry>
            <box>
              <size>0.0762 0.0762 0.0254</size>
            </box>
          </geometry>
        </visual>
        <collision name='row2_block6_sm'>
          <pose frame=''>0 0 0.09698 0 -0 0</pose>
          <geometry>
            <box>
              <size>0.0762 0.0762 0.0254</size>
            </box>
          </geometry>
          <max_contacts>10</max_contacts>
          <surface>
            <contact>
              <ode/>
            </contact>
            <bounce/>
            <friction>
              <torsional>
                <ode/>
              </torsional>
              <ode/>
            </friction>
          </surface>
        </collision>
        <visual name='row2_block7_md'>
          <pose frame=''>-0.1143 0 0.10968 0 -0 0</pose>
          <geometry>
            <box>
              <size>0.0762 0.0762 0.0508</size>
            </box>
          </geometry>
        </visual>
        <collision name='row2_block7_md'>
          <pose frame=''>-0.1143 0 0.10968 0 -0 0</pose>
          <geometry>
            <box>
              <size>0.0762 0.0762 0.0508</size>
            </box>
          </geometry>
          <max_contacts>10</max_contacts>
          <surface>
            <contact>
              <ode/>
            </contact>
            <bounce/>
            <friction>
              <torsional>
                <ode/>
              </torsional>
              <ode/>
            </friction>
          </surface>
        </collision>
        <visual name='row2_block8_lg'>
          <pose frame=''>-0.2286 0 0.12238 0 -0 0</pose>
          <geometry>
            <box>
              <size>0.0762 0.0762 0.0762</size>
            </box>
          </geometry>
        </visual>
        <collision name='row2_block8_lg'>
          <pose frame=''>-0.2286 0 0.12238 0 -0 0</pose>
          <geometry>
            <box>
              <size>0.0762 0.0762 0.0762</size>
            </box>
          </geometry>
          <max_contacts>10</max_contacts>
          <surface>
            <contact>
              <ode/>
            </contact>
            <bounce/>
            <friction>
              <torsional>
                <ode/>
              </torsional>
              <ode/>
            </friction>
          </surface>
        </collision>
        <visual name='row2_block9_sm'>
          <pose frame=''>-0.3429 0 0.09698 0 -0 0</pose>
          <geometry>
            <box>
              <size>0.0762 0.0762 0.0254</size>
            </box>
          </geometry>
        </visual>
        <collision name='row2_block9_sm'>
          <pose frame=''>-0.3429 0 0.09698 0 -0 0</pose>
          <geometry>
            <box>
              <size>0.0762 0.0762 0.0254</size>
            </box>
          </geometry>
          <max_contacts>10</max_contacts>
          <surface>
            <contact>
              <ode/>
            </contact>
            <bounce/>
            <friction>
              <torsional>
                <ode/>
              </torsional>
              <ode/>
            </friction>
          </surface>
        </collision>
        <visual name='row2_block10_lg'>
          <pose frame=''>-0.4572 0 0.12238 0 -0 0</pose>
          <geometry>
            <box>
              <size>0.0762 0.0762 0.0762</size>
            </box>
          </geometry>
        </visual>
        <collision name='row2_block10_lg'>
          <pose frame=''>-0.4572 0 0.12238 0 -0 0</pose>
          <geometry>
            <box>
              <size>0.0762 0.0762 0.0762</size>
            </box>
          </geometry>
          <max_contacts>10</max_contacts>
          <surface>
            <contact>
              <ode/>
            </contact>
            <bounce/>
            <friction>
              <torsional>
                <ode/>
              </torsional>
              <ode/>
            </friction>
          </surface>
        </collision>
        <visual name='row2_block11_md'>
          <pose frame=''>-0.5715 0 0.10968 0 -0 0</pose>
          <geometry>
            <box>
              <size>0.0762 0.0762 0.0508</size>
            </box>
          </geometry>
        </visual>
        <collision name='row2_block11_md'>
          <pose frame=''>-0.5715 0 0.10968 0 -0 0</pose>
          <geometry>
            <box>
              <size>0.0762 0.0762 0.0508</size>
            </box>
          </geometry>
          <max_contacts>10</max_contacts>
          <surface>
            <contact>
              <ode/>
            </contact>
            <bounce/>
            <friction>
              <torsional>
                <ode/>
              </torsional>
              <ode/>
            </friction>
          </surface>
        </collision>
        <visual name='row3_block1_lg'>
          <pose frame=''>0.51435 -0.1143 0.12238 0 -0 0</pose>
          <geometry>
            <box>
              <size>0.0762 0.0762 0.0762</size>
            </box>
          </geometry>
        </visual>
        <collision name='row3_block1_lg'>
          <pose frame=''>0.51435 -0.1143 0.12238 0 -0 0</pose>
          <geometry>
            <box>
              <size>0.0762 0.0762 0.0762</size>
            </box>
          </geometry>
          <max_contacts>10</max_contacts>
          <surface>
            <contact>
              <ode/>
            </contact>
            <bounce/>
            <friction>
              <torsional>
                <ode/>
              </torsional>
              <ode/>
            </friction>
          </surface>
        </collision>
        <visual name='row3_block2_md'>
          <pose frame=''>0.40005 -0.1143 0.10968 0 -0 0</pose>
          <geometry>
            <box>
              <size>0.0762 0.0762 0.0508</size>
            </box>
          </geometry>
        </visual>
        <collision name='row3_block2_md'>
          <pose frame=''>0.40005 -0.1143 0.10968 0 -0 0</pose>
          <geometry>
            <box>
              <size>0.0762 0.0762 0.0508</size>
            </box>
          </geometry>
          <max_contacts>10</max_contacts>
          <surface>
            <contact>
              <ode/>
            </contact>
            <bounce/>
            <friction>
              <torsional>
                <ode/>
              </torsional>
              <ode/>
            </friction>
          </surface>
        </collision>
        <visual name='row3_block3_lg'>
          <pose frame=''>0.28575 -0.1143 0.12238 0 -0 0</pose>
          <geometry>
            <box>
              <size>0.0762 0.0762 0.0762</size>
            </box>
          </geometry>
        </visual>
        <collision name='row3_block3_lg'>
          <pose frame=''>0.28575 -0.1143 0.12238 0 -0 0</pose>
          <geometry>
            <box>
              <size>0.0762 0.0762 0.0762</size>
            </box>
          </geometry>
          <max_contacts>10</max_contacts>
          <surface>
            <contact>
              <ode/>
            </contact>
            <bounce/>
            <friction>
              <torsional>
                <ode/>
              </torsional>
              <ode/>
            </friction>
          </surface>
        </collision>
        <visual name='row3_block4_sm'>
          <pose frame=''>0.17145 -0.1143 0.09698 0 -0 0</pose>
          <geometry>
            <box>
              <size>0.0762 0.0762 0.0254</size>
            </box>
          </geometry>
        </visual>
        <collision name='row3_block4_sm'>
          <pose frame=''>0.17145 -0.1143 0.09698 0 -0 0</pose>
          <geometry>
            <box>
              <size>0.0762 0.0762 0.0254</size>
            </box>
          </geometry>
          <max_contacts>10</max_contacts>
          <surface>
            <contact>
              <ode/>
            </contact>
            <bounce/>
            <friction>
              <torsional>
                <ode/>
              </torsional>
              <ode/>
            </friction>
          </surface>
        </collision>
        <visual name='row3_block5_md'>
          <pose frame=''>0.05715 -0.1143 0.10968 0 -0 0</pose>
          <geometry>
            <box>
              <size>0.0762 0.0762 0.0508</size>
            </box>
          </geometry>
        </visual>
        <collision name='row3_block5_md'>
          <pose frame=''>0.05715 -0.1143 0.10968 0 -0 0</pose>
          <geometry>
            <box>
              <size>0.0762 0.0762 0.0508</size>
            </box>
          </geometry>
          <max_contacts>10</max_contacts>
          <surface>
            <contact>
              <ode/>
            </contact>
            <bounce/>
            <friction>
              <torsional>
                <ode/>
              </torsional>
              <ode/>
            </friction>
          </surface>
        </collision>
        <visual name='row3_block6_md'>
          <pose frame=''>-0.05715 -0.1143 0.10968 0 -0 0</pose>
          <geometry>
            <box>
              <size>0.0762 0.0762 0.0508</size>
            </box>
          </geometry>
        </visual>
        <collision name='row3_block6_md'>
          <pose frame=''>-0.05715 -0.1143 0.10968 0 -0 0</pose>
          <geometry>
            <box>
              <size>0.0762 0.0762 0.0508</size>
            </box>
          </geometry>
          <max_contacts>10</max_contacts>
          <surface>
            <contact>
              <ode/>
            </contact>
            <bounce/>
            <friction>
              <torsional>
                <ode/>
              </torsional>
              <ode/>
            </friction>
          </surface>
        </collision>
        <visual name='row3_block7_lg'>
          <pose frame=''>-0.17145 -0.1143 0.12238 0 -0 0</pose>
          <geometry>
            <box>
              <size>0.0762 0.0762 0.0762</size>
            </box>
          </geometry>
        </visual>
        <collision name='row3_block7_lg'>
          <pose frame=''>-0.17145 -0.1143 0.12238 0 -0 0</pose>
          <geometry>
            <box>
              <size>0.0762 0.0762 0.0762</size>
            </box>
          </geometry>
          <max_contacts>10</max_contacts>
          <surface>
            <contact>
              <ode/>
            </contact>
            <bounce/>
            <friction>
              <torsional>
                <ode/>
              </torsional>
              <ode/>
            </friction>
          </surface>
        </collision>
        <visual name='row3_block8_sm'>
          <pose frame=''>-0.28575 -0.1143 0.09698 0 -0 0</pose>
          <geometry>
            <box>
              <size>0.0762 0.0762 0.0254</size>
            </box>
          </geometry>
        </visual>
        <collision name='row3_block8_sm'>
          <pose frame=''>-0.28575 -0.1143 0.09698 0 -0 0</pose>
          <geometry>
            <box>
              <size>0.0762 0.0762 0.0254</size>
            </box>
          </geometry>
          <max_contacts>10</max_contacts>
          <surface>
            <contact>
              <ode/>
            </contact>
            <bounce/>
            <friction>
              <torsional>
                <ode/>
              </torsional>
              <ode/>
            </friction>
          </surface>
        </collision>
        <visual name='row3_block9_md'>
          <pose frame=''>-0.40005 -0.1143 0.10968 0 -0 0</pose>
          <geometry>
            <box>
              <size>0.0762 0.0762 0.0508</size>
            </box>
          </geometry>
        </visual>
        <collision name='row3_block9_md'>
          <pose frame=''>-0.40005 -0.1143 0.10968 0 -0 0</pose>
          <geometry>
            <box>
              <size>0.0762 0.0762 0.0508</size>
            </box>
          </geometry>
          <max_contacts>10</max_contacts>
          <surface>
            <contact>
              <ode/>
            </contact>
            <bounce/>
            <friction>
              <torsional>
                <ode/>
              </torsional>
              <ode/>
            </friction>
          </surface>
        </collision>
        <visual name='row3_block10_sm'>
          <pose frame=''>-0.51435 -0.1143 0.09698 0 -0 0</pose>
          <geometry>
            <box>
              <size>0.0762 0.0762 0.0254</size>
            </box>
          </geometry>
        </visual>
        <collision name='row3_block10_sm'>
          <pose frame=''>-0.51435 -0.1143 0.09698 0 -0 0</pose>
          <geometry>
            <box>
              <size>0.0762 0.0762 0.0254</size>
            </box>
          </geometry>
          <max_contacts>10</max_contacts>
          <surface>
            <contact>
              <ode/>
            </contact>
            <bounce/>
            <friction>
              <torsional>
                <ode/>
              </torsional>
              <ode/>
            </friction>
          </surface>
        </collision>
        <self_collide>0</self_collide>
        <kinematic>0</kinematic>
        <gravity>1</gravity>
      </link>
      <pose frame=''>-0.923781 -1.55581 0 0 -0 0</pose>
    </model>
    <state world_name='default'>
      <sim_time>509 528000000</sim_time>
      <real_time>548 209324425</real_time>
      <wall_time>1538987092 904679284</wall_time>
      <iterations>509528</iterations>
      <model name='/'>
        <pose frame=''>-0.378906 0.16783 0.431991 0.001851 -0.007928 -0.504206</pose>
        <scale>1 1 1</scale>
        <link name='base_link'>
          <pose frame=''>-0.378906 0.16783 0.431991 0.001851 -0.007928 -0.504206</pose>
          <velocity>4e-06 -2e-06 1e-06 0 -1e-06 -2e-06</velocity>
          <acceleration>0 0 0 0.791776 -1.34005 0.024044</acceleration>
          <wrench>0 0 0 0 -0 0</wrench>
        </link>
        <link name='front_left_1_Link'>
          <pose frame=''>-0.778639 0.188521 0.428814 -1.57873 -0.0019 1.06664</pose>
          <velocity>3e-06 -1e-06 0 6e-06 -0 8e-06</velocity>
          <acceleration>0 0 0 -0.542575 -1.52812 -2.50473</acceleration>
          <wrench>0 0 0 0 -0 0</wrench>
        </link>
        <link name='front_left_2_Link'>
          <pose frame=''>-0.830242 0.177793 0.428431 -0.686374 0.001895 -2.07495</pose>
          <velocity>2e-06 -1e-06 0 5.9e-05 8.4e-05 1.3e-05</velocity>
          <acceleration>0 0 0 0.953883 -0.58053 1.38171</acceleration>
          <wrench>0 0 0 0 -0 0</wrench>
        </link>
        <link name='front_left_3_Link'>
          <pose frame=''>-0.97845 0.23712 0.235014 -0.493077 -0.001906 1.06662</pose>
          <velocity>-1.4e-05 7e-06 1.1e-05 -3.5e-05 -4.9e-05 2.3e-05</velocity>
          <acceleration>0 0 0 -0.353383 -1.4775 -2.26366</acceleration>
          <wrench>0 0 0 0 -0 0</wrench>
        </link>
        <link name='front_right_1_Link'>
          <pose frame=''>-0.609555 0.494969 0.429461 1.57873 0.003001 -2.07499</pose>
          <velocity>5e-06 -2e-06 2e-06 -3e-06 0 -4e-06</velocity>
          <acceleration>0 0 0 1.72226 0.85038 0.619249</acceleration>
          <wrench>0 0 0 0 -0 0</wrench>
        </link>
        <link name='front_right_2_Link'>
          <pose frame=''>-0.627948 0.54443 0.429248 0.69214 -0.002991 1.0666</pose>
          <velocity>5e-06 -2e-06 1e-06 6.4e-05 0.000124 -5e-06</velocity>
          <acceleration>0 0 0 1.1289 -1.5671 -1.88971</acceleration>
          <wrench>0 0 0 0 -0 0</wrench>
        </link>
        <link name='front_right_3_Link'>
          <pose frame=''>-0.7577 0.639523 0.236837 0.477305 0.002987 -2.07499</pose>
          <velocity>-1.8e-05 1.1e-05 2.2e-05 -4.4e-05 -7.6e-05 -4e-06</velocity>
          <acceleration>0 0 0 1.12916 0.850417 2.53251</acceleration>
          <wrench>0 0 0 0 -0 0</wrench>
        </link>
        <link name='rear_left_1_Link'>
          <pose frame=''>-0.148257 -0.159309 0.434521 -1.57873 0.010662 1.0665</pose>
          <velocity>4e-06 -2e-06 2e-06 1e-06 0 3e-06</velocity>
          <acceleration>0 0 0 1.56781 -1.09721 0.18841</acceleration>
          <wrench>0 0 0 0 -0 0</wrench>
        </link>
        <link name='rear_left_2_Link'>
          <pose frame=''>-0.128916 -0.207044 0.435185 -0.638969 -0.010653 -2.07509</pose>
          <velocity>4e-06 -2e-06 2e-06 6e-05 0.000106 3e-06</velocity>
          <acceleration>0 0 0 -1.28852 -0.875077 -2.59113</acceleration>
          <wrench>0 0 0 0 -0 0</wrench>
        </link>
        <link name='rear_left_3_Link'>
          <pose frame=''>-0.270286 -0.154642 0.234734 -0.491487 0.010659 1.06651</pose>
          <velocity>-1.7e-05 9e-06 1.9e-05 -3.8e-05 -7.2e-05 2e-06</velocity>
          <acceleration>0 0 0 -1.71715 -1.09752 -1.02136</acceleration>
          <wrench>0 0 0 0 -0 0</wrench>
        </link>
        <link name='rear_right_1_Link'>
          <pose frame=''>0.020827 0.147139 0.435169 1.57873 0.006101 -2.07496</pose>
          <velocity>4e-06 -4e-06 2e-06 5e-06 -2e-06 5e-06</velocity>
          <acceleration>0 0 0 2.25813 -1.51835 -1.11767</acceleration>
          <wrench>0 0 0 0 -0 0</wrench>
        </link>
        <link name='rear_right_2_Link'>
          <pose frame=''>0.072475 0.157952 0.435696 0.656114 -0.00609 1.06664</pose>
          <velocity>4e-06 -4e-06 2e-06 0.000131 0.000211 -1.5e-05</velocity>
          <acceleration>0 0 0 -0.638665 1.18826 -3.03469</acceleration>
          <wrench>0 0 0 0 -0 0</wrench>
        </link>
        <link name='rear_right_3_Link'>
          <pose frame=''>-0.050816 0.250192 0.237729 0.468461 0.006097 -2.07496</pose>
          <velocity>-3.6e-05 2.3e-05 3.9e-05 -8.8e-05 -0.000152 -2.1e-05</velocity>
          <acceleration>0 0 0 1.99628 1.55536 1.159</acceleration>
          <wrench>0 0 0 0 -0 0</wrench>
        </link>
      </model>
      <model name='frc2016_field'>
        <pose frame=''>0.932876 -0.11768 0 0 -0 0</pose>
        <scale>1 1 1</scale>
        <link name='walls'>
          <pose frame=''>0.932876 -0.11768 0 0 -0 0</pose>
          <velocity>0 0 0 0 -0 0</velocity>
          <acceleration>0 0 0 0 -0 0</acceleration>
          <wrench>0 0 0 0 -0 0</wrench>
        </link>
      </model>
      <model name='frc2016_roughterrain'>
        <pose frame=''>-1.0271 -2.87631 0.00625 0 -0 0</pose>
        <scale>1 1 1</scale>
        <link name='link'>
          <pose frame=''>-1.0271 -2.87631 0.00625 0 -0 0</pose>
          <velocity>0 0 0 0 -0 0</velocity>
          <acceleration>0 0 0 0 -0 0</acceleration>
          <wrench>0 0 0 0 -0 0</wrench>
        </link>
      </model>
      <model name='ground_plane'>
        <pose frame=''>0 0 0 0 -0 0</pose>
        <scale>1 1 1</scale>
        <link name='link'>
          <pose frame=''>0 0 0 0 -0 0</pose>
          <velocity>0 0 0 0 -0 0</velocity>
          <acceleration>0 0 0 0 -0 0</acceleration>
          <wrench>0 0 0 0 -0 0</wrench>
        </link>
      </model>
      <model name='lumber_2x4x48'>
        <pose frame=''>1.0783 0.60559 0.043055 0 0 -0.916391</pose>
        <scale>1 1 1</scale>
        <link name='link'>
          <pose frame=''>1.0783 0.60559 0.043055 0 0 -0.916391</pose>
          <velocity>0 0 0 0 -0 0</velocity>
          <acceleration>0 0 0 0 -0 0</acceleration>
          <wrench>0 0 0 0 -0 0</wrench>
        </link>
      </model>
      <model name='lumber_2x6x48'>
        <pose frame=''>1.58397 -1.10665 0.068258 0 -0 1.58116</pose>
        <scale>1 1 1</scale>
        <link name='link'>
          <pose frame=''>1.58397 -1.10665 0.068258 0 -0 1.58116</pose>
          <velocity>0 0 0 0 -0 0</velocity>
          <acceleration>0 0 0 0 -0 0</acceleration>
          <wrench>0 0 0 0 -0 0</wrench>
        </link>
      </model>
      <model name='lumber_4x4x20'>
        <pose frame=''>0.890607 -0.382046 0.044367 0 -0 1.04183</pose>
        <scale>1 1 1</scale>
        <link name='link'>
          <pose frame=''>0.890607 -0.382046 0.044367 0 -0 1.04183</pose>
          <velocity>0 0 0 0 -0 0</velocity>
          <acceleration>0 0 0 0 -0 0</acceleration>
          <wrench>0 0 0 0 -0 0</wrench>
        </link>
      </model>
      <model name='lumber_4x4x20_0'>
        <pose frame=''>0.151792 -0.894591 0.079775 -0.192507 -0.110489 0.017787</pose>
        <scale>1 1 1</scale>
        <link name='link'>
          <pose frame=''>0.151792 -0.894591 0.079775 -0.192507 -0.110489 0.017787</pose>
          <velocity>0.000901 0.000911 -0.016061 -0.041304 -0.019055 0.009815</velocity>
          <acceleration>-0.05323 0.906194 -12.2454 -2.39606 -0.915209 -0.058268</acceleration>
          <wrench>-0.072925 1.24149 -16.7761 0 -0 0</wrench>
        </link>
      </model>
      <model name='truss'>
        <pose frame=''>0.375128 -1.0678 0.143298 -8e-06 -1.2e-05 -0.054206</pose>
        <scale>1 1 1</scale>
        <link name='link'>
          <pose frame=''>0.375128 -1.0678 0.143298 -8e-06 -1.2e-05 -0.054206</pose>
          <velocity>-0.000475 0.001263 -0.006993 -0.008249 -0.008628 -0.000998</velocity>
          <acceleration>-0.474854 1.26328 -6.99276 -2.60984 -0.148521 -0.999905</acceleration>
          <wrench>-9.84406 26.1888 -144.965 0 -0 0</wrench>
        </link>
      </model>
      <model name='wood_slats'>
        <pose frame=''>2.19663 -1.94952 0 0 -0 0</pose>
        <scale>1 1 1</scale>
        <link name='link'>
          <pose frame=''>2.19663 -1.94952 0 0 -0 0</pose>
          <velocity>0 0 0 0 -0 0</velocity>
          <acceleration>0 0 0 0 -0 0</acceleration>
          <wrench>0 0 0 0 -0 0</wrench>
        </link>
      </model>
      <light name='sun'>
        <pose frame=''>0 0 10 0 -0 0</pose>
      </light>
    </state>
    <gui fullscreen='0'>
      <camera name='user_camera'>
        <pose frame=''>8.02132 -4.36212 6.56984 -0 0.735643 2.6282</pose>
        <view_controller>orbit</view_controller>
        <projection_type>perspective</projection_type>
      </camera>
    </gui>
  </world>
</sdf>
