<sdf version='1.6'>
  <model name='simpledog'>
    <link name='base_link'>
      <pose frame=''>0 0 0 0 -0 0</pose>
      <inertial>
        <pose frame=''>0 -0 0 0 -0 0</pose>
        <mass>15.238</mass>
        <inertia>
          <ixx>0.74932</ixx>
          <ixy>-1.2062e-17</ixy>
          <ixz>-2.0602e-16</ixz>
          <iyy>2.3017</iyy>
          <iyz>-3.8366e-17</iyz>
          <izz>2.9675</izz>
        </inertia>
      </inertial>
      <collision name='base_link_collision'>
        <pose frame=''>0 0 0 0 -0 0</pose>
        <geometry>
          <mesh>
            <scale>1 1 1</scale>
            <uri>model://simpledog/meshes/base_link.STL</uri>
          </mesh>
        </geometry>
        <surface>
          <contact>
            <ode>
              <kp>1e+07</kp>
              <kd>1</kd>
            </ode>
          </contact>
          <friction>
            <ode>
              <mu>10</mu>
              <mu2>10</mu2>
              <fdir1>1 0 0</fdir1>
            </ode>
          </friction>
        </surface>
      </collision>
      <collision name='base_link_fixed_joint_lump__camera_link_collision_1'>
        <pose frame=''>0.3 0 0.1 0 0.18 0</pose>
        <geometry>
          <box>
            <size>0.07 0.3 0.09</size>
          </box>
        </geometry>
        <surface>
          <contact>
            <ode/>
          </contact>
          <friction>
            <ode/>
          </friction>
        </surface>
      </collision>
      <visual name='base_link_visual'>
        <pose frame=''>0 0 0 0 -0 0</pose>
        <geometry>
          <mesh>
            <scale>1 1 1</scale>
            <uri>model://simpledog/meshes/base_link.STL</uri>
          </mesh>
        </geometry>
        <material>
          <script>
            <name>Gazebo/DarkGrey</name>
            <uri>file://media/materials/scripts/gazebo.material</uri>
          </script>
        </material>
      </visual>
      <visual name='base_link_fixed_joint_lump__camera_link_visual_1'>
        <pose frame=''>0.3 0 0.1 0.18 -1e-06 1.5708</pose>
        <geometry>
          <mesh>
            <scale>1 1 1</scale>
            <uri>model://simpledog/meshes/kinect.dae</uri>
          </mesh>
        </geometry>
        <material>
          <script>
            <uri>__default__</uri>
            <name>__default__</name>
          </script>
        </material>
      </visual>
      <velocity_decay/>
      <gravity>1</gravity>
      <gravity>1</gravity>
      <velocity_decay/>
      <self_collide>0</self_collide>
      <sensor name='camera' type='depth'>
        <always_on>1</always_on>
        <update_rate>10</update_rate>
        <camera name='__default__'>
          <horizontal_fov>1.04667</horizontal_fov>
          <image>
            <format>R8G8B8</format>
            <width>640</width>
            <height>480</height>
          </image>
          <clip>
            <near>0.05</near>
            <far>8</far>
          </clip>
        </camera>
        <plugin name='kinect_camera_controller' filename='libgazebo_ros_openni_kinect.so'>
          <cameraName>camera</cameraName>
          <alwaysOn>true</alwaysOn>
          <updateRate>10.0</updateRate>
          <imageTopicName>rgb/image_raw</imageTopicName>
          <depthImageTopicName>depth/image_raw</depthImageTopicName>
          <pointCloudTopicName>depth/points</pointCloudTopicName>
          <cameraInfoTopicName>rgb/camera_info</cameraInfoTopicName>
          <depthImageCameraInfoTopicName>depth/camera_info</depthImageCameraInfoTopicName>
          <frameName>camera_frame_optical</frameName>
          <baseline>0.1</baseline>
          <distortion_k1>0.0</distortion_k1>
          <distortion_k2>0.0</distortion_k2>
          <distortion_k3>0.0</distortion_k3>
          <distortion_t1>0.0</distortion_t1>
          <distortion_t2>0.0</distortion_t2>
          <pointCloudCutoff>0.4</pointCloudCutoff>
          <robotNamespace>/simpledog</robotNamespace>
        </plugin>
        <pose frame=''>0.3 0 0.1 0 0.18 0</pose>
      </sensor>
    </link>
    <link name='front_left_1_Link'>
      <pose frame=''>0.4 0.175 0 1.5708 1.57052 1.5708</pose>
      <inertial>
        <pose frame=''>0 0.012793 -0.000236 0 -0 0</pose>
        <mass>1.1709</mass>
        <inertia>
          <ixx>0.001719</ixx>
          <ixy>2.9302e-20</ixy>
          <ixz>-1.6433e-19</ixz>
          <iyy>0.0013167</iyy>
          <iyz>-7.6795e-20</iyz>
          <izz>0.0021511</izz>
        </inertia>
      </inertial>
      <collision name='front_left_1_Link_collision'>
        <pose frame=''>0 0 0 0 -0 0</pose>
        <geometry>
          <mesh>
            <scale>1 1 1</scale>
            <uri>model://simpledog/meshes/front_left_1_Link.STL</uri>
          </mesh>
        </geometry>
        <surface>
          <contact>
            <ode>
              <kp>1e+07</kp>
              <kd>1</kd>
            </ode>
          </contact>
          <friction>
            <ode>
              <mu>100</mu>
              <mu2>100</mu2>
              <fdir1>1 0 0</fdir1>
            </ode>
          </friction>
        </surface>
      </collision>
      <visual name='front_left_1_Link_visual'>
        <pose frame=''>0 0 0 0 -0 0</pose>
        <geometry>
          <mesh>
            <scale>1 1 1</scale>
            <uri>model://simpledog/meshes/front_left_1_Link.STL</uri>
          </mesh>
        </geometry>
        <material>
          <script>
            <uri>__default__</uri>
            <name>__default__</name>
          </script>
        </material>
      </visual>
      <gravity>1</gravity>
      <velocity_decay/>
      <self_collide>0</self_collide>
    </link>
    <joint name='front_left_1_joint' type='revolute'>
      <child>front_left_1_Link</child>
      <parent>base_link</parent>
      <axis>
        <xyz>1 0 0</xyz>
        <limit>
          <lower>-3</lower>
          <upper>3</upper>
          <effort>300</effort>
          <velocity>10</velocity>
        </limit>
        <dynamics>
          <spring_reference>0</spring_reference>
          <spring_stiffness>0</spring_stiffness>
        </dynamics>
        <use_parent_model_frame>1</use_parent_model_frame>
      </axis>
      <physics>
        <provide_feedback>1</provide_feedback>
        <ode>
          <provide_feedback>1</provide_feedback>
          <limit>
            <cfm>0</cfm>
            <erp>0.2</erp>
          </limit>
        </ode>
      </physics>
    </joint>
    <link name='front_left_2_Link'>
      <pose frame=''>0.4 0.175 0 -4e-06 1.57052 1.5708</pose>
      <inertial>
        <pose frame=''>0.11439 0.000282 0.05942 0 -0 0</pose>
        <mass>1.3902</mass>
        <inertia>
          <ixx>0.0030209</ixx>
          <ixy>-5.6504e-20</ixy>
          <ixz>2.8413e-18</ixz>
          <iyy>0.026875</iyy>
          <iyz>1.5349e-06</iyz>
          <izz>0.028484</izz>
        </inertia>
      </inertial>
      <collision name='front_left_2_Link_collision'>
        <pose frame=''>0 0 0 0 -0 0</pose>
        <geometry>
          <mesh>
            <scale>1 1 1</scale>
            <uri>model://simpledog/meshes/front_left_2_Link.STL</uri>
          </mesh>
        </geometry>
        <surface>
          <contact>
            <ode>
              <kp>1e+07</kp>
              <kd>1</kd>
            </ode>
          </contact>
          <friction>
            <ode>
              <mu>100</mu>
              <mu2>100</mu2>
              <fdir1>1 0 0</fdir1>
            </ode>
          </friction>
        </surface>
      </collision>
      <visual name='front_left_2_Link_visual'>
        <pose frame=''>0 0 0 0 -0 0</pose>
        <geometry>
          <mesh>
            <scale>1 1 1</scale>
            <uri>model://simpledog/meshes/front_left_2_Link.STL</uri>
          </mesh>
        </geometry>
        <material>
          <script>
            <uri>__default__</uri>
            <name>__default__</name>
          </script>
        </material>
      </visual>
      <gravity>1</gravity>
      <velocity_decay/>
      <self_collide>0</self_collide>
    </link>
    <joint name='front_left_2_joint' type='revolute'>
      <child>front_left_2_Link</child>
      <parent>front_left_1_Link</parent>
      <axis>
        <xyz>-4e-06 1 0.00028</xyz>
        <limit>
          <lower>-3</lower>
          <upper>3</upper>
          <effort>300</effort>
          <velocity>10</velocity>
        </limit>
        <dynamics>
          <spring_reference>0</spring_reference>
          <spring_stiffness>0</spring_stiffness>
        </dynamics>
        <use_parent_model_frame>1</use_parent_model_frame>
      </axis>
      <physics>
        <provide_feedback>1</provide_feedback>
        <ode>
          <provide_feedback>1</provide_feedback>
          <limit>
            <cfm>0</cfm>
            <erp>0.2</erp>
          </limit>
        </ode>
      </physics>
    </joint>
    <link name='front_left_3_Link'>
      <pose frame=''>0.399665 0.28949 -0.250037 -4e-06 1.57052 1.5708</pose>
      <inertial>
        <pose frame=''>0.094936 1.5e-05 -0.016638 0 -0 0</pose>
        <mass>1.40792</mass>
        <inertia>
          <ixx>0.000547037</ixx>
          <ixy>-7.05879e-07</ixy>
          <ixz>-0.000224443</ixz>
          <iyy>0.0108863</iyy>
          <iyz>-8.23294e-08</iyz>
          <izz>0.0110815</izz>
        </inertia>
      </inertial>
      <collision name='front_left_3_Link_collision'>
        <pose frame=''>0 0 0 0 -0 0</pose>
        <geometry>
          <mesh>
            <scale>1 1 1</scale>
            <uri>model://simpledog/meshes/front_left_3_Link.STL</uri>
          </mesh>
        </geometry>
        <surface>
          <contact>
            <ode>
              <kp>1e+07</kp>
              <kd>1</kd>
            </ode>
          </contact>
          <friction>
            <ode>
              <mu>100</mu>
              <mu2>100</mu2>
              <fdir1>1 0 0</fdir1>
            </ode>
          </friction>
        </surface>
      </collision>
      <collision name='front_left_3_Link_fixed_joint_lump__lf_foot_Link_collision_1'>
        <pose frame=''>0.250004 0 -0.01494 0 -0 0</pose>
        <geometry>
          <mesh>
            <scale>1 1 1</scale>
            <uri>model://simpledog/meshes/lf_foot_Link.STL</uri>
          </mesh>
        </geometry>
        <surface>
          <contact>
            <ode>
              <kp>1e+07</kp>
              <kd>1</kd>
            </ode>
          </contact>
          <friction>
            <ode>
              <mu>100</mu>
              <mu2>100</mu2>
              <fdir1>1 0 0</fdir1>
            </ode>
          </friction>
        </surface>
      </collision>
      <visual name='front_left_3_Link_visual'>
        <pose frame=''>0 0 0 0 -0 0</pose>
        <geometry>
          <mesh>
            <scale>1 1 1</scale>
            <uri>model://simpledog/meshes/front_left_3_Link.STL</uri>
          </mesh>
        </geometry>
        <material>
          <script>
            <uri>__default__</uri>
            <name>__default__</name>
          </script>
        </material>
      </visual>
      <visual name='front_left_3_Link_fixed_joint_lump__lf_foot_Link_visual_1'>
        <pose frame=''>0.250004 0 -0.01494 0 -0 0</pose>
        <geometry>
          <mesh>
            <scale>1 1 1</scale>
            <uri>model://simpledog/meshes/lf_foot_Link.STL</uri>
          </mesh>
        </geometry>
        <material>
          <script>
            <name>Gazebo/DarkGrey</name>
            <uri>file://media/materials/scripts/gazebo.material</uri>
          </script>
        </material>
      </visual>
      <velocity_decay/>
      <velocity_decay/>
      <gravity>0</gravity>
      <velocity_decay/>
      <self_collide>0</self_collide>
      <sensor name='lf_foot_contact_sensor' type='contact'>
        <update_rate>100</update_rate>
        <contact>
          <collision>front_left_3_Link_fixed_joint_lump__lf_foot_Link_collision_1</collision>
          <topic>__default_topic__</topic>
        </contact>
        <plugin name='lf_foot_gazebo_ros_bumper_controller' filename='libgazebo_ros_bumper.so'>
          <alwaysOn>true</alwaysOn>
          <frameName>lf_foot_Link</frameName>
          <updateRate>100.0</updateRate>
          <bumperTopicName>lf_foot_bumper</bumperTopicName>
        </plugin>
        <pose frame=''>0.250004 0 -0.01494 0 -0 0</pose>
      </sensor>
    </link>
    <joint name='front_left_3_joint' type='revolute'>
      <child>front_left_3_Link</child>
      <parent>front_left_2_Link</parent>
      <axis>
        <xyz>-4e-06 1 0.00028</xyz>
        <limit>
          <lower>-3</lower>
          <upper>3</upper>
          <effort>300</effort>
          <velocity>10</velocity>
        </limit>
        <dynamics>
          <spring_reference>0</spring_reference>
          <spring_stiffness>0</spring_stiffness>
        </dynamics>
        <use_parent_model_frame>1</use_parent_model_frame>
      </axis>
      <physics>
        <provide_feedback>1</provide_feedback>
        <ode>
          <provide_feedback>1</provide_feedback>
          <limit>
            <cfm>0</cfm>
            <erp>0.2</erp>
          </limit>
        </ode>
      </physics>
    </joint>
    <link name='front_right_1_Link'>
      <pose frame=''>0.4 -0.175 0 -1.57079 1.57079 1.57079</pose>
      <inertial>
        <pose frame=''>0 0.012793 0 0 -0 0</pose>
        <mass>1.1709</mass>
        <inertia>
          <ixx>0.001719</ixx>
          <ixy>-5.88e-19</ixy>
          <ixz>-1.7779e-19</ixz>
          <iyy>0.0013167</iyy>
          <iyz>-2.0543e-19</iyz>
          <izz>0.0021511</izz>
        </inertia>
      </inertial>
      <collision name='front_right_1_Link_collision'>
        <pose frame=''>0 0 0 0 -0 0</pose>
        <geometry>
          <mesh>
            <scale>1 1 1</scale>
            <uri>model://simpledog/meshes/front_right_1_Link.STL</uri>
          </mesh>
        </geometry>
        <surface>
          <contact>
            <ode>
              <kp>1e+07</kp>
              <kd>1</kd>
            </ode>
          </contact>
          <friction>
            <ode>
              <mu>100</mu>
              <mu2>100</mu2>
              <fdir1>1 0 0</fdir1>
            </ode>
          </friction>
        </surface>
      </collision>
      <visual name='front_right_1_Link_visual'>
        <pose frame=''>0 0 0 0 -0 0</pose>
        <geometry>
          <mesh>
            <scale>1 1 1</scale>
            <uri>model://simpledog/meshes/front_right_1_Link.STL</uri>
          </mesh>
        </geometry>
        <material>
          <script>
            <uri>__default__</uri>
            <name>__default__</name>
          </script>
        </material>
      </visual>
      <gravity>1</gravity>
      <velocity_decay/>
      <self_collide>0</self_collide>
    </link>
    <joint name='front_right_1_joint' type='revolute'>
      <child>front_right_1_Link</child>
      <parent>base_link</parent>
      <axis>
        <xyz>-1 7e-06 0</xyz>
        <limit>
          <lower>-3</lower>
          <upper>3</upper>
          <effort>300</effort>
          <velocity>10</velocity>
        </limit>
        <dynamics>
          <spring_reference>0</spring_reference>
          <spring_stiffness>0</spring_stiffness>
        </dynamics>
        <use_parent_model_frame>1</use_parent_model_frame>
      </axis>
      <physics>
        <provide_feedback>1</provide_feedback>
        <ode>
          <provide_feedback>1</provide_feedback>
          <limit>
            <cfm>0</cfm>
            <erp>0.2</erp>
          </limit>
        </ode>
      </physics>
    </joint>
    <link name='front_right_2_Link'>
      <pose frame=''>0.4 -0.175 0 3.14159 1.57079 1.57079</pose>
      <inertial>
        <pose frame=''>0.11432 -0 0.05942 0 -0 0</pose>
        <mass>1.3902</mass>
        <inertia>
          <ixx>0.0030209</ixx>
          <ixy>-4.0905e-18</ixy>
          <ixz>-8.1586e-10</ixz>
          <iyy>0.026875</iyy>
          <iyz>2.3399e-19</iyz>
          <izz>0.028484</izz>
        </inertia>
      </inertial>
      <collision name='front_right_2_Link_collision'>
        <pose frame=''>0 0 0 0 -0 0</pose>
        <geometry>
          <mesh>
            <scale>1 1 1</scale>
            <uri>model://simpledog/meshes/front_right_2_Link.STL</uri>
          </mesh>
        </geometry>
        <surface>
          <contact>
            <ode>
              <kp>1e+07</kp>
              <kd>1</kd>
            </ode>
          </contact>
          <friction>
            <ode>
              <mu>100</mu>
              <mu2>100</mu2>
              <fdir1>1 0 0</fdir1>
            </ode>
          </friction>
        </surface>
      </collision>
      <visual name='front_right_2_Link_visual'>
        <pose frame=''>0 0 0 0 -0 0</pose>
        <geometry>
          <mesh>
            <scale>1 1 1</scale>
            <uri>model://simpledog/meshes/front_right_2_Link.STL</uri>
          </mesh>
        </geometry>
        <material>
          <script>
            <uri>__default__</uri>
            <name>__default__</name>
          </script>
        </material>
      </visual>
      <gravity>1</gravity>
      <velocity_decay/>
      <self_collide>0</self_collide>
    </link>
    <joint name='front_right_2_joint' type='revolute'>
      <child>front_right_2_Link</child>
      <parent>front_right_1_Link</parent>
      <axis>
        <xyz>-4e-06 -1 -4e-06</xyz>
        <limit>
          <lower>-3</lower>
          <upper>3</upper>
          <effort>300</effort>
          <velocity>10</velocity>
        </limit>
        <dynamics>
          <spring_reference>0</spring_reference>
          <spring_stiffness>0</spring_stiffness>
        </dynamics>
        <use_parent_model_frame>1</use_parent_model_frame>
      </axis>
      <physics>
        <provide_feedback>1</provide_feedback>
        <ode>
          <provide_feedback>1</provide_feedback>
          <limit>
            <cfm>0</cfm>
            <erp>0.2</erp>
          </limit>
        </ode>
      </physics>
    </joint>
    <link name='front_right_3_Link'>
      <pose frame=''>0.4 -0.289419 -0.25 3.14159 1.57079 1.57079</pose>
      <inertial>
        <pose frame=''>0.094932 6e-06 -0.016661 0 -0 0</pose>
        <mass>1.40792</mass>
        <inertia>
          <ixx>0.00054693</ixx>
          <ixy>-8.93449e-07</ixy>
          <ixz>-0.000221946</ixz>
          <iyy>0.0108863</iyy>
          <iyz>1.7109e-08</iyz>
          <izz>0.0110816</izz>
        </inertia>
      </inertial>
      <collision name='front_right_3_Link_collision'>
        <pose frame=''>0 0 0 0 -0 0</pose>
        <geometry>
          <mesh>
            <scale>1 1 1</scale>
            <uri>model://simpledog/meshes/front_right_3_Link.STL</uri>
          </mesh>
        </geometry>
        <surface>
          <contact>
            <ode>
              <kp>1e+07</kp>
              <kd>1</kd>
            </ode>
          </contact>
          <friction>
            <ode>
              <mu>100</mu>
              <mu2>100</mu2>
              <fdir1>1 0 0</fdir1>
            </ode>
          </friction>
        </surface>
      </collision>
      <collision name='front_right_3_Link_fixed_joint_lump__rf_foot_Link_collision_1'>
        <pose frame=''>0.25 0 -0.015 -0.000206 0 -0</pose>
        <geometry>
          <mesh>
            <scale>1 1 1</scale>
            <uri>model://simpledog/meshes/rf_foot_Link.STL</uri>
          </mesh>
        </geometry>
        <surface>
          <contact>
            <ode>
              <kp>1e+07</kp>
              <kd>1</kd>
            </ode>
          </contact>
          <friction>
            <ode>
              <mu>100</mu>
              <mu2>100</mu2>
              <fdir1>1 0 0</fdir1>
            </ode>
          </friction>
        </surface>
      </collision>
      <visual name='front_right_3_Link_visual'>
        <pose frame=''>0 0 0 0 -0 0</pose>
        <geometry>
          <mesh>
            <scale>1 1 1</scale>
            <uri>model://simpledog/meshes/front_right_3_Link.STL</uri>
          </mesh>
        </geometry>
        <material>
          <script>
            <uri>__default__</uri>
            <name>__default__</name>
          </script>
        </material>
      </visual>
      <visual name='front_right_3_Link_fixed_joint_lump__rf_foot_Link_visual_1'>
        <pose frame=''>0.25 0 -0.015 -0.000206 0 -0</pose>
        <geometry>
          <mesh>
            <scale>1 1 1</scale>
            <uri>model://simpledog/meshes/rf_foot_Link.STL</uri>
          </mesh>
        </geometry>
        <material>
          <script>
            <name>Gazebo/DarkGrey</name>
            <uri>file://media/materials/scripts/gazebo.material</uri>
          </script>
        </material>
      </visual>
      <velocity_decay/>
      <velocity_decay/>
      <gravity>0</gravity>
      <velocity_decay/>
      <self_collide>0</self_collide>
      <sensor name='rf_foot_contact_sensor' type='contact'>
        <update_rate>100</update_rate>
        <contact>
          <collision>front_right_3_Link_fixed_joint_lump__rf_foot_Link_collision_1</collision>
          <topic>__default_topic__</topic>
        </contact>
        <plugin name='rf_foot_gazebo_ros_bumper_controller' filename='libgazebo_ros_bumper.so'>
          <alwaysOn>true</alwaysOn>
          <frameName>rf_foot_Link</frameName>
          <updateRate>100.0</updateRate>
          <bumperTopicName>rf_foot_bumper</bumperTopicName>
        </plugin>
        <pose frame=''>0.25 0 -0.015 -0.000206 0 -0</pose>
      </sensor>
    </link>
    <joint name='front_right_3_joint' type='revolute'>
      <child>front_right_3_Link</child>
      <parent>front_right_2_Link</parent>
      <axis>
        <xyz>-4e-06 -1 -4e-06</xyz>
        <limit>
          <lower>-3</lower>
          <upper>3</upper>
          <effort>300</effort>
          <velocity>10</velocity>
        </limit>
        <dynamics>
          <spring_reference>0</spring_reference>
          <spring_stiffness>0</spring_stiffness>
        </dynamics>
        <use_parent_model_frame>1</use_parent_model_frame>
      </axis>
      <physics>
        <provide_feedback>1</provide_feedback>
        <ode>
          <provide_feedback>1</provide_feedback>
          <limit>
            <cfm>0</cfm>
            <erp>0.2</erp>
          </limit>
        </ode>
      </physics>
    </joint>
    <link name='rear_left_1_Link'>
      <pose frame=''>-0.4 0.175 0 1.5708 1.5652 1.5708</pose>
      <inertial>
        <pose frame=''>0 0.012793 0 0 -0 0</pose>
        <mass>1.1709</mass>
        <inertia>
          <ixx>0.001719</ixx>
          <ixy>-2.0371e-19</ixy>
          <ixz>5.3128e-21</ixz>
          <iyy>0.0013167</iyy>
          <iyz>-3.3901e-19</iyz>
          <izz>0.0021511</izz>
        </inertia>
      </inertial>
      <collision name='rear_left_1_Link_collision'>
        <pose frame=''>0 0 0 0 -0 0</pose>
        <geometry>
          <mesh>
            <scale>1 1 1</scale>
            <uri>model://simpledog/meshes/rear_left_1_Link.STL</uri>
          </mesh>
        </geometry>
        <surface>
          <contact>
            <ode>
              <kp>1e+07</kp>
              <kd>1</kd>
            </ode>
          </contact>
          <friction>
            <ode>
              <mu>100</mu>
              <mu2>100</mu2>
              <fdir1>1 0 0</fdir1>
            </ode>
          </friction>
        </surface>
      </collision>
      <visual name='rear_left_1_Link_visual'>
        <pose frame=''>0 0 0 0 -0 0</pose>
        <geometry>
          <mesh>
            <scale>1 1 1</scale>
            <uri>model://simpledog/meshes/rear_left_1_Link.STL</uri>
          </mesh>
        </geometry>
        <material>
          <script>
            <uri>__default__</uri>
            <name>__default__</name>
          </script>
        </material>
      </visual>
      <gravity>1</gravity>
      <velocity_decay/>
      <self_collide>0</self_collide>
    </link>
    <joint name='rear_left_1_joint' type='revolute'>
      <child>rear_left_1_Link</child>
      <parent>base_link</parent>
      <axis>
        <xyz>1 0 -0</xyz>
        <limit>
          <lower>-3</lower>
          <upper>3</upper>
          <effort>300</effort>
          <velocity>10</velocity>
        </limit>
        <dynamics>
          <spring_reference>0</spring_reference>
          <spring_stiffness>0</spring_stiffness>
        </dynamics>
        <use_parent_model_frame>1</use_parent_model_frame>
      </axis>
      <physics>
        <provide_feedback>1</provide_feedback>
        <ode>
          <provide_feedback>1</provide_feedback>
          <limit>
            <cfm>0</cfm>
            <erp>0.2</erp>
          </limit>
        </ode>
      </physics>
    </joint>
    <link name='rear_left_2_Link'>
      <pose frame=''>-0.4 0.175 0 -0 1.5652 1.5708</pose>
      <inertial>
        <pose frame=''>0.11432 0 0.05942 0 -0 0</pose>
        <mass>1.3902</mass>
        <inertia>
          <ixx>0.0030209</ixx>
          <ixy>-1.8526e-18</ixy>
          <ixz>2.5242e-19</ixz>
          <iyy>0.026875</iyy>
          <iyz>3.7608e-19</iyz>
          <izz>0.028484</izz>
        </inertia>
      </inertial>
      <collision name='rear_left_2_Link_collision'>
        <pose frame=''>0 0 0 0 -0 0</pose>
        <geometry>
          <mesh>
            <scale>1 1 1</scale>
            <uri>model://simpledog/meshes/rear_left_2_Link.STL</uri>
          </mesh>
        </geometry>
        <surface>
          <contact>
            <ode>
              <kp>1e+07</kp>
              <kd>1</kd>
            </ode>
          </contact>
          <friction>
            <ode>
              <mu>100</mu>
              <mu2>100</mu2>
              <fdir1>1 0 0</fdir1>
            </ode>
          </friction>
        </surface>
      </collision>
      <visual name='rear_left_2_Link_visual'>
        <pose frame=''>0 0 0 0 -0 0</pose>
        <geometry>
          <mesh>
            <scale>1 1 1</scale>
            <uri>model://simpledog/meshes/rear_left_2_Link.STL</uri>
          </mesh>
        </geometry>
        <material>
          <script>
            <uri>__default__</uri>
            <name>__default__</name>
          </script>
        </material>
      </visual>
      <gravity>1</gravity>
      <velocity_decay/>
      <self_collide>0</self_collide>
    </link>
    <joint name='rear_left_2_joint' type='revolute'>
      <child>rear_left_2_Link</child>
      <parent>rear_left_1_Link</parent>
      <axis>
        <xyz>-0 0.999984 0.005597</xyz>
        <limit>
          <lower>-3</lower>
          <upper>3</upper>
          <effort>300</effort>
          <velocity>10</velocity>
        </limit>
        <dynamics>
          <spring_reference>0</spring_reference>
          <spring_stiffness>0</spring_stiffness>
        </dynamics>
        <use_parent_model_frame>1</use_parent_model_frame>
      </axis>
      <physics>
        <provide_feedback>1</provide_feedback>
        <ode>
          <provide_feedback>1</provide_feedback>
          <limit>
            <cfm>0</cfm>
            <erp>0.2</erp>
          </limit>
        </ode>
      </physics>
    </joint>
    <link name='rear_left_3_Link'>
      <pose frame=''>-0.4 0.290817 -0.249356 -0 1.5652 1.5708</pose>
      <inertial>
        <pose frame=''>0.09483 7e-05 -0.016661 0 -0 0</pose>
        <mass>1.40792</mass>
        <inertia>
          <ixx>0.000546935</ixx>
          <ixy>-3.3893e-06</ixy>
          <ixz>-0.000221708</ixz>
          <iyy>0.0108371</iyy>
          <iyz>-6.04876e-07</iyz>
          <izz>0.0110324</izz>
        </inertia>
      </inertial>
      <collision name='rear_left_3_Link_collision'>
        <pose frame=''>0 0 0 0 -0 0</pose>
        <geometry>
          <mesh>
            <scale>1 1 1</scale>
            <uri>model://simpledog/meshes/rear_left_3_Link.STL</uri>
          </mesh>
        </geometry>
        <surface>
          <contact>
            <ode>
              <kp>1e+07</kp>
              <kd>1</kd>
            </ode>
          </contact>
          <friction>
            <ode>
              <mu>100</mu>
              <mu2>100</mu2>
              <fdir1>1 0 0</fdir1>
            </ode>
          </friction>
        </surface>
      </collision>
      <collision name='rear_left_3_Link_fixed_joint_lump__lh_foot_Link_collision_1'>
        <pose frame=''>0.247423 0.00038 -0.015 0 -0 0</pose>
        <geometry>
          <mesh>
            <scale>1 1 1</scale>
            <uri>model://simpledog/meshes/rh_foot_Link.STL</uri>
          </mesh>
        </geometry>
        <surface>
          <contact>
            <ode>
              <kp>1e+07</kp>
              <kd>1</kd>
            </ode>
          </contact>
          <friction>
            <ode>
              <mu>100</mu>
              <mu2>100</mu2>
              <fdir1>1 0 0</fdir1>
            </ode>
          </friction>
        </surface>
      </collision>
      <visual name='rear_left_3_Link_visual'>
        <pose frame=''>0 0 0 0 -0 0</pose>
        <geometry>
          <mesh>
            <scale>1 1 1</scale>
            <uri>model://simpledog/meshes/rear_left_3_Link.STL</uri>
          </mesh>
        </geometry>
        <material>
          <script>
            <uri>__default__</uri>
            <name>__default__</name>
          </script>
        </material>
      </visual>
      <visual name='rear_left_3_Link_fixed_joint_lump__lh_foot_Link_visual_1'>
        <pose frame=''>0.247423 0.00038 -0.015 0 -0 0</pose>
        <geometry>
          <mesh>
            <scale>1 1 1</scale>
            <uri>model://simpledog/meshes/rh_foot_Link.STL</uri>
          </mesh>
        </geometry>
        <material>
          <script>
            <name>Gazebo/DarkGrey</name>
            <uri>file://media/materials/scripts/gazebo.material</uri>
          </script>
        </material>
      </visual>
      <velocity_decay/>
      <velocity_decay/>
      <gravity>0</gravity>
      <velocity_decay/>
      <self_collide>0</self_collide>
      <sensor name='lh_foot_contact_sensor' type='contact'>
        <update_rate>100</update_rate>
        <contact>
          <collision>rear_right_3_Link_fixed_joint_lump__lh_foot_Link_collision_1</collision>
          <topic>__default_topic__</topic>
        </contact>
        <plugin name='lh_foot_gazebo_ros_bumper_controller' filename='libgazebo_ros_bumper.so'>
          <alwaysOn>true</alwaysOn>
          <frameName>lh_foot_Link</frameName>
          <updateRate>100.0</updateRate>
          <bumperTopicName>lh_foot_bumper</bumperTopicName>
        </plugin>
        <pose frame=''>0.247423 0.00038 -0.015 0 -0 0</pose>
      </sensor>
    </link>
    <joint name='rear_left_3_joint' type='revolute'>
      <child>rear_left_3_Link</child>
      <parent>rear_left_2_Link</parent>
      <axis>
        <xyz>-0 0.999984 0.005597</xyz>
        <limit>
          <lower>-3</lower>
          <upper>3</upper>
          <effort>300</effort>
          <velocity>10</velocity>
        </limit>
        <dynamics>
          <spring_reference>0</spring_reference>
          <spring_stiffness>0</spring_stiffness>
        </dynamics>
        <use_parent_model_frame>1</use_parent_model_frame>
      </axis>
      <physics>
        <provide_feedback>1</provide_feedback>
        <ode>
          <provide_feedback>1</provide_feedback>
          <limit>
            <cfm>0</cfm>
            <erp>0.2</erp>
          </limit>
        </ode>
      </physics>
    </joint>
    <link name='rear_right_1_Link'>
      <pose frame=''>-0.4 -0.175 0 -1.57079 1.57079 1.57079</pose>
      <inertial>
        <pose frame=''>-6e-06 0.012793 0.000302 0 -0 0</pose>
        <mass>1.1709</mass>
        <inertia>
          <ixx>0.001719</ixx>
          <ixy>1.9803e-07</ixy>
          <ixz>-1.4315e-19</ixz>
          <iyy>0.0013167</iyy>
          <iyz>-1.2614e-19</iyz>
          <izz>0.0021511</izz>
        </inertia>
      </inertial>
      <collision name='rear_right_1_Link_collision'>
        <pose frame=''>0 0 0 0 -0 0</pose>
        <geometry>
          <mesh>
            <scale>1 1 1</scale>
            <uri>model://simpledog/meshes/rear_right_1_Link.STL</uri>
          </mesh>
        </geometry>
        <surface>
          <contact>
            <ode>
              <kp>1e+07</kp>
              <kd>1</kd>
            </ode>
          </contact>
          <friction>
            <ode>
              <mu>100</mu>
              <mu2>100</mu2>
              <fdir1>1 0 0</fdir1>
            </ode>
          </friction>
        </surface>
      </collision>
      <visual name='rear_right_1_Link_visual'>
        <pose frame=''>0 0 0 0 -0 0</pose>
        <geometry>
          <mesh>
            <scale>1 1 1</scale>
            <uri>model://simpledog/meshes/rear_right_1_Link.STL</uri>
          </mesh>
        </geometry>
        <material>
          <script>
            <uri>__default__</uri>
            <name>__default__</name>
          </script>
        </material>
      </visual>
      <gravity>1</gravity>
      <velocity_decay/>
      <self_collide>0</self_collide>
    </link>
    <joint name='rear_right_1_joint' type='revolute'>
      <child>rear_right_1_Link</child>
      <parent>base_link</parent>
      <axis>
        <xyz>-1 7e-06 0</xyz>
        <limit>
          <lower>-3</lower>
          <upper>3</upper>
          <effort>300</effort>
          <velocity>10</velocity>
        </limit>
        <dynamics>
          <spring_reference>0</spring_reference>
          <spring_stiffness>0</spring_stiffness>
        </dynamics>
        <use_parent_model_frame>1</use_parent_model_frame>
      </axis>
      <physics>
        <provide_feedback>1</provide_feedback>
        <ode>
          <provide_feedback>1</provide_feedback>
          <limit>
            <cfm>0</cfm>
            <erp>0.2</erp>
          </limit>
        </ode>
      </physics>
    </joint>
    <link name='rear_right_2_Link'>
      <pose frame=''>-0.4 -0.175 0 3.14159 1.57079 1.57079</pose>
      <inertial>
        <pose frame=''>0.11443 -8.4e-05 0.05942 0 -0 0</pose>
        <mass>1.3902</mass>
        <inertia>
          <ixx>0.0030209</ixx>
          <ixy>-4.1489e-12</ixy>
          <ixz>-1.2337e-09</ixz>
          <iyy>0.026876</iyy>
          <iyz>5.4085e-06</iyz>
          <izz>0.028484</izz>
        </inertia>
      </inertial>
      <collision name='rear_right_2_Link_collision'>
        <pose frame=''>0 0 0 0 -0 0</pose>
        <geometry>
          <mesh>
            <scale>1 1 1</scale>
            <uri>model://simpledog/meshes/rear_right_2_Link.STL</uri>
          </mesh>
        </geometry>
        <surface>
          <contact>
            <ode>
              <kp>1e+07</kp>
              <kd>1</kd>
            </ode>
          </contact>
          <friction>
            <ode>
              <mu>100</mu>
              <mu2>100</mu2>
              <fdir1>1 0 0</fdir1>
            </ode>
          </friction>
        </surface>
      </collision>
      <visual name='rear_right_2_Link_visual'>
        <pose frame=''>0 0 0 0 -0 0</pose>
        <geometry>
          <mesh>
            <scale>1 1 1</scale>
            <uri>model://simpledog/meshes/rear_right_2_Link.STL</uri>
          </mesh>
        </geometry>
        <material>
          <script>
            <uri>__default__</uri>
            <name>__default__</name>
          </script>
        </material>
      </visual>
      <gravity>1</gravity>
      <velocity_decay/>
      <self_collide>0</self_collide>
    </link>
    <joint name='rear_right_2_joint' type='revolute'>
      <child>rear_right_2_Link</child>
      <parent>rear_right_1_Link</parent>
      <axis>
        <xyz>-4e-06 -1 -4e-06</xyz>
        <limit>
          <lower>-3</lower>
          <upper>3</upper>
          <effort>300</effort>
          <velocity>10</velocity>
        </limit>
        <dynamics>
          <spring_reference>0</spring_reference>
          <spring_stiffness>0</spring_stiffness>
        </dynamics>
        <use_parent_model_frame>1</use_parent_model_frame>
      </axis>
      <physics>
        <provide_feedback>1</provide_feedback>
        <ode>
          <provide_feedback>1</provide_feedback>
          <limit>
            <cfm>0</cfm>
            <erp>0.2</erp>
          </limit>
        </ode>
      </physics>
    </joint>
    <link name='rear_right_3_Link'>
      <pose frame=''>-0.3999 -0.289419 -0.250104 3.14159 1.57079 1.57079</pose>
      <inertial>
        <pose frame=''>0.094919 1.9e-05 -0.016661 0 -0 0</pose>
        <mass>1.40792</mass>
        <inertia>
          <ixx>0.000546935</ixx>
          <ixy>-4.11097e-06</ixy>
          <ixz>-0.000221917</ixz>
          <iyy>0.0108802</iyy>
          <iyz>-5.46996e-09</iyz>
          <izz>0.0110755</izz>
        </inertia>
      </inertial>
      <collision name='rear_right_3_Link_collision'>
        <pose frame=''>0 0 0 0 -0 0</pose>
        <geometry>
          <mesh>
            <scale>1 1 1</scale>
            <uri>model://simpledog/meshes/rear_right_3_Link.STL</uri>
          </mesh>
        </geometry>
        <surface>
          <contact>
            <ode>
              <kp>1e+07</kp>
              <kd>1</kd>
            </ode>
          </contact>
          <friction>
            <ode>
              <mu>100</mu>
              <mu2>100</mu2>
              <fdir1>1 0 0</fdir1>
            </ode>
          </friction>
        </surface>
      </collision>
      <collision name='rear_right_3_Link_fixed_joint_lump__rh_foot_Link_collision_1'>
        <pose frame=''>0.24968 0.000334 -0.015 0 -0 0</pose>
        <geometry>
          <mesh>
            <scale>1 1 1</scale>
            <uri>model://simpledog/meshes/lh_foot_Link.STL</uri>
          </mesh>
        </geometry>
        <surface>
          <contact>
            <ode>
              <kp>1e+07</kp>
              <kd>1</kd>
            </ode>
          </contact>
          <friction>
            <ode>
              <mu>100</mu>
              <mu2>100</mu2>
              <fdir1>1 0 0</fdir1>
            </ode>
          </friction>
        </surface>
      </collision>
      <visual name='rear_right_3_Link_visual'>
        <pose frame=''>0 0 0 0 -0 0</pose>
        <geometry>
          <mesh>
            <scale>1 1 1</scale>
            <uri>model://simpledog/meshes/rear_right_3_Link.STL</uri>
          </mesh>
        </geometry>
        <material>
          <script>
            <uri>__default__</uri>
            <name>__default__</name>
          </script>
        </material>
      </visual>
      <visual name='rear_right_3_Link_fixed_joint_lump__rh_foot_Link_visual_1'>
        <pose frame=''>0.24968 0.000334 -0.015 0 -0 0</pose>
        <geometry>
          <mesh>
            <scale>1 1 1</scale>
            <uri>model://simpledog/meshes/lh_foot_Link.STL</uri>
          </mesh>
        </geometry>
        <material>
          <script>
            <name>Gazebo/DarkGrey</name>
            <uri>file://media/materials/scripts/gazebo.material</uri>
          </script>
        </material>
      </visual>
      <velocity_decay/>
      <velocity_decay/>
      <gravity>0</gravity>
      <velocity_decay/>
      <self_collide>0</self_collide>
      <sensor name='rh_foot_contact_sensor' type='contact'>
        <update_rate>100</update_rate>
        <contact>
          <collision>rear_left_3_Link_fixed_joint_lump__rh_foot_Link_collision_1</collision>
          <topic>__default_topic__</topic>
        </contact>
        <plugin name='rh_foot_gazebo_ros_bumper_controller' filename='libgazebo_ros_bumper.so'>
          <alwaysOn>true</alwaysOn>
          <frameName>rh_foot_Link</frameName>
          <updateRate>100.0</updateRate>
          <bumperTopicName>rh_foot_bumper</bumperTopicName>
        </plugin>
        <pose frame=''>0.24968 0.000334 -0.015 0 -0 0</pose>
      </sensor>
    </link>
    <joint name='rear_right_3_joint' type='revolute'>
      <child>rear_right_3_Link</child>
      <parent>rear_right_2_Link</parent>
      <axis>
        <xyz>-4e-06 -1 -4e-06</xyz>
        <limit>
          <lower>-3</lower>
          <upper>3</upper>
          <effort>300</effort>
          <velocity>10</velocity>
        </limit>
        <dynamics>
          <spring_reference>0</spring_reference>
          <spring_stiffness>0</spring_stiffness>
        </dynamics>
        <use_parent_model_frame>1</use_parent_model_frame>
      </axis>
      <physics>
        <provide_feedback>1</provide_feedback>
        <ode>
          <provide_feedback>1</provide_feedback>
          <limit>
            <cfm>0</cfm>
            <erp>0.2</erp>
          </limit>
        </ode>
      </physics>
    </joint>
    <plugin name='balance_controller' filename='librobot_state_gazebo_ros_control_plugin.so'>
      <robotNamespace>/simpledog</robotNamespace>
      <robotSimType>balance_controller/SimRobotStateHardwareInterface</robotSimType>
    </plugin>
    <plugin name='ft_sensor' filename='libgazebo_ros_ft_sensor.so'>
      <updateRate>100.0</updateRate>
      <topicName>front_left_1_joint_ft_feedback</topicName>
      <jointName>front_left_1_joint</jointName>
    </plugin>
    <plugin name='ft_sensor' filename='libgazebo_ros_ft_sensor.so'>
      <updateRate>100.0</updateRate>
      <topicName>front_left_2_joint_ft_feedback</topicName>
      <jointName>front_left_2_joint</jointName>
    </plugin>
    <plugin name='ft_sensor' filename='libgazebo_ros_ft_sensor.so'>
      <updateRate>100.0</updateRate>
      <topicName>front_left_3_joint_ft_feedback</topicName>
      <jointName>front_left_3_joint</jointName>
    </plugin>
    <plugin name='ft_sensor' filename='libgazebo_ros_ft_sensor.so'>
      <updateRate>100.0</updateRate>
      <topicName>front_right_1_joint_ft_feedback</topicName>
      <jointName>front_right_1_joint</jointName>
    </plugin>
    <plugin name='ft_sensor' filename='libgazebo_ros_ft_sensor.so'>
      <updateRate>100.0</updateRate>
      <topicName>front_right_2_joint_ft_feedback</topicName>
      <jointName>front_right_2_joint</jointName>
    </plugin>
    <plugin name='ft_sensor' filename='libgazebo_ros_ft_sensor.so'>
      <updateRate>100.0</updateRate>
      <topicName>front_right_3_joint_ft_feedback</topicName>
      <jointName>front_right_3_joint</jointName>
    </plugin>
    <plugin name='ft_sensor' filename='libgazebo_ros_ft_sensor.so'>
      <updateRate>100.0</updateRate>
      <topicName>rear_right_1_joint_ft_feedback</topicName>
      <jointName>rear_right_1_joint</jointName>
    </plugin>
    <plugin name='ft_sensor' filename='libgazebo_ros_ft_sensor.so'>
      <updateRate>100.0</updateRate>
      <topicName>rear_right_2_joint_ft_feedback</topicName>
      <jointName>rear_right_2_joint</jointName>
    </plugin>
    <plugin name='ft_sensor' filename='libgazebo_ros_ft_sensor.so'>
      <updateRate>100.0</updateRate>
      <topicName>rear_right_3_joint_ft_feedback</topicName>
      <jointName>rear_right_3_joint</jointName>
    </plugin>
    <plugin name='ft_sensor' filename='libgazebo_ros_ft_sensor.so'>
      <updateRate>100.0</updateRate>
      <topicName>rear_left_1_joint_ft_feedback</topicName>
      <jointName>rear_left_1_joint</jointName>
    </plugin>
    <plugin name='ft_sensor' filename='libgazebo_ros_ft_sensor.so'>
      <updateRate>100.0</updateRate>
      <topicName>rear_left_2_joint_ft_feedback</topicName>
      <jointName>rear_left_2_joint</jointName>
    </plugin>
    <plugin name='ft_sensor' filename='libgazebo_ros_ft_sensor.so'>
      <updateRate>100.0</updateRate>
      <topicName>rear_left_3_joint_ft_feedback</topicName>
      <jointName>rear_left_3_joint</jointName>
    </plugin>
    <plugin name='f3d_lf_foot_controller' filename='libgazebo_ros_f3d.so'>
      <alwaysOn>true</alwaysOn>
      <updateRate>10.0</updateRate>
      <frameName>base_link</frameName>
      <topicName>lf_foot_force_ground_truth</topicName>
      <bodyName>front_left_3_Link</bodyName>
      <xyzOffset>-0.250004 0 0.0149398</xyzOffset>
      <rpyOffset>0 -0 0</rpyOffset>
    </plugin>
    <plugin name='f3d_rf_foot_controller' filename='libgazebo_ros_f3d.so'>
      <alwaysOn>true</alwaysOn>
      <updateRate>10.0</updateRate>
      <frameName>base_link</frameName>
      <topicName>rf_foot_force_ground_truth</topicName>
      <bodyName>front_right_3_Link</bodyName>
      <xyzOffset>-0.25 0 0.015</xyzOffset>
      <rpyOffset>0.000206014 -5.04099e-17 4.9959e-16</rpyOffset>
    </plugin>
    <plugin name='f3d_rh_foot_controller' filename='libgazebo_ros_f3d.so'>
      <alwaysOn>true</alwaysOn>
      <updateRate>10.0</updateRate>
      <frameName>base_link</frameName>
      <topicName>rh_foot_force_ground_truth</topicName>
      <bodyName>rear_right_3_Link</bodyName>
      <xyzOffset>-0.24968 -0.00033355 0.015</xyzOffset>
      <rpyOffset>0 -0 0</rpyOffset>
    </plugin>
    <static>0</static>
    <plugin name='f3d_lh_foot_controller' filename='libgazebo_ros_f3d.so'>
      <alwaysOn>true</alwaysOn>
      <updateRate>10.0</updateRate>
      <frameName>base_link</frameName>
      <topicName>lh_foot_force_ground_truth</topicName>
      <bodyName>rear_left_3_Link</bodyName>
      <xyzOffset>-0.247423 -0.000379575 0.015</xyzOffset>
      <rpyOffset>0 -0 0</rpyOffset>
    </plugin>
  </model>
</sdf>
