<?xml version="1.0" encoding="utf-8"?>
<!-- This URDF was automatically created by SolidWorks to URDF Exporter! Originally created by Stephen Brawner (brawner@gmail.com)
     Commit Version: 1.5.0-0-g9aa0fdb  Build Version: 1.5.7004.21443
     For more information, please see http://wiki.ros.org/sw_urdf_exporter -->
<robot name="quadruped_model" xmlns:xacro="http://ros.org/wiki/xacro">

  <xacro:arg name="laser_visual"  default="false"/>
  <xacro:arg name="camera_visual" default="false"/>
  <xacro:arg name="imu_visual"    default="false"/>
  <xacro:arg name="kinect_enabled"    default="true"/>
    <xacro:include filename="$(find simpledog)/urdf/simpledog_gazebo.urdf.xacro" />
    <xacro:include filename="$(find simpledog)/urdf/joint_gazebo.urdf.xacro" />
    <xacro:include filename="$(find simpledog)/urdf/kinect.urdf.xacro"/>
    <xacro:include filename="$(find simpledog)/urdf/foot_sensor_gazebo.urdf.xacro" />
  <!--load kinect urdf-->
  <xacro:if value="$(arg kinect_enabled)">
    <xacro:kinect_camera prefix="camera" robot_namespace="$(arg robot_namespace)"/>
    <joint name="kinect_frame_joint" type="fixed">
      <origin xyz="0.5 0.0 0.0" rpy="0 0.8 0" />
      <parent link="base_link"/>
      <child link="camera_link"/>
    </joint>
  </xacro:if>

  <!-- simple dog joints macros configure the joint driver and param-->
  <xacro:simpledog_joint joint_prefix="front_left_1_"> </xacro:simpledog_joint>
  <xacro:simpledog_joint joint_prefix="front_left_2_"> </xacro:simpledog_joint>
  <xacro:simpledog_joint joint_prefix="front_left_3_"> </xacro:simpledog_joint>
  <xacro:simpledog_joint joint_prefix="front_right_1_"> </xacro:simpledog_joint>
  <xacro:simpledog_joint joint_prefix="front_right_2_"> </xacro:simpledog_joint>
  <xacro:simpledog_joint joint_prefix="front_right_3_"> </xacro:simpledog_joint>
  <xacro:simpledog_joint joint_prefix="rear_right_1_"> </xacro:simpledog_joint>
  <xacro:simpledog_joint joint_prefix="rear_right_2_"> </xacro:simpledog_joint>
  <xacro:simpledog_joint joint_prefix="rear_right_3_"> </xacro:simpledog_joint>
  <xacro:simpledog_joint joint_prefix="rear_left_1_"> </xacro:simpledog_joint>
  <xacro:simpledog_joint joint_prefix="rear_left_2_"> </xacro:simpledog_joint>
  <xacro:simpledog_joint joint_prefix="rear_left_3_"> </xacro:simpledog_joint>

  <xacro:simpledog_foot_sensors foot_prefix="lf_foot" joint_prefix="front_left_3_"> </xacro:simpledog_foot_sensors>
  <xacro:simpledog_foot_sensors foot_prefix="rf_foot" joint_prefix="front_right_3_"> </xacro:simpledog_foot_sensors>
  <xacro:simpledog_foot_sensors foot_prefix="rh_foot" joint_prefix="rear_right_3_"> </xacro:simpledog_foot_sensors>
  <xacro:simpledog_foot_sensors foot_prefix="lh_foot" joint_prefix="rear_left_3_"> </xacro:simpledog_foot_sensors>


  <link
    name="base_link">
    <inertial>
      <origin
        xyz="0.006699 -0.000736 0.001288"
        rpy="0 0 0" />
      <mass
        value="27.801" />
      <inertia
        ixx="0.263947"
        ixy="-0.003647"
        ixz="0.009059"
        iyy="2.018039"
        iyz="-0.000762"
        izz="2.056397" />
    </inertial>
    <visual>
      <origin
        xyz="0 0 0"
        rpy="0 0 0" />
      <geometry>
        <mesh
          filename="package://simpledog/meshes/quadruped/base_link.STL" />
      </geometry>
      <material
        name="">
        <color
          rgba="0 0 1 1" />
      </material>
    </visual>
    <collision>
      <origin
        xyz="0 0 0"
        rpy="0 0 0" />
      <geometry>
        <mesh
          filename="package://simpledog/meshes/quadruped/base_link.STL" />
      </geometry>
    </collision>
  </link>
  <link
    name="front_left_1_Link">
    <inertial>
      <origin
        xyz="0.000688 0.10488 -0.003776"
        rpy="0 0 0" />
      <mass
        value="2.9231" />
      <inertia
        ixx="0.007845"
        ixy="-0.00025"
        ixz="-7.8E-05"
        iyy="0.005144"
        iyz="0.000967"
        izz="0.00794" />
    </inertial>
    <visual>
      <origin
        xyz="0 0 0"
        rpy="0 0 0" />
      <geometry>
        <mesh
          filename="package://simpledog/meshes/quadruped/Origin_front_left_1_link.STL" />
      </geometry>
      <material
        name="">
        <color
          rgba="0.79216 0.81961 0.93333 1" />
      </material>
    </visual>
    <collision>
      <origin
        xyz="0 0 0"
        rpy="0 0 0" />
      <geometry>
        <mesh
          filename="package://simpledog/meshes/quadruped/Origin_front_left_1_link.STL" />
      </geometry>
    </collision>
  </link>
  <joint
    name="front_left_1_joint"
    type="revolute">
    <origin
      xyz="0.427 0.075 -0.0095"
      rpy="0 1.5708 0" />
    <parent
      link="base_link" />
    <child
      link="front_left_1_Link" />
    <axis
      xyz="0 0 1" />
      <limit
      effort="300"
      velocity="10"
      lower="-3.0"
      upper="3.0"/>
    <dynamics damping="0.7"/>
  </joint>
  <link
    name="front_left_2_Link">
    <inertial>
      <origin
        xyz="0.18475 3.2E-05 0.12906"
        rpy="0 0 0" />
      <mass
        value="4.2164" />
      <inertia
        ixx="0.00627"
        ixy="-0.000181"
        ixz="-8.8E-05"
        iyy="0.029233"
        iyz="9.2E-05"
        izz="0.028163" />
    </inertial>
    <visual>
      <origin
        xyz="0 0 0"
        rpy="0 0 0" />
      <geometry>
        <mesh
          filename="package://simpledog/meshes/quadruped/Origin_front_left_2_link.STL" />
      </geometry>
      <material
        name="">
        <color
          rgba="0.79216 0.81961 0.93333 1" />
      </material>
    </visual>
    <collision>
      <origin
        xyz="0 0 0"
        rpy="0 0 0" />
      <geometry>
        <mesh
          filename="package://simpledog/meshes/quadruped/Origin_front_left_2_link.STL" />
      </geometry>
    </collision>
  </link>
  <joint
    name="front_left_2_joint"
    type="continuous">
    <origin
      xyz="0 0 0"
      rpy="-1.5708 0 0" />
    <parent
      link="front_left_1_Link" />
    <child
      link="front_left_2_Link" />
    <axis
      xyz="0 0 1" />
      <limit
      effort="300"
      velocity="10"
      lower="-7.0"
      upper="7.0"/>
    <dynamics damping="0.7"/>
  </joint>
  <link
    name="front_left_3_Link">
    <inertial>
      <origin
        xyz="0.20231 0.000199 0.22543"
        rpy="0 0 0" />
      <mass
        value="0.44457" />
      <inertia
        ixx="0.000397"
        ixy="-4E-06"
        ixz="0.000261"
        iyy="0.0065"
        iyz="-2.4E-05"
        izz="0.006214" />
    </inertial>
    <visual>
      <origin
        xyz="0 0 0"
        rpy="0 0 0" />
      <geometry>
        <mesh
          filename="package://simpledog/meshes/quadruped/Origin_front_left_3_link.STL" />
      </geometry>
      <material
        name="">
        <color
          rgba="0.79216 0.81961 0.93333 1" />
      </material>
    </visual>
    <collision>
      <origin
        xyz="0 0 0"
        rpy="0 0 0" />
      <geometry>
        <mesh
          filename="package://simpledog/meshes/quadruped/Origin_front_left_3_link.STL" />
      </geometry>
    </collision>
  </link>
  <joint
    name="front_left_3_joint"
    type="continuous">
    <origin
      xyz="0.308 0 0"
      rpy="0 0 0" />
    <parent
      link="front_left_2_Link" />
    <child
      link="front_left_3_Link" />
    <axis
      xyz="0 0 1" />
      <limit
      effort="300"
      velocity="10"
      lower="-3.0"
      upper="3.0"/>
      <dynamics damping="0.7"/>
  </joint>
  <link
    name="lf_foot_Link">
    <inertial>
      <origin
        xyz="0.022126 -1.2357E-13 0.00049896"
        rpy="0 0 0" />
      <mass
        value="0.03332" />
      <inertia
        ixx="1.9126E-05"
        ixy="-1.1072E-18"
        ixz="-4.1175E-20"
        iyy="0"
        iyz="1.5428E-10"
        izz="1.3678E-05" />
    </inertial>
    <visual>
      <origin
        xyz="0 0 0"
        rpy="0 0 0" />
      <geometry>
        <mesh
          filename="package://simpledog/meshes/quadruped/Origin_lf_foot_link.STL" />
      </geometry>
      <material
        name="">
        <color
          rgba="0 0 0 1" />
      </material>
    </visual>
    <collision>
      <origin
        xyz="0 0 0"
        rpy="0 0 0" />
      <geometry>
        <mesh
          filename="package://simpledog/meshes/quadruped/Origin_lf_foot_link.STL" />
      </geometry>
    </collision>
  </link>
  <joint
    name="lf_foot_joint"
    type="fixed">
    <origin
      xyz="0.308 0 0.23"
      rpy="0 0 0" />
    <parent
      link="front_left_3_Link" />
    <child
      link="lf_foot_Link" />
    <axis
      xyz="0 0 0" />
  </joint>
  <link
    name="front_right_1_Link">
    <inertial>
      <origin
        xyz="-0.000688 0.104882 0.003776"
        rpy="0 0 0" />
      <mass
        value="2.923111" />
      <inertia
        ixx="0.007845"
        ixy="0.00025"
        ixz="-7.8E-05"
        iyy="0.005144"
        iyz="-0.000967"
        izz="0.00794" />
    </inertial>
    <visual>
      <origin
        xyz="0 0 0"
        rpy="0 0 0" />
      <geometry>
        <mesh
          filename="package://simpledog/meshes/quadruped/Origin_front_right_1_link.STL" />
      </geometry>
      <material
        name="">
        <color
          rgba="0.79216 0.81961 0.93333 1" />
      </material>
    </visual>
    <collision>
      <origin
        xyz="0 0 0"
        rpy="0 0 0" />
      <geometry>
        <mesh
          filename="package://simpledog/meshes/quadruped/Origin_front_right_1_link.STL" />
      </geometry>
    </collision>
  </link>
  <joint
    name="front_right_1_joint"
    type="revolute">
    <origin
      xyz="0.427 -0.075 -0.0095"
      rpy="3.1416 1.5708 0" />
    <parent
      link="base_link" />
    <child
      link="front_right_1_Link" />
    <axis
      xyz="0 0 1" />
      <limit
      effort="300"
      velocity="10"
      lower="-3.0"
      upper="3.0"/>
    <dynamics damping="0.7"/>
  </joint>
  <link
    name="front_right_2_Link">
    <inertial>
      <origin
        xyz="0.184747 3.2E-05 0.129056"
        rpy="0 0 0" />
      <mass
        value="4.216358" />
      <inertia
        ixx="0.00627"
        ixy="-0.000181"
        ixz="-8.8E-05"
        iyy="0.029233"
        iyz="9.2E-05"
        izz="0.028163" />
    </inertial>
    <visual>
      <origin
        xyz="0 0 0"
        rpy="0 0 0" />
      <geometry>
        <mesh
          filename="package://simpledog/meshes/quadruped/Origin_front_right_2_link.STL" />
      </geometry>
      <material
        name="">
        <color
          rgba="0.79216 0.81961 0.93333 1" />
      </material>
    </visual>
    <collision>
      <origin
        xyz="0 0 0"
        rpy="0 0 0" />
      <geometry>
        <mesh
          filename="package://simpledog/meshes/quadruped/Origin_front_right_2_link.STL" />
      </geometry>
    </collision>
  </link>
  <joint
    name="front_right_2_joint"
    type="continuous">
    <origin
      xyz="0 0 0"
      rpy="-1.5708 0 0" />
    <parent
      link="front_right_1_Link" />
    <child
      link="front_right_2_Link" />
    <axis
      xyz="0 0 1" />
      <limit
      effort="300"
      velocity="10"
      lower="-7.0"
      upper="7.0"/>
    <dynamics damping="0.7"/>
  </joint>
  <link
    name="front_right_3_Link">
    <inertial>
      <origin
        xyz="0.202313 0.000199 0.225432"
        rpy="0 0 0" />
      <mass
        value="0.444569" />
      <inertia
        ixx="0.000397"
        ixy="-4E-06"
        ixz="0.000261"
        iyy="0.0065"
        iyz="-2.4E-05"
        izz="0.006214" />
    </inertial>
    <visual>
      <origin
        xyz="0 0 0"
        rpy="0 0 0" />
      <geometry>
        <mesh
          filename="package://simpledog/meshes/quadruped/Origin_front_right_3_link.STL" />
      </geometry>
      <material
        name="">
        <color
          rgba="0.79216 0.81961 0.93333 1" />
      </material>
    </visual>
    <collision>
      <origin
        xyz="0 0 0"
        rpy="0 0 0" />
      <geometry>
        <mesh
          filename="package://simpledog/meshes/quadruped/Origin_front_right_3_link.STL" />
      </geometry>
    </collision>
  </link>
  <joint
    name="front_right_3_joint"
    type="continuous">
    <origin
      xyz="0.308 0 0"
      rpy="0 0 0" />
    <parent
      link="front_right_2_Link" />
    <child
      link="front_right_3_Link" />
    <axis
      xyz="0 0 1" />
      <limit
      effort="300"
      velocity="10"
      lower="-3.0"
      upper="3.0"/>
    <dynamics damping="0.7"/>
  </joint>
  <link
    name="rf_foot_Link">
    <inertial>
      <origin
        xyz="0.022126 -4.4892E-13 -1.0375E-06"
        rpy="0 0 0" />
      <mass
        value="0.03332" />
      <inertia
        ixx="1.9126E-05"
        ixy="-1.0162E-18"
        ixz="-1.1377E-19"
        iyy="1.3677E-05"
        iyz="-6.5798E-11"
        izz="1.3678E-05" />
    </inertial>
    <visual>
      <origin
        xyz="0 0 0"
        rpy="0 0 0" />
      <geometry>
        <mesh
          filename="package://simpledog/meshes/quadruped/Orgin_rf_foot_link.STL" />
      </geometry>
      <material
        name="">
        <color
          rgba="0 0 0 1" />
      </material>
    </visual>
    <collision>
      <origin
        xyz="0 0 0"
        rpy="0 0 0" />
      <geometry>
        <mesh
          filename="package://simpledog/meshes/quadruped/Orgin_rf_foot_link.STL" />
      </geometry>
    </collision>
  </link>
  <joint
    name="rf_foot_Link"
    type="fixed">
    <origin
      xyz="0.308 0 0.22053"
      rpy="0 0 0" />
    <parent
      link="front_right_3_Link" />
    <child
      link="rf_foot_Link" />
    <axis
      xyz="0 0 0" />
  </joint>
  <link
    name="rear_left_1_Link">
    <inertial>
      <origin
        xyz="-0.000688 0.10488 0.003776"
        rpy="0 0 0" />
      <mass
        value="2.9231" />
      <inertia
        ixx="0.007845"
        ixy="0.0025"
        ixz="-7.8E-05"
        iyy="0.005144"
        iyz="-0.000967"
        izz="0.00794" />
    </inertial>
    <visual>
      <origin
        xyz="0 0 0"
        rpy="0 0 0" />
      <geometry>
        <mesh
          filename="package://simpledog/meshes/quadruped/Origin_rear_left_1_link.STL" />
      </geometry>
      <material
        name="">
        <color
          rgba="0.79216 0.81961 0.93333 1" />
      </material>
    </visual>
    <collision>
      <origin
        xyz="0 0 0"
        rpy="0 0 0" />
      <geometry>
        <mesh
          filename="package://simpledog/meshes/quadruped/Origin_rear_left_1_link.STL" />
      </geometry>
    </collision>
  </link>
  <joint
    name="rear_left_1_joint"
    type="revolute">
    <origin
      xyz="-0.427 0.075 -0.0095"
      rpy="0 1.5708 0" />
    <parent
      link="base_link" />
    <child
      link="rear_left_1_Link" />
    <axis
      xyz="0 0 1" />
      <limit
      effort="300"
      velocity="10"
      lower="-3.0"
      upper="3.0"/>
    <dynamics damping="0.7"/>
  </joint>
  <link
    name="rear_left_2_Link">
    <inertial>
      <origin
        xyz="0.184717 3.2E-05 0.129056"
        rpy="0 0 0" />
      <mass
        value="4.216358" />
      <inertia
        ixx="0.00627"
        ixy="-0.000181"
        ixz="-8.8E-05"
        iyy="0.029233"
        iyz="9.2E-05"
        izz="0.028163" />
    </inertial>
    <visual>
      <origin
        xyz="0 0 0"
        rpy="0 0 0" />
      <geometry>
        <mesh
          filename="package://simpledog/meshes/quadruped/Origin_rear_left_2_link.STL" />
      </geometry>
      <material
        name="">
        <color
          rgba="0.79216 0.81961 0.93333 1" />
      </material>
    </visual>
    <collision>
      <origin
        xyz="0 0 0"
        rpy="0 0 0" />
      <geometry>
        <mesh
          filename="package://simpledog/meshes/quadruped/Origin_rear_left_2_link.STL" />
      </geometry>
    </collision>
  </link>
  <joint
    name="rear_left_2_joint"
    type="continuous">
    <origin
      xyz="0 0 0"
      rpy="-1.5708 0 0" />
    <parent
      link="rear_left_1_Link" />
    <child
      link="rear_left_2_Link" />
    <axis
      xyz="0 0 1" />
      <limit
      effort="300"
      velocity="10"
      lower="-7.0"
      upper="7.0"/>
    <dynamics damping="0.7"/>
  </joint>
  <link
    name="rear_left_3_Link">
    <inertial>
      <origin
        xyz="0.202313 0.000199 0.225432"
        rpy="0 0 0" />
      <mass
        value="0.444569" />
      <inertia
        ixx="0.000397"
        ixy="-4E-06"
        ixz="-0.000261"
        iyy="0.0065"
        iyz="-2.4E-05"
        izz="0.006214" />
    </inertial>
    <visual>
      <origin
        xyz="0 0 0"
        rpy="0 0 0" />
      <geometry>
        <mesh
          filename="package://simpledog/meshes/quadruped/Origin_rear_left_3_link.STL" />
      </geometry>
      <material
        name="">
        <color
          rgba="0.79216 0.81961 0.93333 1" />
      </material>
    </visual>
    <collision>
      <origin
        xyz="0 0 0"
        rpy="0 0 0" />
      <geometry>
        <mesh
          filename="package://simpledog/meshes/quadruped/Origin_rear_left_3_link.STL" />
      </geometry>
    </collision>
  </link>
  <joint
    name="rear_left_3_joint"
    type="continuous">
    <origin
      xyz="0.308 0 0"
      rpy="0 0 0" />
    <parent
      link="rear_left_2_Link" />
    <child
      link="rear_left_3_Link" />
    <axis
      xyz="0 0 1" />
      <limit
      effort="300"
      velocity="10"
      lower="-3.0"
      upper="3.0"/>
    <dynamics damping="0.7"/>
  </joint>
  <link
    name="lh_foot_Link">
    <inertial>
      <origin
        xyz="0.022126 -7.7827E-14 0.00049896"
        rpy="0 0 0" />
      <mass
        value="0.03332" />
      <inertia
        ixx="1.9126E-05"
        ixy="-9.3607E-19"
        ixz="2.2915E-19"
        iyy="1.3677E-05"
        iyz="-2.7943E-10"
        izz="1.3678E-05" />
    </inertial>
    <visual>
      <origin
        xyz="0 0 0"
        rpy="0 0 0" />
      <geometry>
        <mesh
          filename="package://simpledog/meshes/quadruped/Origin_rl_foot_link.STL" />
      </geometry>
      <material
        name="">
        <color
          rgba="0 0 0 1" />
      </material>
    </visual>
    <collision>
      <origin
        xyz="0 0 0"
        rpy="0 0 0" />
      <geometry>
        <mesh
          filename="package://simpledog/meshes/quadruped/Origin_rl_foot_link.STL" />
      </geometry>
    </collision>
  </link>
  <joint
    name="lh_foot_joint"
    type="fixed">
    <origin
      xyz="0.308 0 0.23"
      rpy="0 0 0" />
    <parent
      link="rear_left_3_Link" />
    <child
      link="lh_foot_Link" />
    <axis
      xyz="0 0 0" />
  </joint>
  <link
    name="rear_right_1_Link">
    <inertial>
      <origin
        xyz="0.000688 0.104882 0.003776"
        rpy="0 0 0" />
      <mass
        value="2.923111" />
      <inertia
        ixx="0.007845"
        ixy="-0.00025"
        ixz="7.8E-05"
        iyy="0.005144"
        iyz="0.000967"
        izz="0.00794" />
    </inertial>
    <visual>
      <origin
        xyz="0 0 0"
        rpy="0 0 0" />
      <geometry>
        <mesh
          filename="package://simpledog/meshes/quadruped/Origin_rear_right_1_link.STL" />
      </geometry>
      <material
        name="">
        <color
          rgba="0.79216 0.81961 0.93333 1" />
      </material>
    </visual>
    <collision>
      <origin
        xyz="0 0 0"
        rpy="0 0 0" />
      <geometry>
        <mesh
          filename="package://simpledog/meshes/quadruped/Origin_rear_right_1_link.STL" />
      </geometry>
    </collision>
  </link>
  <joint
    name="rear_right_1_joint"
    type="revolute">
    <origin
      xyz="-0.427 -0.075 -0.0095"
      rpy="3.1416 1.5708 0" />
    <parent
      link="base_link" />
    <child
      link="rear_right_1_Link" />
    <axis
      xyz="0 0 1" />
      <limit
      effort="300"
      velocity="10"
      lower="-3.0"
      upper="3.0"/>
    <dynamics damping="0.7"/>
  </joint>
  <link
    name="rear_right_2_Link">
    <inertial>
      <origin
        xyz="0.184747 3.2E-05 0.129056"
        rpy="0 0 0" />
      <mass
        value="4.216358" />
      <inertia
        ixx="0.00627"
        ixy="-0.000181"
        ixz="-8.8E-05"
        iyy="0.029233"
        iyz="9.2E-05"
        izz="0.028163" />
    </inertial>
    <visual>
      <origin
        xyz="0 0 0"
        rpy="0 0 0" />
      <geometry>
        <mesh
          filename="package://simpledog/meshes/quadruped/Origin_rear_right_2_link.STL" />
      </geometry>
      <material
        name="">
        <color
          rgba="0.79216 0.81961 0.93333 1" />
      </material>
    </visual>
    <collision>
      <origin
        xyz="0 0 0"
        rpy="0 0 0" />
      <geometry>
        <mesh
          filename="package://simpledog/meshes/quadruped/Origin_rear_right_2_link.STL" />
      </geometry>
    </collision>
  </link>
  <joint
    name="rear_right_2_joint"
    type="continuous">
    <origin
      xyz="0 0 0"
      rpy="-1.5708 0 0" />
    <parent
      link="rear_right_1_Link" />
    <child
      link="rear_right_2_Link" />
    <axis
      xyz="0 0 1" />
      <limit
      effort="300"
      velocity="10"
      lower="-7.0"
      upper="7.0"/>
    <dynamics damping="0.7"/>
  </joint>
  <link
    name="rear_right_3_Link">
    <inertial>
      <origin
        xyz="0.202313 0.000199 0.225432"
        rpy="0 0 0" />
      <mass
        value="0.444569" />
      <inertia
        ixx="0.000397"
        ixy="-4E-06"
        ixz="0.000261"
        iyy="0.0065"
        iyz="-2.4E-05"
        izz="0.006214" />
    </inertial>
    <visual>
      <origin
        xyz="0 0 0"
        rpy="0 0 0" />
      <geometry>
        <mesh
          filename="package://simpledog/meshes/quadruped/Origin_rear_right_3_link.STL" />
      </geometry>
      <material
        name="">
        <color
          rgba="0.79216 0.81961 0.93333 1" />
      </material>
    </visual>
    <collision>
      <origin
        xyz="0 0 0"
        rpy="0 0 0" />
      <geometry>
        <mesh
          filename="package://simpledog/meshes/quadruped/Origin_rear_right_3_link.STL" />
      </geometry>
    </collision>
  </link>
  <joint
    name="rear_right_3_joint"
    type="continuous">
    <origin
      xyz="0.308 0 0"
      rpy="0 0 0" />
    <parent
      link="rear_right_2_Link" />
    <child
      link="rear_right_3_Link" />
    <axis
      xyz="0 0 1" />
      <limit
      effort="300"
      velocity="10"
      lower="-3.0"
      upper="3.0"/>
    <dynamics damping="0.7"/>
  </joint>
  <link
    name="rh_foot_Link">
    <inertial>
      <origin
        xyz="0.022126 -1.6187E-13 -1E-06"
        rpy="0 0 0" />
      <mass
        value="0.03332" />
      <inertia
        ixx="1.9126E-05"
        ixy="-9.5089E-19"
        ixz="6.7668E-20"
        iyy="1.3677E-05"
        iyz="-2.7242E-10"
        izz="1.3678E-05" />
    </inertial>
    <visual>
      <origin
        xyz="0 0 0"
        rpy="0 0 0" />
      <geometry>
        <mesh
          filename="package://simpledog/meshes/quadruped/Origin_rr_foot_link.STL" />
      </geometry>
      <material
        name="">
        <color
          rgba="0 0 0 1" />
      </material>
    </visual>
    <collision>
      <origin
        xyz="0 0 0"
        rpy="0 0 0" />
      <geometry>
        <mesh
          filename="package://simpledog/meshes/quadruped/Origin_rr_foot_link.STL" />
      </geometry>
    </collision>
  </link>
  <joint
    name="rh_foot_joint"
    type="fixed">
    <origin
      xyz="0.308 0 0.22053"
      rpy="0 0 0" />
    <parent
      link="rear_right_3_Link" />
    <child
      link="rh_foot_Link" />
    <axis
      xyz="0 0 0" />
  </joint>
</robot>
