<?xml version="1.0" ?>
<!-- =================================================================================== -->
<!-- |    This document was autogenerated by xacro from simpledog.urdf.xacro           | -->
<!-- |    EDITING THIS FILE BY HAND IS NOT RECOMMENDED                                 | -->
<!-- =================================================================================== -->
<robot name="simpledog" xmlns:xacro="http://ros.org/wiki/xacro">
  <gazebo reference="base_link">
    <material>Gazebo/DarkGrey</material>
    <mu1 value="10.0"/>
    <mu2 value="10.0"/>
    <kp value="10000000.0"/>
    <kd value="1.0"/>
    <fdir1 value="1 0 0"/>
    <gravity value="ture"/>
  </gazebo>
  <!--load the gazebo rosz-control plug in-->
  <gazebo>
    <plugin filename="libgazebo_ros_control.so" name="gazebo_ros_control">
      <robotNamespace>/simpledog</robotNamespace>
    </plugin>
  </gazebo>
  <!-- <gazebo reference="imu_link">
    <sensor type="imu" name="imu">
      <always_on>true</always_on>
      <visualize>$(arg imu_visual)</visualize>
    </sensor>
    <material>Gazebo/Grey</material>
  </gazebo>

  <gazebo>
    <plugin name="imu_plugin" filename="libgazebo_ros_imu.so">
      <alwaysOn>true</alwaysOn>
      <bodyName>imu_link</bodyName>
      <frameName>imu_link</frameName>
      <topicName>imu</topicName>
      <serviceName>imu_service</serviceName>
      <gaussianNoise>0.0</gaussianNoise>
      <updateRate>200</updateRate>
      <imu>
        <noise>
          <type>gaussian</type>
          <rate>
            <mean>0.0</mean>
            <stddev>2e-4</stddev>
            <bias_mean>0.0000075</bias_mean>
            <bias_stddev>0.0000008</bias_stddev>
          </rate>
          <accel>
            <mean>0.0</mean>
            <stddev>1.7e-2</stddev>
            <bias_mean>0.1</bias_mean>
            <bias_stddev>0.001</bias_stddev>
          </accel>
        </noise>
      </imu>
    </plugin>
  </gazebo>

  <gazebo reference="base_scan">
    <material>Gazebo/FlatBlack</material>
    <sensor type="ray" name="lds_lfcd_sensor">
      <pose>0 0 0 0 0 0</pose>
      <visualize>$(arg laser_visual)</visualize>
      <update_rate>5</update_rate>
      <ray>
        <scan>
          <horizontal>
            <samples>360</samples>
            <resolution>1</resolution>
            <min_angle>0.0</min_angle>
            <max_angle>6.28319</max_angle>
          </horizontal>
        </scan>
        <range>
          <min>0.120</min>
          <max>3.5</max>
          <resolution>0.015</resolution>
        </range>
        <noise>
          <type>gaussian</type>
          <mean>0.0</mean>
          <stddev>0.01</stddev>
        </noise>
      </ray>
      <plugin name="gazebo_ros_lds_lfcd_controller" filename="libgazebo_ros_laser.so">
        <topicName>scan</topicName>
        <frameName>base_scan</frameName>
      </plugin>
    </sensor>
  </gazebo>

  <gazebo reference="camera_rgb_frame">
    <sensor type="depth" name="realsense_R200">
      <always_on>true</always_on>
      <visualize>$(arg camera_visual)</visualize>
      <camera>
          <horizontal_fov>1.3439</horizontal_fov>
          <image>
              <width>1920</width>
              <height>1080</height>
              <format>R8G8B8</format>
          </image>
          <depth_camera></depth_camera>
          <clip>
              <near>0.03</near>
              <far>100</far>
          </clip>
      </camera>
      <plugin name="camera_controller" filename="libgazebo_ros_openni_kinect.so">
        <baseline>0.2</baseline>
        <alwaysOn>true</alwaysOn>
        <updateRate>30.0</updateRate>
        <cameraName>camera</cameraName>
        <frameName>camera_rgb_optical_frame</frameName>
        <imageTopicName>rgb/image_raw</imageTopicName>
        <depthImageTopicName>depth/image_raw</depthImageTopicName>
        <pointCloudTopicName>depth/points</pointCloudTopicName>
        <cameraInfoTopicName>rgb/camera_info</cameraInfoTopicName>
        <depthImageCameraInfoTopicName>depth/camera_info</depthImageCameraInfoTopicName>
        <pointCloudCutoff>0.4</pointCloudCutoff>
            <hackBaseline>0.07</hackBaseline>
            <distortionK1>0.0</distortionK1>
            <distortionK2>0.0</distortionK2>
            <distortionK3>0.0</distortionK3>
            <distortionT1>0.0</distortionT1>
            <distortionT2>0.0</distortionT2>
        <CxPrime>0.0</CxPrime>
        <Cx>0.0</Cx>
        <Cy>0.0</Cy>
        <focalLength>0</focalLength>
        <hackBaseline>0</hackBaseline>
      </plugin>
    </sensor>
  </gazebo>-->
  <!-- Create kinect reference frame -->
  <!-- Add mesh for kinect -->
  <link name="camera_link">
    <origin rpy="0 0 0" xyz="0 0 0"/>
    <mass value="5.238"/>
    <visual>
      <origin rpy="0 0 1.5708" xyz="0 0 0"/>
      <geometry>
        <mesh filename="package://simpledog/meshes/kinect.dae"/>
      </geometry>
    </visual>
    <collision>
      <geometry>
        <box size="0.07 0.3 0.09"/>
      </geometry>
    </collision>
  </link>
  <joint name="camera_optical_joint" type="fixed">
    <origin rpy="-1.5708 0 -1.5708" xyz="0 0 0"/>
    <parent link="camera_link"/>
    <child link="camera_frame_optical"/>
  </joint>
  <link name="camera_frame_optical"/>
  <gazebo reference="camera_link">
    <sensor name="camera" type="depth">
      <always_on>true</always_on>
      <update_rate>10.0</update_rate>
      <camera>
        <horizontal_fov>1.04666666667</horizontal_fov>
        <image>
          <format>R8G8B8</format>
          <width>640</width>
          <height>480</height>
        </image>
        <clip>
          <near>0.05</near>
          <far>8.0</far>
        </clip>
      </camera>
      <plugin filename="libgazebo_ros_openni_kinect.so" name="kinect_camera_controller">
        <cameraName>camera</cameraName>
        <alwaysOn>true</alwaysOn>
        <updateRate>10.0</updateRate>
        <imageTopicName>rgb/image_raw</imageTopicName>
        <depthImageTopicName>depth/image_raw</depthImageTopicName>
        <pointCloudTopicName>depth/points</pointCloudTopicName>
        <cameraInfoTopicName>rgb/camera_info</cameraInfoTopicName>
        <depthImageCameraInfoTopicName>depth/camera_info</depthImageCameraInfoTopicName>
        <frameName>camera_frame_optical</frameName>
        <baseline>0.1</baseline>
        <distortion_k1>0.0</distortion_k1>
        <distortion_k2>0.0</distortion_k2>
        <distortion_k3>0.0</distortion_k3>
        <distortion_t1>0.0</distortion_t1>
        <distortion_t2>0.0</distortion_t2>
        <pointCloudCutoff>0.4</pointCloudCutoff>
        <robotNamespace>/simpledog</robotNamespace>
      </plugin>
    </sensor>
  </gazebo>
  <joint name="kinect_frame_joint" type="fixed">
    <origin rpy="0 0.18 0" xyz="0.3 0 0.1"/>
    <parent link="base_link"/>
    <child link="camera_link"/>
  </joint>
  <gazebo reference="front_left_1_Link">
    <mu1 value="100.0"/>
    <mu2 value="100.0"/>
    <kp value="10000000.0"/>
    <kd value="1.0"/>
    <fdir1 value="1 0 0"/>
  </gazebo>
  <gazebo reference="front_left_1_joint">
    <provideFeedback>true</provideFeedback>
  </gazebo>
  <gazebo>
    <plugin filename="libgazebo_ros_ft_sensor.so" name="ft_sensor">
      <updateRate>100.0</updateRate>
      <topicName>front_left_1_joint_ft_feedback</topicName>
      <jointName>front_left_1_joint</jointName>
    </plugin>
  </gazebo>
  <transmission name="front_left_1_joint_trans" type="SimpleTransmission">
    <type>transmission_interface/SimpleTransmission</type>
    <actuator name="front_left_1_joint_motor">
      <mechanicalReduction>1</mechanicalReduction>
    </actuator>
    <joint name="front_left_1_joint">
      <hardwareInterface>hardware_interface/EffortJointInterface</hardwareInterface>
    </joint>
  </transmission>
  <gazebo reference="front_left_2_Link">
    <mu1 value="100.0"/>
    <mu2 value="100.0"/>
    <kp value="10000000.0"/>
    <kd value="1.0"/>
    <fdir1 value="1 0 0"/>
  </gazebo>
  <gazebo reference="front_left_2_joint">
    <provideFeedback>true</provideFeedback>
  </gazebo>
  <gazebo>
    <plugin filename="libgazebo_ros_ft_sensor.so" name="ft_sensor">
      <updateRate>100.0</updateRate>
      <topicName>front_left_2_joint_ft_feedback</topicName>
      <jointName>front_left_2_joint</jointName>
    </plugin>
  </gazebo>
  <transmission name="front_left_2_joint_trans" type="SimpleTransmission">
    <type>transmission_interface/SimpleTransmission</type>
    <actuator name="front_left_2_joint_motor">
      <mechanicalReduction>1</mechanicalReduction>
    </actuator>
    <joint name="front_left_2_joint">
      <hardwareInterface>hardware_interface/EffortJointInterface</hardwareInterface>
    </joint>
  </transmission>
  <gazebo reference="front_left_3_Link">
    <mu1 value="100.0"/>
    <mu2 value="100.0"/>
    <kp value="10000000.0"/>
    <kd value="1.0"/>
    <fdir1 value="1 0 0"/>
  </gazebo>
  <gazebo reference="front_left_3_joint">
    <provideFeedback>true</provideFeedback>
  </gazebo>
  <gazebo>
    <plugin filename="libgazebo_ros_ft_sensor.so" name="ft_sensor">
      <updateRate>100.0</updateRate>
      <topicName>front_left_3_joint_ft_feedback</topicName>
      <jointName>front_left_3_joint</jointName>
    </plugin>
  </gazebo>
  <transmission name="front_left_3_joint_trans" type="SimpleTransmission">
    <type>transmission_interface/SimpleTransmission</type>
    <actuator name="front_left_3_joint_motor">
      <mechanicalReduction>1</mechanicalReduction>
    </actuator>
    <joint name="front_left_3_joint">
      <hardwareInterface>hardware_interface/EffortJointInterface</hardwareInterface>
    </joint>
  </transmission>
  <gazebo reference="front_right_1_Link">
    <mu1 value="100.0"/>
    <mu2 value="100.0"/>
    <kp value="10000000.0"/>
    <kd value="1.0"/>
    <fdir1 value="1 0 0"/>
  </gazebo>
  <gazebo reference="front_right_1_joint">
    <provideFeedback>true</provideFeedback>
  </gazebo>
  <gazebo>
    <plugin filename="libgazebo_ros_ft_sensor.so" name="ft_sensor">
      <updateRate>100.0</updateRate>
      <topicName>front_right_1_joint_ft_feedback</topicName>
      <jointName>front_right_1_joint</jointName>
    </plugin>
  </gazebo>
  <transmission name="front_right_1_joint_trans" type="SimpleTransmission">
    <type>transmission_interface/SimpleTransmission</type>
    <actuator name="front_right_1_joint_motor">
      <mechanicalReduction>1</mechanicalReduction>
    </actuator>
    <joint name="front_right_1_joint">
      <hardwareInterface>hardware_interface/EffortJointInterface</hardwareInterface>
    </joint>
  </transmission>
  <gazebo reference="front_right_2_Link">
    <mu1 value="100.0"/>
    <mu2 value="100.0"/>
    <kp value="10000000.0"/>
    <kd value="1.0"/>
    <fdir1 value="1 0 0"/>
  </gazebo>
  <gazebo reference="front_right_2_joint">
    <provideFeedback>true</provideFeedback>
  </gazebo>
  <gazebo>
    <plugin filename="libgazebo_ros_ft_sensor.so" name="ft_sensor">
      <updateRate>100.0</updateRate>
      <topicName>front_right_2_joint_ft_feedback</topicName>
      <jointName>front_right_2_joint</jointName>
    </plugin>
  </gazebo>
  <transmission name="front_right_2_joint_trans" type="SimpleTransmission">
    <type>transmission_interface/SimpleTransmission</type>
    <actuator name="front_right_2_joint_motor">
      <mechanicalReduction>1</mechanicalReduction>
    </actuator>
    <joint name="front_right_2_joint">
      <hardwareInterface>hardware_interface/EffortJointInterface</hardwareInterface>
    </joint>
  </transmission>
  <gazebo reference="front_right_3_Link">
    <mu1 value="100.0"/>
    <mu2 value="100.0"/>
    <kp value="10000000.0"/>
    <kd value="1.0"/>
    <fdir1 value="1 0 0"/>
  </gazebo>
  <gazebo reference="front_right_3_joint">
    <provideFeedback>true</provideFeedback>
  </gazebo>
  <gazebo>
    <plugin filename="libgazebo_ros_ft_sensor.so" name="ft_sensor">
      <updateRate>100.0</updateRate>
      <topicName>front_right_3_joint_ft_feedback</topicName>
      <jointName>front_right_3_joint</jointName>
    </plugin>
  </gazebo>
  <transmission name="front_right_3_joint_trans" type="SimpleTransmission">
    <type>transmission_interface/SimpleTransmission</type>
    <actuator name="front_right_3_joint_motor">
      <mechanicalReduction>1</mechanicalReduction>
    </actuator>
    <joint name="front_right_3_joint">
      <hardwareInterface>hardware_interface/EffortJointInterface</hardwareInterface>
    </joint>
  </transmission>
  <gazebo reference="rear_right_1_Link">
    <mu1 value="100.0"/>
    <mu2 value="100.0"/>
    <kp value="10000000.0"/>
    <kd value="1.0"/>
    <fdir1 value="1 0 0"/>
  </gazebo>
  <gazebo reference="rear_right_1_joint">
    <provideFeedback>true</provideFeedback>
  </gazebo>
  <gazebo>
    <plugin filename="libgazebo_ros_ft_sensor.so" name="ft_sensor">
      <updateRate>100.0</updateRate>
      <topicName>rear_right_1_joint_ft_feedback</topicName>
      <jointName>rear_right_1_joint</jointName>
    </plugin>
  </gazebo>
  <transmission name="rear_right_1_joint_trans" type="SimpleTransmission">
    <type>transmission_interface/SimpleTransmission</type>
    <actuator name="rear_right_1_joint_motor">
      <mechanicalReduction>1</mechanicalReduction>
    </actuator>
    <joint name="rear_right_1_joint">
      <hardwareInterface>hardware_interface/EffortJointInterface</hardwareInterface>
    </joint>
  </transmission>
  <gazebo reference="rear_right_2_Link">
    <mu1 value="100.0"/>
    <mu2 value="100.0"/>
    <kp value="10000000.0"/>
    <kd value="1.0"/>
    <fdir1 value="1 0 0"/>
  </gazebo>
  <gazebo reference="rear_right_2_joint">
    <provideFeedback>true</provideFeedback>
  </gazebo>
  <gazebo>
    <plugin filename="libgazebo_ros_ft_sensor.so" name="ft_sensor">
      <updateRate>100.0</updateRate>
      <topicName>rear_right_2_joint_ft_feedback</topicName>
      <jointName>rear_right_2_joint</jointName>
    </plugin>
  </gazebo>
  <transmission name="rear_right_2_joint_trans" type="SimpleTransmission">
    <type>transmission_interface/SimpleTransmission</type>
    <actuator name="rear_right_2_joint_motor">
      <mechanicalReduction>1</mechanicalReduction>
    </actuator>
    <joint name="rear_right_2_joint">
      <hardwareInterface>hardware_interface/EffortJointInterface</hardwareInterface>
    </joint>
  </transmission>
  <gazebo reference="rear_right_3_Link">
    <mu1 value="100.0"/>
    <mu2 value="100.0"/>
    <kp value="10000000.0"/>
    <kd value="1.0"/>
    <fdir1 value="1 0 0"/>
  </gazebo>
  <gazebo reference="rear_right_3_joint">
    <provideFeedback>true</provideFeedback>
  </gazebo>
  <gazebo>
    <plugin filename="libgazebo_ros_ft_sensor.so" name="ft_sensor">
      <updateRate>100.0</updateRate>
      <topicName>rear_right_3_joint_ft_feedback</topicName>
      <jointName>rear_right_3_joint</jointName>
    </plugin>
  </gazebo>
  <transmission name="rear_right_3_joint_trans" type="SimpleTransmission">
    <type>transmission_interface/SimpleTransmission</type>
    <actuator name="rear_right_3_joint_motor">
      <mechanicalReduction>1</mechanicalReduction>
    </actuator>
    <joint name="rear_right_3_joint">
      <hardwareInterface>hardware_interface/EffortJointInterface</hardwareInterface>
    </joint>
  </transmission>
  <gazebo reference="rear_left_1_Link">
    <mu1 value="100.0"/>
    <mu2 value="100.0"/>
    <kp value="10000000.0"/>
    <kd value="1.0"/>
    <fdir1 value="1 0 0"/>
  </gazebo>
  <gazebo reference="rear_left_1_joint">
    <provideFeedback>true</provideFeedback>
  </gazebo>
  <gazebo>
    <plugin filename="libgazebo_ros_ft_sensor.so" name="ft_sensor">
      <updateRate>100.0</updateRate>
      <topicName>rear_left_1_joint_ft_feedback</topicName>
      <jointName>rear_left_1_joint</jointName>
    </plugin>
  </gazebo>
  <transmission name="rear_left_1_joint_trans" type="SimpleTransmission">
    <type>transmission_interface/SimpleTransmission</type>
    <actuator name="rear_left_1_joint_motor">
      <mechanicalReduction>1</mechanicalReduction>
    </actuator>
    <joint name="rear_left_1_joint">
      <hardwareInterface>hardware_interface/EffortJointInterface</hardwareInterface>
    </joint>
  </transmission>
  <gazebo reference="rear_left_2_Link">
    <mu1 value="100.0"/>
    <mu2 value="100.0"/>
    <kp value="10000000.0"/>
    <kd value="1.0"/>
    <fdir1 value="1 0 0"/>
  </gazebo>
  <gazebo reference="rear_left_2_joint">
    <provideFeedback>true</provideFeedback>
  </gazebo>
  <gazebo>
    <plugin filename="libgazebo_ros_ft_sensor.so" name="ft_sensor">
      <updateRate>100.0</updateRate>
      <topicName>rear_left_2_joint_ft_feedback</topicName>
      <jointName>rear_left_2_joint</jointName>
    </plugin>
  </gazebo>
  <transmission name="rear_left_2_joint_trans" type="SimpleTransmission">
    <type>transmission_interface/SimpleTransmission</type>
    <actuator name="rear_left_2_joint_motor">
      <mechanicalReduction>1</mechanicalReduction>
    </actuator>
    <joint name="rear_left_2_joint">
      <hardwareInterface>hardware_interface/EffortJointInterface</hardwareInterface>
    </joint>
  </transmission>
  <gazebo reference="rear_left_3_Link">
    <mu1 value="100.0"/>
    <mu2 value="100.0"/>
    <kp value="10000000.0"/>
    <kd value="1.0"/>
    <fdir1 value="1 0 0"/>
  </gazebo>
  <gazebo reference="rear_left_3_joint">
    <provideFeedback>true</provideFeedback>
  </gazebo>
  <gazebo>
    <plugin filename="libgazebo_ros_ft_sensor.so" name="ft_sensor">
      <updateRate>100.0</updateRate>
      <topicName>rear_left_3_joint_ft_feedback</topicName>
      <jointName>rear_left_3_joint</jointName>
    </plugin>
  </gazebo>
  <transmission name="rear_left_3_joint_trans" type="SimpleTransmission">
    <type>transmission_interface/SimpleTransmission</type>
    <actuator name="rear_left_3_joint_motor">
      <mechanicalReduction>1</mechanicalReduction>
    </actuator>
    <joint name="rear_left_3_joint">
      <hardwareInterface>hardware_interface/EffortJointInterface</hardwareInterface>
    </joint>
  </transmission>
  <gazebo reference="lf_foot_Link">
    <material>Gazebo/DarkGrey</material>
    <mu1 value="100.0"/>
    <mu2 value="100.0"/>
    <kp value="10000000.0"/>
    <kd value="1.0"/>
    <fdir1 value="1 0 0"/>
  </gazebo>
  <gazebo reference="lf_foot_joint">
    <provideFeedback value="true"/>
  </gazebo>
  <gazebo reference="lf_foot_Link">
    <turnGravityOff>true</turnGravityOff>
    <selfCollide>false</selfCollide>
    <sensor name="lf_foot_contact_sensor" type="contact">
      <update_rate>100.0</update_rate>
      <contact>
        <collision>front_left_3_Link_fixed_joint_lump__lf_foot_Link_collision_1</collision>
      </contact>
      <plugin filename="libgazebo_ros_bumper.so" name="lf_foot_gazebo_ros_bumper_controller">
        <alwaysOn>true</alwaysOn>
        <frameName>lf_foot_Link</frameName>
        <!-- <frameName>world</frameName> -->
        <updateRate>100.0</updateRate>
        <bumperTopicName>lf_foot_bumper</bumperTopicName>
      </plugin>
    </sensor>
  </gazebo>
  <!-- <gazebo>
                <plugin name="ft_sensor" filename="libgazebo_ros_ft_sensor.so">
                    <updateRate>100.0</updateRate>
                    <topicName>${foot_prefix}_joint_ft_feedback</topicName>
                    <jointName>${foot_prefix}_joint</jointName>
                </plugin>
            </gazebo> -->
  <gazebo>
    <plugin filename="libgazebo_ros_f3d.so" name="f3d_lf_foot_controller">
      <alwaysOn>true</alwaysOn>
      <updateRate>10.0</updateRate>
      <frameName>base_link</frameName>
      <bodyName>lf_foot_Link</bodyName>
      <topicName>lf_foot_force_ground_truth</topicName>
    </plugin>
  </gazebo>
  <gazebo reference="rf_foot_Link">
    <material>Gazebo/DarkGrey</material>
    <mu1 value="100.0"/>
    <mu2 value="100.0"/>
    <kp value="10000000.0"/>
    <kd value="1.0"/>
    <fdir1 value="1 0 0"/>
  </gazebo>
  <gazebo reference="rf_foot_joint">
    <provideFeedback value="true"/>
  </gazebo>
  <gazebo reference="rf_foot_Link">
    <turnGravityOff>true</turnGravityOff>
    <selfCollide>false</selfCollide>
    <sensor name="rf_foot_contact_sensor" type="contact">
      <update_rate>100.0</update_rate>
      <contact>
        <collision>front_right_3_Link_fixed_joint_lump__rf_foot_Link_collision_1</collision>
      </contact>
      <plugin filename="libgazebo_ros_bumper.so" name="rf_foot_gazebo_ros_bumper_controller">
        <alwaysOn>true</alwaysOn>
        <frameName>rf_foot_Link</frameName>
        <!-- <frameName>world</frameName> -->
        <updateRate>100.0</updateRate>
        <bumperTopicName>rf_foot_bumper</bumperTopicName>
      </plugin>
    </sensor>
  </gazebo>
  <!-- <gazebo>
                <plugin name="ft_sensor" filename="libgazebo_ros_ft_sensor.so">
                    <updateRate>100.0</updateRate>
                    <topicName>${foot_prefix}_joint_ft_feedback</topicName>
                    <jointName>${foot_prefix}_joint</jointName>
                </plugin>
            </gazebo> -->
  <gazebo>
    <plugin filename="libgazebo_ros_f3d.so" name="f3d_rf_foot_controller">
      <alwaysOn>true</alwaysOn>
      <updateRate>10.0</updateRate>
      <frameName>base_link</frameName>
      <bodyName>rf_foot_Link</bodyName>
      <topicName>rf_foot_force_ground_truth</topicName>
    </plugin>
  </gazebo>
  <gazebo reference="rh_foot_Link">
    <material>Gazebo/DarkGrey</material>
    <mu1 value="100.0"/>
    <mu2 value="100.0"/>
    <kp value="10000000.0"/>
    <kd value="1.0"/>
    <fdir1 value="1 0 0"/>
  </gazebo>
  <gazebo reference="rh_foot_joint">
    <provideFeedback value="true"/>
  </gazebo>
  <gazebo reference="rh_foot_Link">
    <turnGravityOff>true</turnGravityOff>
    <selfCollide>false</selfCollide>
    <sensor name="rh_foot_contact_sensor" type="contact">
      <update_rate>100.0</update_rate>
      <contact>
        <collision>rear_left_3_Link_fixed_joint_lump__rh_foot_Link_collision_1</collision>
      </contact>
      <plugin filename="libgazebo_ros_bumper.so" name="rh_foot_gazebo_ros_bumper_controller">
        <alwaysOn>true</alwaysOn>
        <frameName>rh_foot_Link</frameName>
        <!-- <frameName>world</frameName> -->
        <updateRate>100.0</updateRate>
        <bumperTopicName>rh_foot_bumper</bumperTopicName>
      </plugin>
    </sensor>
  </gazebo>
  <!-- <gazebo>
                <plugin name="ft_sensor" filename="libgazebo_ros_ft_sensor.so">
                    <updateRate>100.0</updateRate>
                    <topicName>${foot_prefix}_joint_ft_feedback</topicName>
                    <jointName>${foot_prefix}_joint</jointName>
                </plugin>
            </gazebo> -->
  <gazebo>
    <plugin filename="libgazebo_ros_f3d.so" name="f3d_rh_foot_controller">
      <alwaysOn>true</alwaysOn>
      <updateRate>10.0</updateRate>
      <frameName>base_link</frameName>
      <bodyName>rh_foot_Link</bodyName>
      <topicName>rh_foot_force_ground_truth</topicName>
    </plugin>
  </gazebo>
  <gazebo reference="lh_foot_Link">
    <material>Gazebo/DarkGrey</material>
    <mu1 value="100.0"/>
    <mu2 value="100.0"/>
    <kp value="10000000.0"/>
    <kd value="1.0"/>
    <fdir1 value="1 0 0"/>
  </gazebo>
  <gazebo reference="lh_foot_joint">
    <provideFeedback value="true"/>
  </gazebo>
  <gazebo reference="lh_foot_Link">
    <turnGravityOff>true</turnGravityOff>
    <selfCollide>false</selfCollide>
    <sensor name="lh_foot_contact_sensor" type="contact">
      <update_rate>100.0</update_rate>
      <contact>
        <collision>rear_right_3_Link_fixed_joint_lump__lh_foot_Link_collision_1</collision>
      </contact>
      <plugin filename="libgazebo_ros_bumper.so" name="lh_foot_gazebo_ros_bumper_controller">
        <alwaysOn>true</alwaysOn>
        <frameName>lh_foot_Link</frameName>
        <!-- <frameName>world</frameName> -->
        <updateRate>100.0</updateRate>
        <bumperTopicName>lh_foot_bumper</bumperTopicName>
      </plugin>
    </sensor>
  </gazebo>
  <!-- <gazebo>
                <plugin name="ft_sensor" filename="libgazebo_ros_ft_sensor.so">
                    <updateRate>100.0</updateRate>
                    <topicName>${foot_prefix}_joint_ft_feedback</topicName>
                    <jointName>${foot_prefix}_joint</jointName>
                </plugin>
            </gazebo> -->
  <gazebo>
    <plugin filename="libgazebo_ros_f3d.so" name="f3d_lh_foot_controller">
      <alwaysOn>true</alwaysOn>
      <updateRate>10.0</updateRate>
      <frameName>base_link</frameName>
      <bodyName>lh_foot_Link</bodyName>
      <topicName>lh_foot_force_ground_truth</topicName>
    </plugin>
  </gazebo>
  <limit effort="100" lower="-3.0" upper="3.0" velocity="10"/>
  <link name="base_link">
    <inertial>
      <origin rpy="0 0 0" xyz="2.919E-17 -4.8141E-17 9.4163E-19"/>
      <mass value="15.238"/>
      <inertia ixx="0.74932" ixy="-1.2062E-17" ixz="-2.0602E-16" iyy="2.3017" iyz="-3.8366E-17" izz="2.9675"/>
    </inertial>
    <visual>
      <origin rpy="0 0 0" xyz="0 0 0"/>
      <geometry>
        <mesh filename="package://simpledog/meshes/base_link.STL"/>
      </geometry>
      <material name="">
        <color rgba="1 1 1 1"/>
      </material>
    </visual>
    <collision>
      <origin rpy="0 0 0" xyz="0 0 0"/>
      <geometry>
        <mesh filename="package://simpledog/meshes/base_link.STL"/>
      </geometry>
    </collision>
  </link>
  <link name="front_left_1_Link">
    <inertial>
      <origin rpy="0 0 0" xyz="1.7015E-17 0.012793 -0.00023552"/>
      <mass value="1.1709"/>
      <inertia ixx="0.001719" ixy="2.9302E-20" ixz="-1.6433E-19" iyy="0.0013167" iyz="-7.6795E-20" izz="0.0021511"/>
    </inertial>
    <visual>
      <origin rpy="0 0 0" xyz="0 0 0"/>
      <geometry>
        <mesh filename="package://simpledog/meshes/front_left_1_Link.STL"/>
      </geometry>
      <material name="">
        <color rgba="0.89804 0.91765 0.92941 1"/>
      </material>
    </visual>
    <collision>
      <origin rpy="0 0 0" xyz="0 0 0"/>
      <geometry>
        <mesh filename="package://simpledog/meshes/front_left_1_Link.STL"/>
      </geometry>
    </collision>
  </link>
  <joint name="front_left_1_joint" type="revolute">
    <origin rpy="1.57079632679453 1.57051603921301 1.57079632679453" xyz="0.400 0.175 0"/>
    <parent link="base_link"/>
    <child link="front_left_1_Link"/>
    <axis xyz="0 0 1"/>
    <limit effort="100" lower="-3.0" upper="3.0" velocity="10"/>
  </joint>
  <link name="front_left_2_Link">
    <inertial>
      <origin rpy="0 0 0" xyz="0.11439 0.00028184 0.05942"/>
      <mass value="1.3902"/>
      <inertia ixx="0.0030209" ixy="-5.6504E-20" ixz="2.8413E-18" iyy="0.026875" iyz="1.5349E-06" izz="0.028484"/>
    </inertial>
    <visual>
      <origin rpy="0 0 0" xyz="0 0 0"/>
      <geometry>
        <mesh filename="package://simpledog/meshes/front_left_2_Link.STL"/>
      </geometry>
      <material name="">
        <color rgba="0.89804 0.91765 0.92941 1"/>
      </material>
    </visual>
    <collision>
      <origin rpy="0 0 0" xyz="0 0 0"/>
      <geometry>
        <mesh filename="package://simpledog/meshes/front_left_2_Link.STL"/>
      </geometry>
    </collision>
  </link>
  <joint name="front_left_2_joint" type="revolute">
    <origin rpy="-1.5708 0 0" xyz="0 0 0"/>
    <parent link="front_left_1_Link"/>
    <child link="front_left_2_Link"/>
    <axis xyz="0 0 1"/>
    <limit effort="100" lower="-3.0" upper="3.0" velocity="10"/>
  </joint>
  <link name="front_left_3_Link">
    <inertial>
      <origin rpy="0 0 0" xyz="0.087825 1.529E-05 -0.016708"/>
      <mass value="1.3523"/>
      <inertia ixx="0.00053032" ixy="-8.5291E-07" ixz="-0.00020744" iyy="0.0091429" iyz="-8.3738E-08" izz="0.009338"/>
    </inertial>
    <visual>
      <origin rpy="0 0 0" xyz="0 0 0"/>
      <geometry>
        <mesh filename="package://simpledog/meshes/front_left_3_Link.STL"/>
      </geometry>
      <material name="">
        <color rgba="0.89804 0.91765 0.92941 1"/>
      </material>
    </visual>
    <collision>
      <origin rpy="0 0 0" xyz="0 0 0"/>
      <geometry>
        <mesh filename="package://simpledog/meshes/front_left_3_Link.STL"/>
      </geometry>
    </collision>
  </link>
  <joint name="front_left_3_joint" type="revolute">
    <origin rpy="0 0 0" xyz="0.250069171339977 0.000334332414087979 0.11441948932032"/>
    <parent link="front_left_2_Link"/>
    <child link="front_left_3_Link"/>
    <axis xyz="0 0 1"/>
    <limit effort="100" lower="-3.0" upper="3.0" velocity="10"/>
  </joint>
  <link name="lf_foot_Link">
    <inertial>
      <origin rpy="0 0 0" xyz="0.0178251114319979 0 0"/>
      <mass value="0.0556193699314689"/>
      <inertia ixx="1.65498601680364E-05" ixy="-1.00565663974796E-21" ixz="1.3524403015242E-22" iyy="1.23221647613412E-05" iyz="-3.56241096455504E-11" izz="1.25699738250509E-05"/>
    </inertial>
    <visual>
      <origin rpy="0 0 0" xyz="0 0 0"/>
      <geometry>
        <mesh filename="package://simpledog/meshes/lf_foot_Link.STL"/>
      </geometry>
      <material name="">
        <color rgba="0.298039215686275 0.298039215686275 0.298039215686275 1"/>
      </material>
    </visual>
    <collision>
      <maxContacts>1</maxContacts>
      <origin rpy="0 0 0" xyz="0 0 0"/>
      <geometry>
        <mesh filename="package://simpledog/meshes/lf_foot_Link.STL"/>
      </geometry>
    </collision>
  </link>
  <joint name="lf_foot_joint" type="fixed">
    <origin rpy="0 0 0" xyz="0.250003601978058 0 -0.0149398452771417"/>
    <parent link="front_left_3_Link"/>
    <child link="lf_foot_Link"/>
    <axis xyz="0 0 0"/>
  </joint>
  <link name="front_right_1_Link">
    <inertial>
      <origin rpy="0 0 0" xyz="9.7104E-17 0.012793 1.6653E-16"/>
      <mass value="1.1709"/>
      <inertia ixx="0.001719" ixy="-5.88E-19" ixz="-1.7779E-19" iyy="0.0013167" iyz="-2.0543E-19" izz="0.0021511"/>
    </inertial>
    <visual>
      <origin rpy="0 0 0" xyz="0 0 0"/>
      <geometry>
        <mesh filename="package://simpledog/meshes/front_right_1_Link.STL"/>
      </geometry>
      <material name="">
        <color rgba="0.89804 0.91765 0.92941 1"/>
      </material>
    </visual>
    <collision>
      <origin rpy="0 0 0" xyz="0 0 0"/>
      <geometry>
        <mesh filename="package://simpledog/meshes/front_right_1_Link.STL"/>
      </geometry>
    </collision>
  </link>
  <joint name="front_right_1_joint" type="revolute">
    <origin rpy="1.5708 1.5708 -1.5708" xyz="0.4 -0.175 0"/>
    <parent link="base_link"/>
    <child link="front_right_1_Link"/>
    <axis xyz="0 0 1"/>
    <limit effort="100" lower="-3.0" upper="3.0" velocity="10"/>
  </joint>
  <link name="front_right_2_Link">
    <inertial>
      <origin rpy="0 0 0" xyz="0.11432 -5.5511E-17 0.05942"/>
      <mass value="1.3902"/>
      <inertia ixx="0.0030209" ixy="-4.0905E-18" ixz="-8.1586E-10" iyy="0.026875" iyz="2.3399E-19" izz="0.028484"/>
    </inertial>
    <visual>
      <origin rpy="0 0 0" xyz="0 0 0"/>
      <geometry>
        <mesh filename="package://simpledog/meshes/front_right_2_Link.STL"/>
      </geometry>
      <material name="">
        <color rgba="0.89804 0.91765 0.92941 1"/>
      </material>
    </visual>
    <collision>
      <origin rpy="0 0 0" xyz="0 0 0"/>
      <geometry>
        <mesh filename="package://simpledog/meshes/front_right_2_Link.STL"/>
      </geometry>
    </collision>
  </link>
  <joint name="front_right_2_joint" type="revolute">
    <origin rpy="-1.5708 0 0" xyz="0 0 0"/>
    <parent link="front_right_1_Link"/>
    <child link="front_right_2_Link"/>
    <axis xyz="0 0 1"/>
    <limit effort="100" lower="-3.0" upper="3.0" velocity="10"/>
  </joint>
  <link name="front_right_3_Link">
    <inertial>
      <origin rpy="0 0 0" xyz="0.087821 6.7221E-06 -0.016729"/>
      <mass value="1.3523"/>
      <inertia ixx="0.00053022" ixy="-9.5809E-07" ixz="-0.00020532" iyy="0.0091429" iyz="1.6437E-08" izz="0.0093381"/>
    </inertial>
    <visual>
      <origin rpy="0 0 0" xyz="0 0 0"/>
      <geometry>
        <mesh filename="package://simpledog/meshes/front_right_3_Link.STL"/>
      </geometry>
      <material name="">
        <color rgba="0.89804 0.91765 0.92941 1"/>
      </material>
    </visual>
    <collision>
      <origin rpy="0 0 0" xyz="0 0 0"/>
      <geometry>
        <mesh filename="package://simpledog/meshes/front_right_3_Link.STL"/>
      </geometry>
    </collision>
  </link>
  <joint name="front_right_3_joint" type="revolute">
    <origin rpy="0 0 0" xyz="0.249999996334044 0 0.114419764295838"/>
    <parent link="front_right_2_Link"/>
    <child link="front_right_3_Link"/>
    <axis xyz="0 0 1"/>
    <limit effort="100" lower="-3.0" upper="3.0" velocity="10"/>
  </joint>
  <link name="rf_foot_Link">
    <inertial>
      <origin rpy="0 0 0" xyz="0.017825 0 0"/>
      <mass value="0.055619"/>
      <inertia ixx="1.655E-05" ixy="2.2089E-21" ixz="-1.1638E-21" iyy="1.2322E-05" iyz="-2.0835E-21" izz="1.257E-05"/>
    </inertial>
    <visual>
      <origin rpy="0 0 0" xyz="0 0 0"/>
      <geometry>
        <mesh filename="package://simpledog/meshes/rf_foot_Link.STL"/>
      </geometry>
      <material name="">
        <color rgba="0.29804 0.29804 0.29804 1"/>
      </material>
    </visual>
    <collision>
      <origin rpy="0 0 0" xyz="0 0 0"/>
      <geometry>
        <mesh filename="package://simpledog/meshes/rf_foot_Link.STL"/>
      </geometry>
    </collision>
  </link>
  <joint name="rf_foot_joint" type="fixed">
    <origin rpy="-0.00020601381558494 5.03069808033274E-17 -4.99600361081321E-16" xyz="0.25 0 -0.0149999996816874"/>
    <parent link="front_right_3_Link"/>
    <child link="rf_foot_Link"/>
    <axis xyz="0 0 0"/>
  </joint>
  <link name="rear_left_1_Link">
    <inertial>
      <origin rpy="0 0 0" xyz="5.7896E-17 0.012793 2.7756E-16"/>
      <mass value="1.1709"/>
      <inertia ixx="0.001719" ixy="-2.0371E-19" ixz="5.3128E-21" iyy="0.0013167" iyz="-3.3901E-19" izz="0.0021511"/>
    </inertial>
    <visual>
      <origin rpy="0 0 0" xyz="0 0 0"/>
      <geometry>
        <mesh filename="package://simpledog/meshes/rear_left_1_Link.STL"/>
      </geometry>
      <material name="">
        <color rgba="0.89804 0.91765 0.92941 1"/>
      </material>
    </visual>
    <collision>
      <origin rpy="0 0 0" xyz="0 0 0"/>
      <geometry>
        <mesh filename="package://simpledog/meshes/rear_left_1_Link.STL"/>
      </geometry>
    </collision>
  </link>
  <joint name="rear_left_1_joint" type="revolute">
    <origin rpy="1.57079632679488 1.56519932988528 1.57079632679488" xyz="-0.4 0.175 0"/>
    <parent link="base_link"/>
    <child link="rear_left_1_Link"/>
    <axis xyz="0 0 1"/>
    <limit effort="100" lower="-3.0" upper="3.0" velocity="10"/>
  </joint>
  <link name="rear_left_2_Link">
    <inertial>
      <origin rpy="0 0 0" xyz="0.11432 0 0.05942"/>
      <mass value="1.3902"/>
      <inertia ixx="0.0030209" ixy="-1.8526E-18" ixz="2.5242E-19" iyy="0.026875" iyz="3.7608E-19" izz="0.028484"/>
    </inertial>
    <visual>
      <origin rpy="0 0 0" xyz="0 0 0"/>
      <geometry>
        <mesh filename="package://simpledog/meshes/rear_left_2_Link.STL"/>
      </geometry>
      <material name="">
        <color rgba="0.89804 0.91765 0.92941 1"/>
      </material>
    </visual>
    <collision>
      <origin rpy="0 0 0" xyz="0 0 0"/>
      <geometry>
        <mesh filename="package://simpledog/meshes/rear_left_2_Link.STL"/>
      </geometry>
    </collision>
  </link>
  <joint name="rear_left_2_joint" type="revolute">
    <origin rpy="-1.5707963267949 0 0" xyz="0 0 0"/>
    <parent link="rear_left_1_Link"/>
    <child link="rear_left_2_Link"/>
    <axis xyz="0 0 1"/>
    <limit effort="100" lower="-3.0" upper="3.0" velocity="10"/>
  </joint>
  <link name="rear_left_3_Link">
    <inertial>
      <origin rpy="0 0 0" xyz="0.087821 5.7424E-05 -0.016729"/>
      <mass value="1.3523"/>
      <inertia ixx="0.00053022" ixy="-3.3581E-07" ixz="-0.00020532" iyy="0.0091429" iyz="-5.7512E-07" izz="0.0093381"/>
    </inertial>
    <visual>
      <origin rpy="0 0 0" xyz="0 0 0"/>
      <geometry>
        <mesh filename="package://simpledog/meshes/rear_left_3_Link.STL"/>
      </geometry>
      <material name="">
        <color rgba="0.89804 0.91765 0.92941 1"/>
      </material>
    </visual>
    <collision>
      <origin rpy="0 0 0" xyz="0 0 0"/>
      <geometry>
        <mesh filename="package://simpledog/meshes/rear_left_3_Link.STL"/>
      </geometry>
    </collision>
  </link>
  <joint name="rear_left_3_joint" type="revolute">
    <origin rpy="0 0 0" xyz="0.25 0 0.114419756285561"/>
    <parent link="rear_left_2_Link"/>
    <child link="rear_left_3_Link"/>
    <axis xyz="0 0 1"/>
    <limit effort="100" lower="-3.0" upper="3.0" velocity="10"/>
  </joint>
  <link name="rh_foot_Link">
    <inertial>
      <origin rpy="0 0 0" xyz="0.017825 -1.1102E-16 5.5511E-17"/>
      <mass value="0.055619"/>
      <inertia ixx="1.655E-05" ixy="3.2567E-22" ixz="-9.7111E-22" iyy="1.2322E-05" iyz="5.4896E-20" izz="1.257E-05"/>
    </inertial>
    <visual>
      <origin rpy="0 0 0" xyz="0 0 0"/>
      <geometry>
        <mesh filename="package://simpledog/meshes/rh_foot_Link.STL"/>
      </geometry>
      <material name="">
        <color rgba="0.29804 0.29804 0.29804 1"/>
      </material>
    </visual>
    <collision>
      <origin rpy="0 0 0" xyz="0 0 0"/>
      <geometry>
        <mesh filename="package://simpledog/meshes/rh_foot_Link.STL"/>
      </geometry>
    </collision>
  </link>
  <joint name="rh_foot_joint" type="fixed">
    <origin rpy="0 0 0" xyz="0.24742286767759 0.000379574544590811 -0.015"/>
    <parent link="rear_left_3_Link"/>
    <child link="rh_foot_Link"/>
    <axis xyz="0 0 0"/>
  </joint>
  <link name="rear_right_1_Link">
    <inertial>
      <origin rpy="0 0 0" xyz="-6.2968E-06 0.012793 0.0003022"/>
      <mass value="1.1709"/>
      <inertia ixx="0.001719" ixy="1.9803E-07" ixz="-1.4315E-19" iyy="0.0013167" iyz="-1.2614E-19" izz="0.0021511"/>
    </inertial>
    <visual>
      <origin rpy="0 0 0" xyz="0 0 0"/>
      <geometry>
        <mesh filename="package://simpledog/meshes/rear_right_1_Link.STL"/>
      </geometry>
      <material name="">
        <color rgba="0.89804 0.91765 0.92941 1"/>
      </material>
    </visual>
    <collision>
      <origin rpy="0 0 0" xyz="0 0 0"/>
      <geometry>
        <mesh filename="package://simpledog/meshes/rear_right_1_Link.STL"/>
      </geometry>
    </collision>
  </link>
  <joint name="rear_right_1_joint" type="revolute">
    <origin rpy="1.5708 1.5708 -1.5708" xyz="-0.4 -0.175 0"/>
    <parent link="base_link"/>
    <child link="rear_right_1_Link"/>
    <axis xyz="0 0 1"/>
    <limit effort="100" lower="-3.0" upper="3.0" velocity="10"/>
  </joint>
  <link name="rear_right_2_Link">
    <inertial>
      <origin rpy="0 0 0" xyz="0.11443 -8.407E-05 0.05942"/>
      <mass value="1.3902"/>
      <inertia ixx="0.0030209" ixy="-4.1489E-12" ixz="-1.2337E-09" iyy="0.026876" iyz="5.4085E-06" izz="0.028484"/>
    </inertial>
    <visual>
      <origin rpy="0 0 0" xyz="0 0 0"/>
      <geometry>
        <mesh filename="package://simpledog/meshes/rear_right_2_Link.STL"/>
      </geometry>
      <material name="">
        <color rgba="0.89804 0.91765 0.92941 1"/>
      </material>
    </visual>
    <collision>
      <origin rpy="0 0 0" xyz="0 0 0"/>
      <geometry>
        <mesh filename="package://simpledog/meshes/rear_right_2_Link.STL"/>
      </geometry>
    </collision>
  </link>
  <joint name="rear_right_2_joint" type="revolute">
    <origin rpy="-1.5708 0 0" xyz="0 0 0"/>
    <parent link="rear_right_1_Link"/>
    <child link="rear_right_2_Link"/>
    <axis xyz="0 0 1"/>
    <limit effort="100" lower="-3.0" upper="3.0" velocity="10"/>
  </joint>
  <link name="rear_right_3_Link">
    <inertial>
      <origin rpy="0 0 0" xyz="0.087821 6.0067E-06 -0.016729"/>
      <mass value="1.3523"/>
      <inertia ixx="0.00053022" ixy="-9.6687E-07" ixz="-0.00020532" iyy="0.0091429" iyz="2.4784E-08" izz="0.0093381"/>
    </inertial>
    <visual>
      <origin rpy="0 0 0" xyz="0 0 0"/>
      <geometry>
        <mesh filename="package://simpledog/meshes/rear_right_3_Link.STL"/>
      </geometry>
      <material name="">
        <color rgba="0.89804 0.91765 0.92941 1"/>
      </material>
    </visual>
    <collision>
      <origin rpy="0 0 0" xyz="0 0 0"/>
      <geometry>
        <mesh filename="package://simpledog/meshes/rear_right_3_Link.STL"/>
      </geometry>
    </collision>
  </link>
  <joint name="rear_right_3_joint" type="revolute">
    <origin rpy="0 0 0" xyz="0.25010358767993 0.0001008844556592 0.114420076111023"/>
    <parent link="rear_right_2_Link"/>
    <child link="rear_right_3_Link"/>
    <axis xyz="0 0 1"/>
    <limit effort="100" lower="-3.0" upper="3.0" velocity="10"/>
  </joint>
  <link name="lh_foot_Link">
    <inertial>
      <origin rpy="0 0 0" xyz="0.017825 -1.1102E-16 0"/>
      <mass value="0.055619"/>
      <inertia ixx="1.655E-05" ixy="2.3509E-21" ixz="-1.4161E-21" iyy="1.2322E-05" iyz="6.8491E-22" izz="1.257E-05"/>
    </inertial>
    <visual>
      <origin rpy="0 0 0" xyz="0 0 0"/>
      <geometry>
        <mesh filename="package://simpledog/meshes/lh_foot_Link.STL"/>
      </geometry>
      <material name="">
        <color rgba="0.29804 0.29804 0.29804 1"/>
      </material>
    </visual>
    <collision>
      <origin rpy="0 0 0" xyz="0 0 0"/>
      <geometry>
        <mesh filename="package://simpledog/meshes/lh_foot_Link.STL"/>
      </geometry>
    </collision>
  </link>
  <joint name="lh_foot_joint" type="fixed">
    <origin rpy="0 0 0" xyz="0.24968 0.00033355 -0.015"/>
    <parent link="rear_right_3_Link"/>
    <child link="lh_foot_Link"/>
    <axis xyz="0 0 0"/>
  </joint>
</robot>

