<?xml version="1.0" ?>
<robot name="simpledog" xmlns:xacro="http://ros.org/wiki/xacro">
<xacro:arg name="laser_visual"  default="false"/>
<xacro:arg name="camera_visual" default="false"/>
<xacro:arg name="imu_visual"    default="false"/>
<xacro:arg name="kinect_enabled"    default="true"/>
  <xacro:include filename="$(find simpledog)/urdf/simpledog_gazebo.urdf.xacro" />
  <xacro:include filename="$(find simpledog)/urdf/joint_gazebo.urdf.xacro" />
  <xacro:include filename="$(find simpledog)/urdf/kinect.urdf.xacro"/>
<!--load kinect urdf-->
<xacro:if value="$(arg kinect_enabled)">
  <xacro:kinect_camera prefix="camera" robot_namespace="$(arg robot_namespace)"/>
  <joint name="kinect_frame_joint" type="fixed">
    <origin xyz="-0.3 0 0.1" rpy="0 0.18 3.14159" />
    <parent link="base_link"/>
    <child link="camera_link"/>
  </joint>
</xacro:if>

<!-- simple dog joints macros configure the joint driver and param-->
<xacro:simpledog_joint joint_prefix="front_left_1_"> </xacro:simpledog_joint>
<xacro:simpledog_joint joint_prefix="front_left_2_"> </xacro:simpledog_joint>
<xacro:simpledog_joint joint_prefix="front_left_3_"> </xacro:simpledog_joint>
<xacro:simpledog_joint joint_prefix="front_right_1_"> </xacro:simpledog_joint>
<xacro:simpledog_joint joint_prefix="front_right_2_"> </xacro:simpledog_joint>
<xacro:simpledog_joint joint_prefix="front_right_3_"> </xacro:simpledog_joint>
<xacro:simpledog_joint joint_prefix="rear_right_1_"> </xacro:simpledog_joint>
<xacro:simpledog_joint joint_prefix="rear_right_2_"> </xacro:simpledog_joint>
<xacro:simpledog_joint joint_prefix="rear_right_3_"> </xacro:simpledog_joint>
<xacro:simpledog_joint joint_prefix="rear_left_1_"> </xacro:simpledog_joint>
<xacro:simpledog_joint joint_prefix="rear_left_2_"> </xacro:simpledog_joint>
<xacro:simpledog_joint joint_prefix="rear_left_3_"> </xacro:simpledog_joint>

  <link
    name="base_link">
    <inertial>
      <origin
        xyz="-2.919E-17 4.8611E-17 9.4163E-19"
        rpy="0 0 0" />
      <mass
        value="15.238" />
      <inertia
        ixx="0.74932"
        ixy="-1.2062E-17"
        ixz="-1.9781E-17"
        iyy="2.3017"
        iyz="7.9134E-17"
        izz="2.9675" />
    </inertial>
    <visual>
      <origin
        xyz="0 0 0"
        rpy="0 0 0" />
      <geometry>
        <mesh
          filename="package://simpledog/meshes/base_link.STL" />
      </geometry>
      <material
        name="">
        <color
          rgba="1 1 1 1" />
      </material>
    </visual>
    <collision>
      <origin
        xyz="0 0 0"
        rpy="0 0 0" />
      <geometry>
        <mesh
          filename="package://simpledog/meshes/base_link.STL" />
      </geometry>
    </collision>
  </link>
  <link
    name="front_left_1_Link">
    <inertial>
      <origin
        xyz="-0.012793 -1.5357E-15 0.04"
        rpy="0 0 0" />
      <mass
        value="1.1709" />
      <inertia
        ixx="0.0013167"
        ixy="-4.8862E-17"
        ixz="7.6795E-20"
        iyy="0.001719"
        iyz="-1.6433E-19"
        izz="0.0021511" />
    </inertial>
    <visual>
      <origin
        xyz="0 0 0"
        rpy="0 0 0" />
      <geometry>
        <mesh
          filename="package://simpledog/meshes/front_left_1_Link.STL" />
      </geometry>
      <material
        name="">
        <color
          rgba="0.89804 0.91765 0.92941 1" />
      </material>
    </visual>
    <collision>
      <origin
        xyz="0 0 0"
        rpy="0 0 0" />
      <geometry>
        <mesh
          filename="package://simpledog/meshes/front_left_1_Link.STL" />
      </geometry>
    </collision>
  </link>
  <joint
    name="front_left_1_joint"
    type="revolute">
    <origin
      xyz="-0.36 -0.175 0"
      rpy="-1.5708 0 1.5708" />
    <parent
      link="base_link" />
    <child
      link="front_left_1_Link" />
    <axis
      xyz="0 0 1" />
    <sensor name="force_torque" type="force_torque">
        <update_rate>30</update_rate>
    </sensor>
      <limit
        effort="100"
        velocity="10"
        lower="-3.0"
        upper="3.0"/>
  </joint>
  <link
    name="front_left_2_Link">
    <inertial>
      <origin
        xyz="0.025099 2.8253E-06 -0.11431"
        rpy="0 0 0" />
      <mass
        value="1.3902" />
      <inertia
        ixx="0.028484"
        ixy="2.4654E-16"
        ixz="1.2624E-14"
        iyy="0.026875"
        iyz="5.6397E-18"
        izz="0.0030209" />
    </inertial>
    <visual>
      <origin
        xyz="0 0 0"
        rpy="0 0 0" />
      <geometry>
        <mesh
          filename="package://simpledog/meshes/front_left_2_Link.STL" />
      </geometry>
      <material
        name="">
        <color
          rgba="0.89804 0.91765 0.92941 1" />
      </material>
    </visual>
    <collision>
      <origin
        xyz="0 0 0"
        rpy="0 0 0" />
      <geometry>
        <mesh
          filename="package://simpledog/meshes/front_left_2_Link.STL" />
      </geometry>
    </collision>
  </link>
  <joint
    name="front_left_2_joint"
    type="revolute">
    <origin
      xyz="-0.034321 0 0.04"
      rpy="-1.5708 0 3.1416" />
    <parent
      link="front_left_1_Link" />
    <child
      link="front_left_2_Link" />
    <axis
      xyz="1 0 0" />
      <limit
        effort="100"
        velocity="10"
        lower="-3.0"
        upper="3.0"/>
  </joint>
  <link
    name="front_left_3_Link">
    <inertial>
      <origin
        xyz="-0.043355 -1.0168E-05 -0.087821"
        rpy="0 0 0" />
      <mass
        value="1.3523" />
      <inertia
        ixx="0.0093381"
        ixy="-2.3773E-08"
        ixz="-0.00020532"
        iyy="0.0091429"
        iyz="-9.1579E-07"
        izz="0.00053022" />
    </inertial>
    <visual>
      <origin
        xyz="0 0 0"
        rpy="0 0 0" />
      <geometry>
        <mesh
          filename="package://simpledog/meshes/front_left_3_Link.STL" />
      </geometry>
      <material
        name="">
        <color
          rgba="0.89804 0.91765 0.92941 1" />
      </material>
    </visual>
    <collision>
      <origin
        xyz="0 0 0"
        rpy="0 0 0" />
      <geometry>
        <mesh
          filename="package://simpledog/meshes/front_left_3_Link.STL" />
      </geometry>
    </collision>
  </link>
  <joint
    name="front_left_3_joint"
    type="revolute">
    <origin
      xyz="0.020015 0 -0.24999"
      rpy="0 0 -3.1416" />
    <parent
      link="front_left_2_Link" />
    <child
      link="front_left_3_Link" />
    <axis
      xyz="-1 0 0" />
      <limit
        effort="100"
        velocity="10"
        lower="-3.0"
        upper="3.0"/>
  </joint>
  <link
    name="front_right_1_Link">
    <inertial>
      <origin
        xyz="-0.012793 4.0953E-15 0.04"
        rpy="0 0 0" />
      <mass
        value="1.1709" />
      <inertia
        ixx="0.0013167"
        ixy="1.2874E-16"
        ixz="-2.0543E-19"
        iyy="0.001719"
        iyz="-1.7779E-19"
        izz="0.0021511" />
    </inertial>
    <visual>
      <origin
        xyz="0 0 0"
        rpy="0 0 0" />
      <geometry>
        <mesh
          filename="package://simpledog/meshes/front_right_1_Link.STL" />
      </geometry>
      <material
        name="">
        <color
          rgba="0.89804 0.91765 0.92941 1" />
      </material>
    </visual>
    <collision>
      <origin
        xyz="0 0 0"
        rpy="0 0 0" />
      <geometry>
        <mesh
          filename="package://simpledog/meshes/front_right_1_Link.STL" />
      </geometry>
    </collision>
  </link>
  <joint
    name="front_right_1_joint"
    type="revolute">
    <origin
      xyz="-0.36 0.175 0"
      rpy="1.5708 0 -1.5708" />
    <parent
      link="base_link" />
    <child
      link="front_right_1_Link" />
    <axis
      xyz="0 0 -1" />
      <limit
        effort="100"
        velocity="10"
        lower="-3.0"
        upper="3.0"/>
  </joint>
  <link
    name="front_right_2_Link">
    <inertial>
      <origin
        xyz="0.025 -4.4409E-16 -0.11432"
        rpy="0 0 0" />
      <mass
        value="1.3902" />
      <inertia
        ixx="0.028484"
        ixy="-1.9935E-17"
        ixz="1.0386E-15"
        iyy="0.026875"
        iyz="-1.4151E-17"
        izz="0.0030209" />
    </inertial>
    <visual>
      <origin
        xyz="0 0 0"
        rpy="0 0 0" />
      <geometry>
        <mesh
          filename="package://simpledog/meshes/front_right_2_Link.STL" />
      </geometry>
      <material
        name="">
        <color
          rgba="0.89804 0.91765 0.92941 1" />
      </material>
    </visual>
    <collision>
      <origin
        xyz="0 0 0"
        rpy="0 0 0" />
      <geometry>
        <mesh
          filename="package://simpledog/meshes/front_right_2_Link.STL" />
      </geometry>
    </collision>
  </link>
  <joint
    name="front_right_2_joint"
    type="revolute">
    <origin
      xyz="-0.03442 0 0.04"
      rpy="1.5708 0 3.1416" />
    <parent
      link="front_right_1_Link" />
    <child
      link="front_right_2_Link" />
    <axis
      xyz="1 0 0" />
      <limit
        effort="100"
        velocity="10"
        lower="-3.0"
        upper="3.0"/>
  </joint>
  <link
    name="front_right_3_Link">
    <inertial>
      <origin
        xyz="-0.043271 -1.0168E-05 -0.087821"
        rpy="0 0 0" />
      <mass
        value="1.3523" />
      <inertia
        ixx="0.0093381"
        ixy="-2.3773E-08"
        ixz="-0.00020532"
        iyy="0.0091429"
        iyz="-9.1579E-07"
        izz="0.00053022" />
    </inertial>
    <visual>
      <origin
        xyz="0 0 0"
        rpy="0 0 0" />
      <geometry>
        <mesh
          filename="package://simpledog/meshes/front_right_3_Link.STL" />
      </geometry>
      <material
        name="">
        <color
          rgba="0.89804 0.91765 0.92941 1" />
      </material>
    </visual>
    <collision>
      <origin
        xyz="0 0 0"
        rpy="0 0 0" />
      <geometry>
        <mesh
          filename="package://simpledog/meshes/front_right_3_Link.STL" />
      </geometry>
    </collision>
  </link>
  <joint
    name="front_right_3_joint"
    type="revolute">
    <origin
      xyz="0.02 0 -0.25"
      rpy="0 0 -3.1416" />
    <parent
      link="front_right_2_Link" />
    <child
      link="front_right_3_Link" />
    <axis
      xyz="-1 0 0" />
      <limit
        effort="100"
        velocity="10"
        lower="-3.0"
        upper="3.0"/>
  </joint>
  <link
    name="rear_left_1_Link">
    <inertial>
      <origin
        xyz="-0.012793 9.5193E-17 -0.04"
        rpy="0 0 0" />
      <mass
        value="1.1709" />
      <inertia
        ixx="0.0013167"
        ixy="2.8409E-18"
        ixz="3.3901E-19"
        iyy="0.001719"
        iyz="5.3128E-21"
        izz="0.0021511" />
    </inertial>
    <visual>
      <origin
        xyz="0 0 0"
        rpy="0 0 0" />
      <geometry>
        <mesh
          filename="package://simpledog/meshes/rear_left_1_Link.STL" />
      </geometry>
      <material
        name="">
        <color
          rgba="0.89804 0.91765 0.92941 1" />
      </material>
    </visual>
    <collision>
      <origin
        xyz="0 0 0"
        rpy="0 0 0" />
      <geometry>
        <mesh
          filename="package://simpledog/meshes/rear_left_1_Link.STL" />
      </geometry>
    </collision>
  </link>
  <joint
    name="rear_left_1_joint"
    type="revolute">
    <origin
      xyz="0.36 -0.175 0"
      rpy="-1.5708 0 1.5708" />
    <parent
      link="base_link" />
    <child
      link="rear_left_1_Link" />
    <axis
      xyz="0 0 1" />
      <limit
        effort="100"
        velocity="10"
        lower="-3.0"
        upper="3.0"/>
  </joint>
  <link
    name="rear_left_2_Link">
    <inertial>
      <origin
        xyz="0.026967 -5.5511E-17 -0.11432"
        rpy="0 0 0" />
      <mass
        value="1.3902" />
      <inertia
        ixx="0.028484"
        ixy="-2.8833E-18"
        ixz="-1.9987E-16"
        iyy="0.026875"
        iyz="7.9636E-18"
        izz="0.0030209" />
    </inertial>
    <visual>
      <origin
        xyz="0 0 0"
        rpy="0 0 0" />
      <geometry>
        <mesh
          filename="package://simpledog/meshes/rear_left_2_Link.STL" />
      </geometry>
      <material
        name="">
        <color
          rgba="0.89804 0.91765 0.92941 1" />
      </material>
    </visual>
    <collision>
      <origin
        xyz="0 0 0"
        rpy="0 0 0" />
      <geometry>
        <mesh
          filename="package://simpledog/meshes/rear_left_2_Link.STL" />
      </geometry>
    </collision>
  </link>
  <joint
    name="rear_left_2_joint"
    type="revolute">
    <origin
      xyz="-0.032453 0 -0.04"
      rpy="-1.5708 0 -3.1416" />
    <parent
      link="rear_left_1_Link" />
    <child
      link="rear_left_2_Link" />
    <axis
      xyz="1 0 0" />
      <limit
        effort="100"
        velocity="10"
        lower="-3.0"
        upper="3.0"/>
  </joint>
  <link
    name="rear_left_3_Link">
    <inertial>
      <origin
        xyz="-0.044945 -1.0168E-05 -0.087821"
        rpy="0 0 0" />
      <mass
        value="1.3523" />
      <inertia
        ixx="0.0093381"
        ixy="-2.3773E-08"
        ixz="-0.00020532"
        iyy="0.0091429"
        iyz="-9.1579E-07"
        izz="0.00053022" />
    </inertial>
    <visual>
      <origin
        xyz="0 0 0"
        rpy="0 0 0" />
      <geometry>
        <mesh
          filename="package://simpledog/meshes/rear_left_3_Link.STL" />
      </geometry>
      <material
        name="">
        <color
          rgba="0.89804 0.91765 0.92941 1" />
      </material>
    </visual>
    <collision>
      <origin
        xyz="0 0 0"
        rpy="0 0 0" />
      <geometry>
        <mesh
          filename="package://simpledog/meshes/rear_left_3_Link.STL" />
      </geometry>
    </collision>
  </link>
  <joint
    name="rear_left_3_joint"
    type="revolute">
    <origin
      xyz="0.020293 0 -0.25"
      rpy="0 0 3.1416" />
    <parent
      link="rear_left_2_Link" />
    <child
      link="rear_left_3_Link" />
    <axis
      xyz="-1 0 0" />
      <limit
        effort="100"
        velocity="10"
        lower="-3.0"
        upper="3.0"/>
  </joint>
  <link
    name="rear_right_1_Link">
    <inertial>
      <origin
        xyz="-0.012793 -1.8946E-16 -0.04"
        rpy="0 0 0" />
      <mass
        value="1.1709" />
      <inertia
        ixx="0.0013167"
        ixy="-7.0709E-18"
        ixz="-1.3209E-19"
        iyy="0.001719"
        iyz="-1.4321E-19"
        izz="0.0021511" />
    </inertial>
    <visual>
      <origin
        xyz="0 0 0"
        rpy="0 0 0" />
      <geometry>
        <mesh
          filename="package://simpledog/meshes/rear_right_1_Link.STL" />
      </geometry>
      <material
        name="">
        <color
          rgba="0.89804 0.91765 0.92941 1" />
      </material>
    </visual>
    <collision>
      <origin
        xyz="0 0 0"
        rpy="0 0 0" />
      <geometry>
        <mesh
          filename="package://simpledog/meshes/rear_right_1_Link.STL" />
      </geometry>
    </collision>
  </link>
  <joint
    name="rear_right_1_joint"
    type="revolute">
    <origin
      xyz="0.36 0.175 0"
      rpy="1.5708 0 -1.5708" />
    <parent
      link="base_link" />
    <child
      link="rear_right_1_Link" />
    <axis
      xyz="0 0 -1" />
      <limit
        effort="100"
        velocity="10"
        lower="-3.0"
        upper="3.0"/>
  </joint>
  <link
    name="rear_right_2_Link">
    <inertial>
      <origin
        xyz="0.025 1.6653E-16 -0.11432"
        rpy="0 0 0" />
      <mass
        value="1.3902" />
      <inertia
        ixx="0.028484"
        ixy="1.1937E-17"
        ixz="-4.1954E-16"
        iyy="0.026875"
        iyz="4.0516E-18"
        izz="0.0030209" />
    </inertial>
    <visual>
      <origin
        xyz="0 0 0"
        rpy="0 0 0" />
      <geometry>
        <mesh
          filename="package://simpledog/meshes/rear_right_2_Link.STL" />
      </geometry>
      <material
        name="">
        <color
          rgba="0.89804 0.91765 0.92941 1" />
      </material>
    </visual>
    <collision>
      <origin
        xyz="0 0 0"
        rpy="0 0 0" />
      <geometry>
        <mesh
          filename="package://simpledog/meshes/rear_right_2_Link.STL" />
      </geometry>
    </collision>
  </link>
  <joint
    name="rear_right_2_joint"
    type="revolute">
    <origin
      xyz="-0.03442 0 -0.04"
      rpy="1.5708 0 3.1416" />
    <parent
      link="rear_right_1_Link" />
    <child
      link="rear_right_2_Link" />
    <axis
      xyz="1 0 0" />
      <limit
        effort="100"
        velocity="10"
        lower="-3.0"
        upper="3.0"/>
  </joint>
  <link
    name="rear_right_3_Link">
    <inertial>
      <origin
        xyz="-0.043271 -1.0168E-05 -0.087821"
        rpy="0 0 0" />
      <mass
        value="1.3523" />
      <inertia
        ixx="0.0093381"
        ixy="-2.3773E-08"
        ixz="-0.00020532"
        iyy="0.0091429"
        iyz="-9.1579E-07"
        izz="0.00053022" />
    </inertial>
    <visual>
      <origin
        xyz="0 0 0"
        rpy="0 0 0" />
      <geometry>
        <mesh
          filename="package://simpledog/meshes/rear_right_3_Link.STL" />
      </geometry>
      <material
        name="">
        <color
          rgba="0.89804 0.91765 0.92941 1" />
      </material>
    </visual>
    <collision>
      <origin
        xyz="0 0 0"
        rpy="0 0 0" />
      <geometry>
        <mesh
          filename="package://simpledog/meshes/rear_right_3_Link.STL" />
      </geometry>
    </collision>
  </link>
  <joint
    name="rear_right_3_joint"
    type="revolute">
    <origin
      xyz="0.02 0 -0.25"
      rpy="0 0 -3.1416" />
    <parent
      link="rear_right_2_Link" />
    <child
      link="rear_right_3_Link" />
    <axis
      xyz="-1 0 0" />
      <limit
        effort="100"
        velocity="10"
        lower="-3.0"
        upper="3.0"/>
  </joint>

</robot>
